Workbook
Name \0: #REF!
Name \a: #N/A
Name \E: #REF!
Name \f: #N/A
Name \g: #REF!
Name \h: #REF!
Name \i: #REF!
Name \j: #REF!
Name \l: #REF!
Name \M: #REF!
Name \n: #REF!
Name \p: #N/A
Name \q: #REF!
Name \R: #REF!
Name \s: #REF!
Name \T: #REF!
Name \u: #REF!
Name \V: #REF!
Name \w: #REF!
Name \x: #N/A
Name \z: #N/A
Name __: #REF!
Name __________________________________New1: #REF!
Name __________________________________sep97: #REF!
Name __________________________________sht1: #REF!
Name _________________________________Grp12: #REF!
Name _________________________________Grp13: #REF!
Name _________________________________Grp14: #REF!
Name _________________________________Grp15: #REF!
Name _________________________________Grp2: #REF!
Name _________________________________New1: #REF!
Name _________________________________sep97: #REF!
Name _________________________________sht1: #REF!
Name ________________________________FST1: #REF!
Name ________________________________Grp12: #REF!
Name ________________________________Grp13: #REF!
Name ________________________________Grp14: #REF!
Name ________________________________Grp15: #REF!
Name ________________________________Grp2: #REF!
Name ________________________________ILT1: #REF!
Name ________________________________New1: #REF!
Name ________________________________sep97: #REF!
Name ________________________________sht1: #REF!
Name ________________________________ST1: #REF!
Name ________________________________TLT1: #REF!
Name ________________________________TOT1: #REF!
Name ________________________________UER1: #REF!
Name _______________________________FST1: #REF!
Name _______________________________Grp12: #REF!
Name _______________________________Grp13: #REF!
Name _______________________________Grp14: #REF!
Name _______________________________Grp15: #REF!
Name _______________________________Grp2: #REF!
Name _______________________________ILT1: #REF!
Name _______________________________New1: #REF!
Name _______________________________sep97: #REF!
Name _______________________________sht1: #REF!
Name _______________________________ST1: #REF!
Name _______________________________TLT1: #REF!
Name _______________________________TOT1: #REF!

Sheet Assumption Cost
B2: 21.77a Violet Hill - [0118] [Fee calculations] | F2: Cost | J2: Fee | K2: 5 | L2: 3 | M2: 2 | N2: 7
K3: 0.05 | L3: 0.0106 | M3: 0.0059 | N3: 0.0033
B4: 1 | C4: Total Construction cost | D4: 53.709675 | F4: Construction | G4: Structural | H4: MEP | I4: Landscaping | K4: Architectural | L4: Structural | M4: MEP | N4: Landscaping | Q4: Construction cost to be punched in D4
C6: Total | D6: 100 | E6: % | F6: =SUM(F8,F14,F18,F23) -> 53.709675 | G6: =SUM(G8,G14,G18,G23) -> 18.977419 | H6: =SUM(H8,H14,H18,H23) -> 15.844354 | I6: =SUM(I8,I14,I18,I23) -> 2.5320275 | J6: =SUM(J8,J14,J18,J23) -> 0 | K6: =SUM(K8,K14,K18,K23) -> 2.6854838 | L6: =SUM(L8,L14,L18,L23) -> 0.56932256 | M6: =SUM(M8,M14,M18,M23) -> 0.31688708 | N6: =SUM(N8,N14,N18,N23) -> 0.17724193 | Q6: Punch values in F15 and 16 respectively for Plotted land and Amenities
B8: A | C8: Residential | D8: 0 | E8: =D8/100 -> 0 | F8: =SUM($D$4*E8) -> 0 | G8: =SUM(L8*100)/$L$2 -> 0 | H8: =SUM(M8*100)/$M$2 -> 0 | I8: =SUM(N8*100)/$N$2 -> 0 | K8: =(F8*$K$3)/100 -> 0 | L8: =(F8*$L$3)/100 -> 0 | M8: =($F8*$M$3)/100 -> 0 | N8: =($F8*$N$3)/100 -> 0 | Q8: Once BOQ is available then use BOQ cost sheet for fee calculation
C9: Apartments | D9: 0 | E9: =D9/100 -> 0 | F9: =SUM($D$4*E9) -> 0 | G9: =SUM(L9*100)/$L$2 -> 0 | H9: =SUM(M9*100)/$M$2 -> 0 | I9: =SUM(N9*100)/$N$2 -> 0 | K9: =(F9*$K$3)/100 -> 0 | L9: =(F9*$L$3)/100 -> 0 | M9: =($F9*$M$3)/100 -> 0 | N9: =($F9*$N$3)/100 -> 0
C10: Villas | D10: 0 | E10: =D10/100 -> 0 | F10: =SUM($D$4*E10) -> 0 | G10: =SUM(L10*100)/$L$2 -> 0 | H10: =SUM(M10*100)/$M$2 -> 0 | I10: =SUM(N10*100)/$N$2 -> 0 | K10: =(F10*$K$3)/100 -> 0 | L10: =(F10*$L$3)/100 -> 0 | M10: =($F10*$M$3)/100 -> 0 | N10: =($F10*$N$3)/100 -> 0
C11: Townhouses | D11: 0 | E11: =D11/100 -> 0 | F11: =SUM($D$4*E11) -> 0 | G11: =SUM(L11*100)/$L$2 -> 0 | H11: =SUM(M11*100)/$M$2 -> 0 | I11: =SUM(N11*100)/$N$2 -> 0 | K11: =(F11*$K$3)/100 -> 0 | L11: =(F11*$L$3)/100 -> 0 | M11: =($F11*$M$3)/100 -> 0 | N11: =($F11*$N$3)/100 -> 0
C12: Amenities | D12: 0 | E12: =D12/100 -> 0 | F12: =SUM($D$4*E12) -> 0 | G12: =SUM(L12*100)/$L$2 -> 0 | H12: =SUM(M12*100)/$M$2 -> 0 | I12: =SUM(N12*100)/$N$2 -> 0 | K12: =(F12*$K$3)/100 -> 0 | L12: =(F12*$L$3)/100 -> 0 | M12: =($F12*$M$3)/100 -> 0 | N12: =($F12*$N$3)/100 -> 0
B14: B | C14: Plotted development | D14: =SUM(D15:D16) -> 100 | E14: =D14/100 -> 1 | F14: =SUM($D$4*E14) -> 53.709675 | G14: =SUM(L14*100)/$L$2 -> 18.977419 | H14: =SUM(M14*100)/$M$2 -> 15.844354 | I14: =SUM(N14*100)/$N$2 -> 2.5320275 | K14: =(F14*$K$3) -> 2.6854838 | L14: =(F14*$L$3) -> 0.56932256 | M14: =($F14*$M$3) -> 0.31688708 | N14: =($F14*$N$3) -> 0.17724193
C15: Plotted Land | D15: 100 | E15: =D15/100 -> 1 | F15: 48.641048 | G15: =SUM(L15*100)/$L$2 -> 17.186504 | H15: =SUM(M15*100)/$M$2 -> 14.349109 | I15: =SUM(N15*100)/$N$2 -> 2.293078 | K15: =(F15*$K$3) -> 2.4320524 | L15: =(F15*$L$3) -> 0.51559511 | M15: =($F15*$M$3) -> 0.28698218 | N15: =($F15*$N$3) -> 0.16051546
C16: Amenities | D16: 0 | E16: =D16/100 -> 0 | F16: 5.0686273 | G16: =SUM(L16*100)/$L$2 -> 1.790915 | H16: =SUM(M16*100)/$M$2 -> 1.4952451 | I16: =SUM(N16*100)/$N$2 -> 0.23894957 | K16: =(F16*$K$3) -> 0.25343137 | L16: =(F16*$L$3) -> 0.053727449 | M16: =($F16*$M$3) -> 0.029904901 | N16: =($F16*$N$3) -> 0.01672647
B18: C | C18: Commercial | D18: 0 | E18: =D18/100 -> 0 | F18: =SUM($D$4*E18) -> 0 | G18: =SUM(L18*100)/$L$2 -> 0 | H18: =SUM(M18*100)/$M$2 -> 0 | I18: =SUM(N18*100)/$N$2 -> 0 | K18: =(F18*$K$2)/100 -> 0 | L18: =(F18*$L$3)/100 -> 0 | M18: =($F18*$M$3)/100 -> 0 | N18: =($F18*$N$3)/100 -> 0
C19: Tower - Office | D19: 0 | E19: =D19/100 -> 0 | F19: =SUM($D$4*E19) -> 0 | G19: =SUM(L19*100)/$L$2 -> 0 | H19: =SUM(M19*100)/$M$2 -> 0 | I19: =SUM(N19*100)/$N$2 -> 0 | K19: =(F19*$K$2)/100 -> 0 | L19: =(F19*$L$3)/100 -> 0 | M19: =($F19*$M$3)/100 -> 0 | N19: =($F19*$N$3)/100 -> 0
C20: Health + Wellness | D20: 0 | E20: =D20/100 -> 0 | F20: =SUM($D$4*E20) -> 0 | G20: =SUM(L20*100)/$L$2 -> 0 | H20: =SUM(M20*100)/$M$2 -> 0 | I20: =SUM(N20*100)/$N$2 -> 0 | K20: =(F20*$K$2)/100 -> 0 | L20: =(F20*$L$3)/100 -> 0 | M20: =($F20*$M$3)/100 -> 0 | N20: =($F20*$N$3)/100 -> 0
C21: Hospitality (Resort) | D21: 0 | E21: =D21/100 -> 0 | F21: =SUM($D$4*E21) -> 0 | G21: =SUM(L21*100)/$L$2 -> 0 | H21: =SUM(M21*100)/$M$2 -> 0 | I21: =SUM(N21*100)/$N$2 -> 0 | K21: =(F21*$K$2)/100 -> 0 | L21: =(F21*$L$3)/100 -> 0 | M21: =($F21*$M$3)/100 -> 0 | N21: =($F21*$N$3)/100 -> 0
B23: D | C23: Festival centre | D23: 0 | E23: =D23/100 -> 0 | F23: =SUM($D$4*E23) -> 0 | G23: =SUM(L23*100)/$L$2 -> 0 | H23: =SUM(M23*100)/$M$2 -> 0 | I23: =SUM(N23*100)/$N$2 -> 0 | K23: =(F23*$K$3)/100 -> 0 | L23: =(F23*$L$3)/100 -> 0 | M23: =($F23*$M$3)/100 -> 0 | N23: =($F23*$N$3)/100 -> 0
C24: Festival centre | D24: 0 | E24: =D24/100 -> 0 | F24: =SUM($D$4*E24) -> 0 | G24: =SUM(L24*100)/$L$2 -> 0 | H24: =SUM(M24*100)/$M$2 -> 0 | I24: =SUM(N24*100)/$N$2 -> 0 | K24: =(F24*$K$3)/100 -> 0 | L24: =(F24*$L$3)/100 -> 0 | M24: =($F24*$M$3)/100 -> 0 | N24: =($F24*$N$3)/100 -> 0
C25: Education - School | D25: 0 | E25: =D25/100 -> 0 | F25: =SUM($D$4*E25) -> 0 | G25: =SUM(L25*100)/$L$2 -> 0 | H25: =SUM(M25*100)/$M$2 -> 0 | I25: =SUM(N25*100)/$N$2 -> 0 | K25: =(F25*$K$3)/100 -> 0 | L25: =(F25*$L$3)/100 -> 0 | M25: =($F25*$M$3)/100 -> 0 | N25: =($F25*$N$3)/100 -> 0

Sheet Design Fee
E4: =E12+E13+E15+E14+E17+E42+E16+E20 -> 1 | G4: =G12+G13+G15+G14+G17+G42+G16+G20 -> 1 | I4: =I12+I13+I15+I14+I17+I42+I16+I20 -> 1 | K4: =K12+K13+K15+K14+K17+K42+K16+K20 -> 1
B5: Plotted Development | E5: AR | G5: ST | I5: MEP | K5: LS
B10: 1 | C10: DESIGN CONCEPT | E10: 0.45 | F10: =E10*'Assumption Cost'!$K$6 -> 1.2084677 | G10: 0.4 | H10: =G10*'Assumption Cost'!$L$6 -> 0.22772902 | I10: 0.3 | J10: =I10*'Assumption Cost'!$M$6 -> 0.095066125 | K10: 0.4 | L10: =K10*'Assumption Cost'!$N$6 -> 0.070896771 | M10: MP | N10: Amenities
C12: DC 01 | D12: Contract + Design Brief | E12: 0.05 | F12: =E12*'Assumption Cost'!$K$6 -> 0.13427419 | G12: 0 | I12: 0 | K12: 0
C13: DC 02 | D13: Schematic Concept | E13: 0.1 | F13: =E13*'Assumption Cost'!$K$6 -> 0.26854838 | G13: 0.1 | H13: =G13*'Assumption Cost'!$L$6 -> 0.056932256 | I13: 0.05 | J13: =I13*'Assumption Cost'!$M$6 -> 0.015844354 | K13: 0.1 | L13: =K13*'Assumption Cost'!$N$6 -> 0.017724193 | M13: =E13*'Assumption Cost'!$K$15 -> 0.24320524 | N13: =E13*'Assumption Cost'!$K$16 -> 0.025343137
C14: DC 03 | D14: Approvals | E14: 0.1 | F14: =E14*'Assumption Cost'!$K$6 -> 0.26854838 | G14: 0 | I14: 0.1 | J14: =I14*'Assumption Cost'!$M$6 -> 0.031688708 | K14: 0.15 | L14: =K14*'Assumption Cost'!$N$6 -> 0.026586289 | M14: =E14*'Assumption Cost'!$K$15 -> 0.24320524 | N14: =E14*'Assumption Cost'!$K$16 -> 0.025343137
C15: DC 04 | D15: Pre Construction Set | E15: 0.1 | F15: =E15*'Assumption Cost'!$K$6 -> 0.26854838 | G15: 0.2 | H15: =G15*'Assumption Cost'!$L$6 -> 0.11386451 | I15: 0.1 | J15: =I15*'Assumption Cost'!$M$6 -> 0.031688708 | K15: 0.05 | L15: =K15*'Assumption Cost'!$N$6 -> 0.0088620964 | M15: =E15*'Assumption Cost'!$K$15 -> 0.24320524 | N15: =E15*'Assumption Cost'!$K$16 -> 0.025343137
C16: DC 05 | D16: Project Experience | E16: 0.05 | F16: =E16*'Assumption Cost'!$K$6 -> 0.13427419 | G16: 0.1 | H16: =G16*'Assumption Cost'!$L$6 -> 0.056932256 | I16: 0.05 | J16: =I16*'Assumption Cost'!$M$6 -> 0.015844354 | K16: 0.05 | L16: =K16*'Assumption Cost'!$N$6 -> 0.0088620964
C17: DC 06 | D17: Marketing and Sales | E17: 0.05 | F17: =E17*'Assumption Cost'!$K$6 -> 0.13427419 | G17: 0 | I17: 0 | K17: 0.05 | L17: =K17*'Assumption Cost'!$N$6 -> 0.0088620964
C18: CONSTRUCTION DOCUMENTS
B20: 2 | C20: MP | D20: Master Plan | E20: =SUM(E21:E32) -> 0.5 | F20: =E20*'Assumption Cost'!$K$15 -> 1.2160262 | G20: =SUM(G21:G32) -> 0.55 | H20: =G20*'Assumption Cost'!$L$15 -> 0.28357731 | I20: =SUM(I21:I32) -> 0.65 | J20: =I20*'Assumption Cost'!$M$15 -> 0.18653842 | K20: =SUM(K21:K32) -> 0.55 | L20: =K20*'Assumption Cost'!$N$15 -> 0.088283502
C21: MP 01 | D21: Infra - Grading | E21: 0.1 | F21: =E21*'Assumption Cost'!$K$15 -> 0.24320524 | G21: 0.05 | H21: =G21*'Assumption Cost'!$L$15 -> 0.025779755 | I21: 0 | J21: =I21*'Assumption Cost'!$M$15 -> 0 | K21: 0 | L21: =K21*'Assumption Cost'!$N$15 -> 0
C22: MP 02 | D22: Infra - MEP | E22: 0.05 | F22: =E22*'Assumption Cost'!$K$15 -> 0.12160262 | G22: 0.1 | H22: =G22*'Assumption Cost'!$L$15 -> 0.051559511 | I22: 0.15 | J22: =I22*'Assumption Cost'!$M$15 -> 0.043047327 | K22: 0.05 | L22: =K22*'Assumption Cost'!$N$15 -> 0.0080257729
C23: MP 03 | D23: BOQ & Technical Specifications | E23: 0.1 | F23: =E23*'Assumption Cost'!$K$15 -> 0.24320524 | G23: 0 | H23: =G23*'Assumption Cost'!$L$15 -> 0 | I23: 0.05 | J23: =I23*'Assumption Cost'!$M$15 -> 0.014349109 | K23: 0.05 | L23: =K23*'Assumption Cost'!$N$15 -> 0.0080257729
C24: MP 04 | D24: Infra - Coordinated | E24: 0 | F24: =E24*'Assumption Cost'!$K$15 -> 0 | G24: 0 | H24: =G24*'Assumption Cost'!$L$15 -> 0 | I24: 0.1 | J24: =I24*'Assumption Cost'!$M$15 -> 0.028698218 | K24: 0.05 | L24: =K24*'Assumption Cost'!$N$15 -> 0.0080257729
C25: MP 05 | D25: Structures - Security Cabin and Entrance | E25: 0.03 | F25: =E25*'Assumption Cost'!$K$15 -> 0.072961572 | G25: 0.05 | H25: =G25*'Assumption Cost'!$L$15 -> 0.025779755 | I25: 0.05 | J25: =I25*'Assumption Cost'!$M$15 -> 0.014349109 | K25: 0.05 | L25: =K25*'Assumption Cost'!$N$15 -> 0.0080257729
C26: MP 06 | D26: Infra - Plot Boundary & Enclosures | E26: 0.03 | F26: =E26*'Assumption Cost'!$K$15 -> 0.072961572 | G26: 0.05 | H26: =G26*'Assumption Cost'!$L$15 -> 0.025779755 | I26: 0 | J26: =I26*'Assumption Cost'!$M$15 -> 0 | K26: 0.05 | L26: =K26*'Assumption Cost'!$N$15 -> 0.0080257729
C27: MP 07 | D27: Infra - Signage & Street Lighting | E27: 0.03 | F27: =E27*'Assumption Cost'!$K$15 -> 0.072961572 | G27: 0.05 | H27: =G27*'Assumption Cost'!$L$15 -> 0.025779755 | I27: 0.05 | J27: =I27*'Assumption Cost'!$M$15 -> 0.014349109 | K27: 0.05 | L27: =K27*'Assumption Cost'!$N$15 -> 0.0080257729
C28: MP 08 | D28: Structures - Electrical Room & Toilet Block | E28: 0.03 | F28: =E28*'Assumption Cost'!$K$15 -> 0.072961572 | G28: 0.05 | H28: =G28*'Assumption Cost'!$L$15 -> 0.025779755 | I28: 0.05 | J28: =I28*'Assumption Cost'!$M$15 -> 0.014349109 | K28: 0.05 | L28: =K28*'Assumption Cost'!$N$15 -> 0.0080257729
C29: MP 09 | D29: Structures - UGT | E29: 0.03 | F29: =E29*'Assumption Cost'!$K$15 -> 0.072961572 | G29: 0.05 | H29: =G29*'Assumption Cost'!$L$15 -> 0.025779755 | I29: 0.05 | J29: =I29*'Assumption Cost'!$M$15 -> 0.014349109 | K29: 0.05 | L29: =K29*'Assumption Cost'!$N$15 -> 0.0080257729
C30: MP 10 | D30: Structures - OHT | E30: 0.03 | F30: =E30*'Assumption Cost'!$K$15 -> 0.072961572 | G30: 0.05 | H30: =G30*'Assumption Cost'!$L$15 -> 0.025779755 | I30: 0.05 | J30: =I30*'Assumption Cost'!$M$15 -> 0.014349109 | K30: 0.05 | L30: =K30*'Assumption Cost'!$N$15 -> 0.0080257729
C31: MP 11 | D31: Structures - STP | E31: 0.03 | F31: =E31*'Assumption Cost'!$K$15 -> 0.072961572 | G31: 0.05 | H31: =G31*'Assumption Cost'!$L$15 -> 0.025779755 | I31: 0.05 | J31: =I31*'Assumption Cost'!$M$15 -> 0.014349109 | K31: 0.05 | L31: =K31*'Assumption Cost'!$N$15 -> 0.0080257729
C32: MP 12 | D32: Structures - OWC & other structure | E32: 0.04 | F32: =E32*'Assumption Cost'!$K$15 -> 0.097282095 | G32: 0.05 | H32: =G32*'Assumption Cost'!$L$15 -> 0.025779755 | I32: 0.05 | J32: =I32*'Assumption Cost'!$M$15 -> 0.014349109 | K32: 0.05 | L32: =K32*'Assumption Cost'!$N$15 -> 0.0080257729
B33: 3 | C33: AM | D33: Clubhouse + Amenities | E33: =E34+E35+E36+E37+E38 -> 0.5 | F33: =E33*'Assumption Cost'!$K$16 -> 0.12671568 | G33: =G34+G35+G36+G37+G38 -> 0.55 | H33: =G33*'Assumption Cost'!$L$16 -> 0.029550097 | I33: =I34+I35+I36+I37+I38 -> 0.65 | J33: =I33*'Assumption Cost'!$M$16 -> 0.019438186 | K33: =K34+K35+K36+K37+K38 -> 0.55 | L33: =K33*'Assumption Cost'!$N$16 -> 0.0091995586
C34: AM 01 | D34: Clubhouse—Structure and Envelope | E34: 0.15 | F34: =E34*'Assumption Cost'!$K$16 -> 0.038014705 | G34: 0.35 | H34: =G34*'Assumption Cost'!$L$16 -> 0.018804607 | I34: 0.35 | J34: =I34*'Assumption Cost'!$M$16 -> 0.010466715 | K34: 0
C35: AM 02 | D35: Clubhouse—Interiors and Facilities | E35: 0.2 | F35: =E35*'Assumption Cost'!$K$16 -> 0.050686273 | G35: 0 | I35: 0.15 | J35: =I35*'Assumption Cost'!$M$16 -> 0.0044857352 | K35: 0.1 | L35: =K35*'Assumption Cost'!$N$16 -> 0.001672647
C36: AM 03 | D36: Clubhouse—Outdoor Spaces and pool | E36: 0.05 | F36: =E36*'Assumption Cost'!$K$16 -> 0.012671568 | G36: 0.05 | H36: =G36*'Assumption Cost'!$L$16 -> 0.0026863725 | I36: 0.1 | J36: =I36*'Assumption Cost'!$M$16 -> 0.0029904901 | K36: 0.2 | L36: =K36*'Assumption Cost'!$N$16 -> 0.003345294
C37: AM 04 | D37: Community spaces [Children play area, Open Park space] | E37: 0.05 | F37: =E37*'Assumption Cost'!$K$16 -> 0.012671568 | G37: 0.05 | H37: =G37*'Assumption Cost'!$L$16 -> 0.0026863725 | K37: 0.25 | L37: =K37*'Assumption Cost'!$N$16 -> 0.0041816175
C38: AM 05 | D38: Sporting Facilities | E38: 0.05 | F38: =E38*'Assumption Cost'!$K$16 -> 0.012671568 | G38: 0.1 | H38: =G38*'Assumption Cost'!$L$16 -> 0.0053727449 | I38: 0.05 | J38: =I38*'Assumption Cost'!$M$16 -> 0.0014952451 | K38: 0
C40: POST-CONSTRUCTION
B42: 4 | C42: MA | D42: Master Archives | E42: 0.05 | F42: =E42*'Assumption Cost'!$K$6 -> 0.13427419 | G42: 0.05 | H42: =G42*'Assumption Cost'!$L$6 -> 0.028466128 | I42: 0.05 | J42: =I42*'Assumption Cost'!$M$6 -> 0.015844354 | K42: 0.05 | L42: =K42*'Assumption Cost'!$N$6 -> 0.0088620964

Sheet Packages deliverables
A1: =SUM(A19:A129) -> 285 | B1: Package Code | C1: Package Description | D1: Master Planning | E1: Released Status | G1: Released Status | H1: MEP | I1: Released Status | K1: Released Status | M1: Released Status | N1: Structural | O1: Released Status | P1: Landscape | Q1: Released Status
F2: Infra Consultants | H2: PHE | J2: ELE | L2: IBMS
B3: Master Planning - Schematic
F4: Traffic & Transporation
F5: Reports
F6: Earthworks & Site Grading:
F7: Concept Exhibit Drawings
F8: Budget Estimate
F9: Roadways Engineering:
F10: Budget Estimate
F11: Storm Water Management:
F12: Report with Schematic Drawings
F13: Budget Estimate
F14: Public Health Engineering - Infrastructure Services.
F15: Report with Schematic Drawings | H15: Schematic for Utilities
F16: Budget Estimate
B18: Construction Documents
A19: 30 | B19: Batch 01 | C19: Infra - Grading
D20: Survey Drawing | F20: Road Center Line, Setout Plan & Tables | N20: Boundary Wall Details
D21: Existing Structure Demolition Plan | F21: Road plans & Profile Sections | N21: Typical Road Details
D22: Area Details & Plot Schedule | F22: Isopach Plan | N22: Typical Planter Box Details
D23: Master Plan - GA | F23: Typical Grading Sections
D24: Part plans - Plot Set Outs, Tree Transplantation info, Road Set out.
D25: Master Plan - Boundary Wall
D26: Boundary Wall Details
D27: Road Sections - GA
A28: 30 | B28: Batch 02 | C28: Infra - MEP
D29: Junction Details | F29: Master Plan - Road Storm Drain Network with Sheet Index | J29: Master Plan - Zoning, Equipment and Cable Routing Layout. | L29: Site Plan CCTV Layout | N29: Storm Water Drain & Chamber Details | P29: LDS - 01
D30: Plot Entry Ramp Details | F30: Storm Drain - Road Plan & Profile Sections, Open space Catch Basin Tap off points. | J30: Enlarged plans for Cable Routing | L30: Standard Details for CCTV | N30: Sewage chmaber details | P30: General Arrangement Plan
D31: Cul-de-sac Details | F31: Storm Drain Pipe Details | J31: Tranformer & DG Yard Details | N31: Electrical Chamber Details | P31: All Marking Plan
F32: Storm Drain Structure Table | J32: Feeder Pillar Details | N32: Trench Details | P32: Material Details
F33: Storm Drain Details | J33: Site Plan Earthing Layout | N33: Plot Entry Ramp Details | P33: Irrigation plan
F34: Master Plan - Sanitary and Sewer Network | J34: Earthing Scheme | N34: Tranformer & DG Yard Details | P34: Tree and Shrub Planting plans
F35: Sanitary & Sewer - Road Plan & Profile Sections, including plot connections | J35: Earthing layout for tranformer and DG Yrads | P35: Sections, Elevations & Details
F36: Pipe Table SS network | J36: Standard Details for Street Lights
F37: Structure Table SS Network | J37: Site - Power Disbibution Scheme
F38: Sanitary Sewer Details | J38: Elctrical Chamber & Pipe Details
F39: Master Plan - Water Supply Network
F40: Water Supply Network Cover Sheet
F41: Roads Water Supply Plans
...

Sheet BOQ cost
B2: Project Name - [Code] (Fee calculations) | F2: BOQ Cost | J2: Design Fee | K2: 0.05 | L2: 0.03 | M2: 0.02 | N2: 0.07
B4: 1 | C4: Total Construction cost | F4: Architectural | G4: Structural | H4: MEP | I4: Landscaping | K4: Architectural | L4: Structural | M4: MEP | N4: Landscaping
C6: Total | F6: =SUM(F8,F14) -> 0 | G6: =SUM(G8,G14) -> 0 | H6: =SUM(H8,H14) -> 0 | I6: =SUM(I8,I14) -> 0 | J6: =SUM(J8,J14) -> 0 | K6: =SUM(K8,K14) -> 0 | L6: =SUM(L8,L14) -> 0 | M6: =SUM(M8,M14) -> 0 | N6: =SUM(N8,N14) -> 0
B8: A | C8: Plotted development | F8: =SUM(F9:F12) -> 0 | G8: =SUM(G9:G12) -> 0 | H8: =SUM(H9:H12) -> 0 | I8: =SUM(I9:I12) -> 0 | K8: =(F8*$K$3) -> 0 | L8: =(F8*$L$3) -> 0 | M8: =($F8*$M$3) -> 0 | N8: =($F8*$N$3) -> 0
C9: Site Development | K9: =(F9*$K$2) -> 0 | L9: =(G9*$L$2) -> 0 | M9: =(H9*$M$2) -> 0 | N9: =(I9*$N$2) -> 0
C10: Site MEP | K10: =(F10*$K$2) -> 0 | L10: =(G10*$L$2) -> 0 | M10: =(H10*$M$2) -> 0 | N10: =(I10*$N$2) -> 0
C11: Utilities | K11: =(F11*$K$2) -> 0 | L11: =(G11*$L$2) -> 0 | M11: =(H11*$M$2) -> 0 | N11: =(I11*$N$2) -> 0
C12: Amenities | K12: =(F12*$K$2) -> 0 | L12: =(G12*$L$2) -> 0 | M12: =(H12*$M$2) -> 0 | N12: =(I12*$N$2) -> 0
B14: B | C14: Commercial | F14: =SUM(F15:F17) -> 0 | G14: =SUM(G15:G17) -> 0 | H14: =SUM(H15:H17) -> 0 | I14: =SUM(I15:I17) -> 0 | K14: =(F14*$K$2)/100 -> 0 | L14: =(F14*$L$3)/100 -> 0 | M14: =($F14*$M$3)/100 -> 0 | N14: =($F14*$N$3)/100 -> 0
C15: Tower - Office | K15: =(F15*$K$2)/100 -> 0 | L15: =(F15*$L$3)/100 -> 0 | M15: =($F15*$M$3)/100 -> 0 | N15: =($F15*$N$3)/100 -> 0
C16: Health + Wellness | K16: =(F16*$K$2)/100 -> 0 | L16: =(F16*$L$3)/100 -> 0 | M16: =($F16*$M$3)/100 -> 0 | N16: =($F16*$N$3)/100 -> 0
C17: Hospitality (Resort) | K17: =(F17*$K$2)/100 -> 0 | L17: =(F17*$L$3)/100 -> 0 | M17: =($F17*$M$3)/100 -> 0 | N17: =($F17*$N$3)/100 -> 0

Sheet Drawing list | MP & AR
B1: 0118 Violet Hill | M1: P26 | N1: 1 | O1: 2 | P1: 3 | Q1: 4 | R1: A26 | S1: 5 | T1: 6 | U1: 7 | V1: 8 | X1: P27 | Y1: 9 | Z1: 10 | AA1: 11 | AB1: 12 | AC1: A27 | AD1: 13 | AE1: 14 | AF1: 15 | AG1: 16
B2: Sl. No. | C2: Drawing No. | F2: DRAWING NAME | G2: Location | H2: Batch Code | I2: Batch | J2: Issue Status | M2: =SUM(M5:M60) -> 33 | N2: =SUM(N5:N60) -> 33 | O2: =SUM(O5:O60) -> 0 | P2: =SUM(P5:P60) -> 0 | Q2: =SUM(Q5:Q60) -> 0 | R2: Issue in Yr 2026 | S2: =SUM(S5:S60) -> 0 | T2: =SUM(T5:T60) -> 33 | U2: =SUM(U5:U60) -> 0 | V2: =SUM(V5:V60) -> 0 | X2: =SUM(X5:X60) -> 0 | Y2: =SUM(Y5:Y60) -> 0 | Z2: =SUM(Z5:Z60) -> 0 | AA2: =SUM(AA5:AA60) -> 0 | AB2: =SUM(AB5:AB60) -> 0 | AC2: Issue in Yr 2027 | AD2: =SUM(AD5:AD60) -> 0 | AE2: =SUM(AE5:AE60) -> 0 | AF2: =SUM(AF5:AF60) -> 0 | AG2: =SUM(AG5:AG60) -> 0
B3: Discipline | C3: Area of works | D3: Sheet No | E3: Dwg. No. | J3: Till Dec'25 | K3: Date of receipt | L3: Revision | M3: Plan for Yr 2026 | N3: Q1 | O3: Q2 | P3: Q3 | Q3: Q4 | S3: Q1 | T3: Q2 | U3: Q3 | V3: Q4 | W3: Till Dec'26 | X3: Plan for Yr 2027 | Y3: Q1 | Z3: Q2 | AA3: Q3 | AB3: Q4 | AD3: Q1 | AE3: Q2 | AF3: Q3 | AG3: Q4
D4: GFC | INFRA - GRADING
A5: UD | B5: MP | C5: 000 | D5: 0001 | E5: =CONCATENATE(B5,"-",C5,"-",D5) -> MP-000-0001 | F5: MASTER PLAN-GENERAL ARRANGEMENT | G5: MP | H5: 1 | I5: =CONCATENATE(A5,"-",G5,"-",H5) -> UD-MP-1 | J5: -1 | K5: 46244 | L5: R2 | M5: 1 | N5: 1 | R5: 1 | T5: 1 | W5: 1
A6: UD | B6: MP | C6: 000 | D6: 0003 | E6: =CONCATENATE(B6,"-",C6,"-",D6) -> MP-000-0003 | F6: MASTER PLAN-SETTING OUT-PLOTS & ROADS | G6: MP | H6: 1 | I6: =CONCATENATE(A6,"-",G6,"-",H6) -> UD-MP-1 | J6: -1 | K6: 46244 | L6: R2 | M6: 1 | N6: 1 | R6: 1 | T6: 1 | W6: 1
A7: UD | B7: MP | C7: 000 | D7: 0004 | E7: =CONCATENATE(B7,"-",C7,"-",D7) -> MP-000-0004 | F7: MASTER PLAN-SETTING OUT-SIGNAGE, CCTV, LIGHT POLES | G7: MP | H7: 1 | I7: =CONCATENATE(A7,"-",G7,"-",H7) -> UD-MP-1 | J7: -1 | K7: 46244 | L7: R2 | M7: 1 | N7: 1 | R7: 1 | T7: 1 | W7: 1
A8: UD | B8: MP | C8: 000 | D8: 0005 | E8: =CONCATENATE(B8,"-",C8,"-",D8) -> MP-000-0005 | F8: MASTER PLAN-PERIPHERAL BOUNDARY WALL | G8: MP | H8: 1 | I8: =CONCATENATE(A8,"-",G8,"-",H8) -> UD-MP-1 | J8: -1 | K8: 46244 | L8: R2 | M8: 1 | N8: 1 | R8: 1 | T8: 1 | W8: 1
A9: UD | B9: MP | C9: GR | D9: 0001 | E9: =CONCATENATE(B9,"-",C9,"-",D9) -> MP-GR-0001 | F9: MASTER PLAN-ROAD GRADING | G9: MP | H9: 1 | I9: =CONCATENATE(A9,"-",G9,"-",H9) -> UD-MP-1 | J9: -1 | K9: 46135 | L9: R0 | M9: 1 | N9: 1 | R9: 1 | T9: 1 | W9: 1
A10: UD | B10: MP | C10: GR | D10: 0002 | E10: =CONCATENATE(B10,"-",C10,"-",D10) -> MP-GR-0002 | F10: MASTER PLAN-SITE SECTIONS | G10: MP | H10: 1 | I10: =CONCATENATE(A10,"-",G10,"-",H10) -> UD-MP-1 | J10: -1 | K10: 46135 | L10: R0 | M10: 1 | N10: 1 | R10: 1 | T10: 1 | W10: 1
A11: UD | B11: MP | C11: GR | D11: 0003 | E11: =CONCATENATE(B11,"-",C11,"-",D11) -> MP-GR-0003 | F11: MASTER PLAN-ISOPACH | G11: MP | H11: 1 | I11: =CONCATENATE(A11,"-",G11,"-",H11) -> UD-MP-1 | J11: -1 | K11: 46135 | L11: R0 | M11: 1 | N11: 1 | R11: 1 | T11: 1 | W11: 1
A12: UD | B12: MP | C12: GR | D12: 0004 | E12: =CONCATENATE(B12,"-",C12,"-",D12) -> MP-GR-0004 | F12: MASTER PLAN-RETAINING WALL | G12: MP | H12: 1 | I12: =CONCATENATE(A12,"-",G12,"-",H12) -> UD-MP-1 | J12: -1 | K12: 46244 | L12: R2 | M12: 1 | N12: 1 | R12: 1 | T12: 1 | W12: 1
A13: UD | B13: MP | C13: RDS | D13: 3011 | E13: =CONCATENATE(B13,"-",C13,"-",D13) -> MP-RDS-3011 | F13: ROAD SECTION-R30N SECTION 1 | G13: MP | H13: 1 | I13: =CONCATENATE(A13,"-",G13,"-",H13) -> UD-MP-1 | J13: -1 | K13: 46136 | L13: R0 | M13: 1 | N13: 1 | R13: 1 | T13: 1 | W13: 1
A14: UD | B14: MP | C14: RDS | D14: 3012 | E14: =CONCATENATE(B14,"-",C14,"-",D14) -> MP-RDS-3012 | F14: ROAD SECTION-R30N SECTION 2 | G14: MP | H14: 1 | I14: =CONCATENATE(A14,"-",G14,"-",H14) -> UD-MP-1 | J14: -1 | K14: 46136 | L14: R0 | M14: 1 | N14: 1 | R14: 1 | T14: 1 | W14: 1
A15: UD | B15: MP | C15: RDS | D15: 3013 | E15: =CONCATENATE(B15,"-",C15,"-",D15) -> MP-RDS-3013 | F15: ROAD SECTION-R30N SECTION 3 | G15: MP | H15: 1 | I15: =CONCATENATE(A15,"-",G15,"-",H15) -> UD-MP-1 | J15: -1 | K15: 46136 | L15: R0 | M15: 1 | N15: 1 | R15: 1 | T15: 1 | W15: 1
A16: UD | B16: MP | C16: RDS | D16: 3021 | E16: =CONCATENATE(B16,"-",C16,"-",D16) -> MP-RDS-3021 | F16: ROAD SECTION-R33N SECTION 1 | G16: MP | H16: 1 | I16: =CONCATENATE(A16,"-",G16,"-",H16) -> UD-MP-1 | J16: -1 | K16: 46136 | L16: R0 | M16: 1 | N16: 1 | R16: 1 | T16: 1 | W16: 1
... A24: UD | B24: MP | C24: RDS | D24: 3043 | E24: =CONCATENATE(B24,"-",C24,"-",D24) -> MP-RDS-3043 | F24: ROAD SECTION-R40D SECTION 3 | G24: MP | H24: 1 | I24: =CONCATENATE(A24,"-",G24,"-",H24) -> UD-MP-1 | J24: -1 | K24: 46136 | L24: R0 | M24: 1 | N24: 1 | R24: 1 | T24: 1 | W24: 1
D25: GFC | INFRA - COORDINATED
A26: UD | B26: MP | C26: CO | D26: 0001 | E26: =CONCATENATE(B26,"-",C26,"-",D26) | F26: MASTER PLAN-CO-ORDINATED UTILITIES | G26: MP | H26: 1 | I26: =CONCATENATE(A26,"-",G26,"-",H26) -> UD-MP-1 | J26: -1 | K26: 46251 | L26: R2 | M26: 1 | N26: 1 | R26: 1 | T26: 1 | W26: 1
A27: UD | B27: MP | C27: CO | D27: 3001 | E27: =CONCATENATE(B27,"-",C27,"-",D27) | F27: STREET SECTIONS 1-1', 2-2', 3-3', 4-4' | G27: MP | H27: 1 | I27: =CONCATENATE(A27,"-",G27,"-",H27) -> UD-MP-1 | J27: -1 | K27: 46248 | L27: R0 | M27: 1 | N27: 1 | R27: 1 | T27: 1 | W27: 1
A28: UD | B28: MP | C28: CO | D28: 3002 | E28: =CONCATENATE(B28,"-",C28,"-",D28) -> MP-CO-3002 | F28: STREET SECTIONS 5-5', 6-6', 7-7', 8-8' | G28: MP | H28: 1 | I28: =CONCATENATE(A28,"-",G28,"-",H28) -> UD-MP-1 | J28: -1 | K28: 46248 | L28: R0 | M28: 1 | N28: 1 | R28: 1 | T28: 1 | W28: 1
A29: UD | B29: MP | C29: CO | D29: 3003 | E29: =CONCATENATE(B29,"-",C29,"-",D29) -> MP-CO-3003 | F29: STREET SECTIONS 9-9', 10-10', 11-11', 12-12' | G29: MP | H29: 1 | I29: =CONCATENATE(A29,"-",G29,"-",H29) -> UD-MP-1 | J29: -1 | K29: 46248 | L29: R0 | M29: 1 | N29: 1 | R29: 1 | T29: 1 | W29: 1
A30: UD | B30: MP | C30: CO | D30: 3004 | E30: =CONCATENATE(B30,"-",C30,"-",D30) -> MP-CO-3004 | F30: STREET SECTIONS 13-13', 14-14', 15-15' | G30: MP | H30: 1 | I30: =CONCATENATE(A30,"-",G30,"-",H30) -> UD-MP-1 | J30: -1 | K30: 46248 | L30: R0 | M30: 1 | N30: 1 | R30: 1 | T30: 1 | W30: 1
D31: GFC | INFRA - MEP
A32: UD | B32: MP | C32: SD | D32: 0001 | E32: =CONCATENATE(B32,"-",C32,"-",D32) -> MP-SD-0001 | F32: MASTER PLAN-STORM DRAIN SLD | G32: MP | H32: 2 | I32: =CONCATENATE(A32,"-",G32,"-",H32) -> UD-MP-2 | J32: -1 | K32: 46244 | L32: R2 | M32: 1 | N32: 1 | R32: 1 | T32: 1 | W32: 1
A33: UD | B33: MP | C33: SD | D33: 0002 | E33: =CONCATENATE(B33,"-",C33,"-",D33) -> MP-SD-0002 | F33: MASTER PLAN-STORM DRAIN | G33: MP | H33: 2 | I33: =CONCATENATE(A33,"-",G33,"-",H33) -> UD-MP-2 | J33: -1 | K33: 46244 | L33: R2 | M33: 1 | N33: 1 | R33: 1 | T33: 1 | W33: 1
A34: UD | B34: MP | C34: SS | D34: 0001 | E34: =CONCATENATE(B34,"-",C34,"-",D34) -> MP-SS-0001 | F34: MASTER PLAN-SANITARY SEWER SLD | G34: MP | H34: 2 | I34: =CONCATENATE(A34,"-",G34,"-",H34) -> UD-MP-2 | J34: -1 | K34: 46244 | L34: R2 | M34: 1 | N34: 1 | R34: 1 | T34: 1 | W34: 1
A35: UD | B35: MP | C35: SS | D35: 0002 | E35: =CONCATENATE(B35,"-",C35,"-",D35) -> MP-SS-0002 | F35: MASTER PLAN-SANITARY SEWER | G35: MP | H35: 2 | I35: =CONCATENATE(A35,"-",G35,"-",H35) -> UD-MP-2 | J35: -1 | K35: 46244 | L35: R2 | M35: 1 | N35: 1 | R35: 1 | T35: 1 | W35: 1
A36: UD | B36: MP | C36: WS | D36: 0001 | E36: =CONCATENATE(B36,"-",C36,"-",D36) -> MP-WS-0001 | F36: MASTER PLAN-WATER SUPPLY SLD | G36: MP | H36: 2 | I36: =CONCATENATE(A36,"-",G36,"-",H36) -> UD-MP-2 | J36: -1 | K36: 46244 | L36: R2 | M36: 1 | N36: 1 | R36: 1 | T36: 1 | W36: 1
A37: UD | B37: MP | C37: WS | D37: 0002 | E37: =CONCATENATE(B37,"-",C37,"-",D37) -> MP-WS-0002 | F37: MASTER PLAN-WATER SUPPLY | G37: MP | H37: 2 | I37: =CONCATENATE(A37,"-",G37,"-",H37) -> UD-MP-2 | J37: -1 | K37: 46244 | L37: R2 | M37: 1 | N37: 1 | R37: 1 | T37: 1 | W37: 1
A38: UD | B38: MP | C38: WS | D38: 0003 | E38: =CONCATENATE(B38,"-",C38,"-",D38) -> MP-WS-0003 | F38: MASTER PLAN-IRRIGATION SLD | G38: MP | H38: 2 | I38: =CONCATENATE(A38,"-",G38,"-",H38) -> UD-MP-2 | J38: -1 | K38: 46244 | L38: R2 | M38: 1 | N38: 1 | R38: 1 | T38: 1 | W38: 1
D39: GFC | STRUCTURES - SECURITY CABIN AND ENTRANCE
A40: UD | B40: MP | C40: SC1 | D40: 0001 | E40: =CONCATENATE(B40,"-",C40,"-",D40) -> MP-SC1-0001 | F40: SC1- SITE PLAN & SECTION | G40: MP | H40: 5 | I40: =CONCATENATE(A40,"-",G40,"-",H40) -> UD-MP-5 | J40: 1 | K40: 45912 | L40: R0
A41: UD | B41: MP | C41: SC1 | D41: 1001 | E41: =CONCATENATE(B41,"-",C41,"-",D41) -> MP-SC1-1001 | F41: MASONRY AND FLOORING PLAN | G41: MP | H41: 5 | I41: =CONCATENATE(A41,"-",G41,"-",H41) -> UD-MP-5 | J41: 1 | K41: 45912 | L41: R0
A42: UD | B42: MP | C42: SC1 | D42: 1002 | E42: =CONCATENATE(B42,"-",C42,"-",D42) -> MP-SC1-1002 | F42: SECURITY CABIN 1 - ELECTRICAL PLAN | G42: MP | H42: 5 | I42: =CONCATENATE(A42,"-",G42,"-",H42) -> UD-MP-5 | J42: 1 | K42: 45912 | L42: R0
A43: UD | B43: MP | C43: SC1 | D43: 1003 | E43: =CONCATENATE(B43,"-",C43,"-",D43) -> MP-SC1-1003 | F43: SECURITY CABIN 1 - DRAINAGE PLAN | G43: MP | H43: 5 | I43: =CONCATENATE(A43,"-",G43,"-",H43) -> UD-MP-5 | J43: 1 | K43: 45912 | L43: R0
A44: UD | B44: MP | C44: SC1 | D44: 2001 | E44: =CONCATENATE(B44,"-",C44,"-",D44) -> MP-SC1-2001 | F44: ELEVATION & SECTIONS | G44: MP | H44: 5 | I44: =CONCATENATE(A44,"-",G44,"-",H44) -> UD-MP-5 | J44: 1 | K44: 45912 | L44: R0
A45: UD | B45: MP | C45: SC1 | D45: 4001 | E45: =CONCATENATE(B45,"-",C45,"-",D45) -> MP-SC1-4001 | F45: GUARD ROOM PLAN | G45: MP | H45: 5 | I45: =CONCATENATE(A45,"-",G45,"-",H45) -> UD-MP-5 | J45: 1 | K45: 45912 | L45: R0
A46: UD | B46: MP | C46: SC1 | D46: 4002 | E46: =CONCATENATE(B46,"-",C46,"-",D46) -> MP-SC1-4002 | F46: CONTROL ROOM PLAN | G46: MP | H46: 5 | I46: =CONCATENATE(A46,"-",G46,"-",H46) -> UD-MP-5 | J46: 1 | K46: 45912 | L46: R0
A47: UD | B47: MP | C47: SC1 | D47: 4003 | E47: =CONCATENATE(B47,"-",C47,"-",D47) -> MP-SC1-4003 | F47: CIRCULAR SKY LIGHT - TERRACE DETAIL | G47: MP | H47: 5 | I47: =CONCATENATE(A47,"-",G47,"-",H47) -> UD-MP-5 | J47: 1 | K47: 45912 | L47: R0
...

Sheet Drawing list | ST
B1: 0118 Violet Hill | M1: P26 | N1: 1 | O1: 2 | P1: 3 | Q1: 4 | R1: A26 | S1: 5 | T1: 6 | U1: 7 | V1: 8 | X1: P27 | Y1: 9 | Z1: 10 | AA1: 11 | AB1: 12 | AC1: A27 | AD1: 13 | AE1: 14 | AF1: 15 | AG1: 16
B2: Sl. No. | C2: Drawing No. | F2: DRAWING NAME | G2: Location | H2: Batch Code | I2: Batch | J2: Issue Status | M2: =SUM(M9:M24) -> 0 | N2: =SUM(N9:N24) -> 0 | O2: =SUM(O9:O24) -> 0 | P2: =SUM(P9:P24) -> 0 | Q2: =SUM(Q9:Q24) -> 0 | R2: Issue in Yr 2026 | S2: =SUM(S9:S24) -> 0 | T2: =SUM(T9:T24) -> 0 | U2: =SUM(U9:U24) -> 0 | V2: =SUM(V9:V24) -> 0 | X2: =SUM(X9:X24) -> 0 | Y2: =SUM(Y9:Y24) -> 0 | Z2: =SUM(Z9:Z24) -> 0 | AA2: =SUM(AA9:AA24) -> 0 | AB2: =SUM(AB9:AB24) -> 0 | AC2: Issue in Yr 2027 | AD2: =SUM(AD9:AD24) -> 0 | AE2: =SUM(AE9:AE24) -> 0 | AF2: =SUM(AF9:AF24) -> 0 | AG2: =SUM(AG9:AG24) -> 0
B3: Discipline | C3: Area of works | D3: Sheet No | E3: Dwg. No. | J3: Till Dec'25 | K3: Date of receipt | L3: Revision | M3: Plan for Yr 2026 | N3: Q1 | O3: Q2 | P3: Q3 | Q3: Q4 | S3: Q1 | T3: Q2 | U3: Q3 | V3: Q4 | W3: Till Dec'26 | X3: Plan for Yr 2027 | Y3: Q1 | Z3: Q2 | AA3: Q3 | AB3: Q4 | AD3: Q1 | AE3: Q2 | AF3: Q3 | AG3: Q4
D4: GFC | INFRA - GRADING
A5: UD | B5: S | C5: BXX | D5: RW0001 | E5: =CONCATENATE(B5,"-",C5,"-",D5) -> S-BXX-RW0001 | F5: ROAD RETAINING WALL / INDIVIDUAL PLOT BOUNDARY WALL DETAILS (SHEET-1) | G5: MP | H5: 2 | I5: =CONCATENATE(A5,"-",G5,"-",H5) -> UD-MP-2 | J5: -1 | K5: 46156 | L5: R0 | M5: 1 | N5: 1 | R5: 1 | T5: 1 | W5: 1
A6: UD | B6: S | C6: BXX | D6: RW0002 | E6: =CONCATENATE(B6,"-",C6,"-",D6) -> S-BXX-RW0002 | F6: ROAD RETAINING WALL / INDIVIDUAL PLOT BOUNDARY WALL DETAILS (SHEET-2) | G6: MP | H6: 2 | I6: =CONCATENATE(A6,"-",G6,"-",H6) -> UD-MP-2 | J6: -1 | K6: 46156 | L6: R0 | M6: 1 | N6: 1 | R6: 1 | T6: 1 | W6: 1
A7: UD | B7: S | C7: BXX | D7: RW0003 | E7: =CONCATENATE(B7,"-",C7,"-",D7) -> S-BXX-RW0003 | F7: ROAD RETAINING WALL / INDIVIDUAL PLOT BOUNDARY WALL DETAILS (SHEET-3) | G7: MP | H7: 2 | I7: =CONCATENATE(A7,"-",G7,"-",H7) -> UD-MP-2 | J7: -1 | K7: 46156 | L7: R0 | M7: 1 | N7: 1 | R7: 1 | T7: 1 | W7: 1
A8: UD | B8: S | C8: BXX | D8: RW0004 | E8: =CONCATENATE(B8,"-",C8,"-",D8) -> S-BXX-RW0004 | F8: RETAINING WALL MISCELLANEOUS DETAILS | G8: MP | H8: 2 | I8: =CONCATENATE(A8,"-",G8,"-",H8) -> UD-MP-2 | J8: -1 | K8: 46156 | L8: R0 | M8: 1 | N8: 1 | R8: 1 | T8: 1 | W8: 1
D9: GFC | STRUCTURES - SECURITY CABIN AND ENTRANCE
A10: UD | B10: S | C10: SC1 | D10: FD0001 | E10: =CONCATENATE(B10,"-",C10,"-",D10) -> S-SC1-FD0001 | F10: FOUNDATION LAYOUT | G10: MP | H10: 5 | I10: =CONCATENATE(A10,"-",G10,"-",H10) -> UD-MP-5 | J10: 1 | K10: 45905 | L10: R0
A11: UD | B11: S | C11: SC1 | D11: FD0002 | E11: =CONCATENATE(B11,"-",C11,"-",D11) -> S-SC1-FD0002 | F11: FOOTING REINF. DETAIL | G11: MP | H11: 5 | I11: =CONCATENATE(A11,"-",G11,"-",H11) -> UD-MP-5 | J11: 1 | K11: 45905 | L11: R0
A12: UD | B12: S | C12: SC1 | D12: FD0003 | E12: =CONCATENATE(B12,"-",C12,"-",D12) -> S-SC1-FD0003 | F12: FOOTING CF1 REINF. DETAIL | G12: MP | H12: 5 | I12: =CONCATENATE(A12,"-",G12,"-",H12) -> UD-MP-5 | J12: 1 | K12: 45905 | L12: R0
A13: UD | B13: S | C13: SC1 | D13: FD0004 | E13: =CONCATENATE(B13,"-",C13,"-",D13) -> S-SC1-FD0004 | F13: FOOTING CF6 REINF. DETAIL | G13: MP | H13: 5 | I13: =CONCATENATE(A13,"-",G13,"-",H13) -> UD-MP-5 | J13: 1 | K13: 45905 | L13: R0
A14: UD | B14: S | C14: SC1 | D14: CL0001 | E14: =CONCATENATE(B14,"-",C14,"-",D14) -> S-SC1-CL0001 | F14: COLUMN REINF. DETAIL | G14: MP | H14: 5 | I14: =CONCATENATE(A14,"-",G14,"-",H14) -> UD-MP-5 | J14: 1 | K14: 45905 | L14: R0
A15: UD | B15: S | C15: SC1 | D15: FP0001 | E15: =CONCATENATE(B15,"-",C15,"-",D15) -> S-SC1-FP0001 | F15: FRAMING PLAN AT ROOF LEVEL | G15: MP | H15: 5 | I15: =CONCATENATE(A15,"-",G15,"-",H15) -> UD-MP-5 | J15: 1 | K15: 45905 | L15: R0
A16: UD | B16: S | C16: SC1 | D16: BM0001 | E16: =CONCATENATE(B16,"-",C16,"-",D16) -> S-SC1-BM0001 | F16: REINFORCEMENT DETAILS OF BEAM 0B1 & 0B2 | G16: MP | H16: 5 | I16: =CONCATENATE(A16,"-",G16,"-",H16) -> UD-MP-5 | J16: 1 | K16: 45905 | L16: R0
A17: UD | B17: S | C17: SC1 | D17: BM0002 | E17: =CONCATENATE(B17,"-",C17,"-",D17) -> S-SC1-BM0002 | F17: REINFORCEMENT DETAILS OF BEAM 0B3 & 0B4 | G17: MP | H17: 5 | I17: =CONCATENATE(A17,"-",G17,"-",H17) -> UD-MP-5 | J17: 1 | K17: 45905 | L17: R0
A18: UD | B18: S | C18: SC1 | D18: BM0003 | E18: =CONCATENATE(B18,"-",C18,"-",D18) -> S-SC1-BM0003 | F18: BEAM B1, B2, B3, & B4 REINFORCEMENT DETAILS | G18: MP | H18: 5 | I18: =CONCATENATE(A18,"-",G18,"-",H18) -> UD-MP-5 | J18: 1 | K18: 45929 | L18: R0
A19: UD | B19: S | C19: SC1 | D19: BM0004 | E19: =CONCATENATE(B19,"-",C19,"-",D19) -> S-SC1-BM0004 | F19: BBS OF BEAM B1, B2, B3 & B4 | G19: MP | H19: 5 | I19: =CONCATENATE(A19,"-",G19,"-",H19) -> UD-MP-5 | J19: 1 | K19: 45929 | L19: R0
A20: UD | B20: S | C20: SC1 | D20: SB0001 | E20: =CONCATENATE(B20,"-",C20,"-",D20) -> S-SC1-SB0001 | F20: SLAB BOTTOM REINF. DETAIL | G20: MP | H20: 5 | I20: =CONCATENATE(A20,"-",G20,"-",H20) -> UD-MP-5 | J20: 1 | K20: 45929 | L20: R0
A21: UD | B21: S | C21: SC1 | D21: SB0002 | E21: =CONCATENATE(B21,"-",C21,"-",D21) -> S-SC1-SB0002 | F21: BBS FOR SLAB BOTTOM REINF. DETAIL | G21: MP | H21: 5 | I21: =CONCATENATE(A21,"-",G21,"-",H21) -> UD-MP-5 | J21: 1 | K21: 45929 | L21: R0
... A24: UD | B24: S | C24: SC1 | D24: SB0005 | E24: =CONCATENATE(B24,"-",C24,"-",D24) -> S-SC1-SB0005 | F24: SLAB SHEAR REINF. DETAIL AND SECTIONS | G24: MP | H24: 5 | I24: =CONCATENATE(A24,"-",G24,"-",H24) -> UD-MP-5 | J24: 1 | K24: 45929 | L24: R0
D25: GFC | STRUCTURES - PROJECT EXPERIENCE
B26: S | C26: AS01 | D26: FD0101 | E26: S-AS01-FD0101 | F26: FOUNDATION LAYOUT | G26: DC | H26: 5 | I26: UD-DC-5 | J26: -1 | K26: 46219 | L26: R0 | M26: 1 | P26: 1 | R26: 1 | U26: 1 | W26: 1
B27: S | C27: AS01 | D27: FD0102 | E27: S-AS01-FD0102 | F27: FOOTING & COLUMN BASE CONNECTION DETAILS | G27: DC | H27: 5 | I27: UD-DC-5 | J27: -1 | K27: 46219 | L27: R0 | M27: 1 | P27: 1 | R27: 1 | U27: 1 | W27: 1
B28: S | C28: AS01 | D28: FD0101 | E28: S-AS01-FP0101 | F28: FRAMING PLAN AT SSL 01 | G28: DC | H28: 5 | I28: UD-DC-5 | J28: -1 | K28: 46219 | L28: R0 | M28: 1 | P28: 1 | R28: 1 | U28: 1 | W28: 1
B29: S | C29: AS01 | D29: FD0101 | E29: S-AS01-FP0102 | F29: CANOPY SECTIONS DETAILS | G29: DC | H29: 5 | I29: UD-DC-5 | J29: -1 | K29: 46219 | L29: R0 | M29: 1 | P29: 1 | R29: 1 | U29: 1 | W29: 1
B30: S | C30: AS01 | D30: FD0101 | E30: S-AS01-FP0201 | F30: FRAMING PLAN AT SSL 02 | G30: DC | H30: 5 | I30: UD-DC-5 | J30: -1 | K30: 46219 | L30: R0 | M30: 1 | P30: 1 | R30: 1 | U30: 1 | W30: 1

Sheet Drawing list | MEP
B1: 0118 Violet Hill | M1: P26 | N1: 1 | O1: 2 | P1: 3 | Q1: 4 | R1: A26 | S1: 5 | T1: 6 | U1: 7 | V1: 8 | X1: P27 | Y1: 9 | Z1: 10 | AA1: 11 | AB1: 12 | AC1: A27 | AD1: 13 | AE1: 14 | AF1: 15 | AG1: 16
B2: Sl. No. | C2: Drawing No. | F2: DRAWING NAME | G2: Location | H2: Batch Code | I2: Batch | J2: Issue Status | M2: =SUM(M15:M17) -> 0 | N2: =SUM(N15:N17) -> 0 | O2: =SUM(O15:O17) -> 0 | P2: =SUM(P15:P17) -> 0 | Q2: =SUM(Q15:Q17) -> 0 | R2: Issue in Yr 2026 | S2: =SUM(S15:S17) -> 0 | T2: =SUM(T15:T17) -> 0 | U2: =SUM(U15:U17) -> 0 | V2: =SUM(V15:V17) -> 0 | X2: =SUM(X15:X17) -> 0 | Y2: =SUM(Y15:Y17) -> 0 | Z2: =SUM(Z15:Z17) -> 0 | AA2: =SUM(AA15:AA17) -> 0 | AB2: =SUM(AB15:AB17) -> 0 | AC2: Issue in Yr 2027 | AD2: =SUM(AD15:AD17) -> 0 | AE2: =SUM(AE15:AE17) -> 0 | AF2: =SUM(AF15:AF17) -> 0 | AG2: =SUM(AG15:AG17) -> 0
B3: Discipline | C3: Area of works | D3: Sheet No | E3: Dwg. No. | J3: Till Dec'25 | K3: Date of receipt | L3: Revision | M3: Plan for Yr 2026 | N3: Q1 | O3: Q2 | P3: Q3 | Q3: Q4 | S3: Q1 | T3: Q2 | U3: Q3 | V3: Q4 | W3: Till Dec'26 | X3: Plan for Yr 2027 | Y3: Q1 | Z3: Q2 | AA3: Q3 | AB3: Q4 | AD3: Q1 | AE3: Q2 | AF3: Q3 | AG3: Q4
D4: GFC | INFRA - MEP
A5: UD | B5: IBMS | C5: 000 | D5: 0001 | E5: =CONCATENATE(B5,"-",C5,"-",D5) -> IBMS-000-0001 | F5: SITE PLAN CCTV LAYOUT | G5: MP | H5: 2 | I5: =CONCATENATE(A5,"-",G5,"-",H5) -> UD-MP-2 | J5: -1 | K5: 46164 | L5: R0 | M5: 1 | N5: 1 | R5: 1 | T5: 1 | W5: 1
A6: UD | B6: ELE | C6: 00 | D6: 0001 | E6: =CONCATENATE(B6,"-",C6,"-",D6) -> ELE-00-0001 | F6: SITE PLAN EQUIPMENT AND CABLE ROUTING LAYOUT | G6: MP | H6: 2 | I6: =CONCATENATE(A6,"-",G6,"-",H6) -> UD-MP-2 | J6: -1 | K6: 46247 | L6: R2 | M6: 1 | N6: 1 | R6: 1 | T6: 1 | W6: 1
A7: UD | B7: ELE | C7: 00 | D7: 0031 | E7: =CONCATENATE(B7,"-",C7,"-",D7) -> ELE-00-0031 | F7: SITE PLAN EARTHING LAYOUT | G7: MP | H7: 2 | I7: =CONCATENATE(A7,"-",G7,"-",H7) -> UD-MP-2 | J7: -1 | K7: 46262 | L7: R2 | M7: 1 | N7: 1 | R7: 1 | T7: 1 | W7: 1
A8: UD | B8: ELE | C8: 00 | D8: 0032 | E8: =CONCATENATE(B8,"-",C8,"-",D8) -> ELE-00-0032 | F8: TRANSFORMER YARD EARTHING LAYOUT | G8: MP | H8: 2 | I8: =CONCATENATE(A8,"-",G8,"-",H8) -> UD-MP-2 | J8: -1 | K8: 46262 | L8: R2 | M8: 1 | N8: 1 | R8: 1 | T8: 1 | W8: 1
A9: UD | B9: ELE | C9: 00 | D9: 0033 | E9: =CONCATENATE(B9,"-",C9,"-",D9) -> ELE-00-0033 | F9: SITE PLAN EARTHING SCHEME | G9: MP | H9: 2 | I9: =CONCATENATE(A9,"-",G9,"-",H9) -> UD-MP-2 | J9: -1 | K9: 46262 | L9: R2 | M9: 1 | N9: 1 | R9: 1 | T9: 1 | W9: 1
A10: UD | B10: ELE | C10: 00 | D10: 0041 | E10: =CONCATENATE(B10,"-",C10,"-",D10) -> ELE-00-0041 | F10: SITE PLAN EXTERNAL LIGHTING LAYOUT | G10: MP | H10: 2 | I10: =CONCATENATE(A10,"-",G10,"-",H10) -> UD-MP-2 | J10: -1 | K10: 46164 | L10: R0 | M10: 1 | N10: 1 | R10: 1 | T10: 1 | W10: 1
A11: UD | B11: ELE | C11: 00 | D11: 9001 | E11: =CONCATENATE(B11,"-",C11,"-",D11) -> ELE-00-9001 | F11: POWER DISTRIBUTION SCHEME | G11: MP | H11: 2 | I11: =CONCATENATE(A11,"-",G11,"-",H11) -> UD-MP-2 | J11: -1 | K11: 46164 | L11: R0 | M11: 1 | N11: 1 | R11: 1 | T11: 1 | W11: 1
A12: UD | B12: ELE | C12: 00 | D12: 9002 | E12: =CONCATENATE(B12,"-",C12,"-",D12) -> ELE-00-9002 | F12: STANDARD NOTES AND FEEDER PILLAR DETAILS | G12: MP | H12: 2 | I12: =CONCATENATE(A12,"-",G12,"-",H12) -> UD-MP-2 | J12: -1 | K12: 46164 | L12: R0 | M12: 1 | N12: 1 | R12: 1 | T12: 1 | W12: 1
A13: UD | B13: ELE | C13: TY | D13: 0021 | E13: =CONCATENATE(B13,"-",C13,"-",D13) -> ELE-TY-0021 | F13: ENLARGED VIEW OF TRANSFORMER YARD AND SECTION LAYOUT | G13: MP | H13: 2 | I13: =CONCATENATE(A13,"-",G13,"-",H13) -> UD-MP-2 | J13: -1 | K13: 46262 | L13: R2 | M13: 1 | N13: 1 | R13: 1 | T13: 1 | W13: 1
A14: UD | B14: ELE | C14: TY | D14: 0022 | E14: =CONCATENATE(B14,"-",C14,"-",D14) -> ELE-TY-0022 | F14: FEEDER PILLAR LAYOUT | G14: MP | H14: 2 | I14: =CONCATENATE(A14,"-",G14,"-",H14) -> UD-MP-2 | J14: -1 | K14: 46164 | L14: R0 | M14: 1 | N14: 1 | R14: 1 | T14: 1 | W14: 1
D15: GFC | STRUCTURES - SECURITY CABIN AND ENTRANCE
A16: UD | B16: PHE | C16: SC1 | D16: 0001 | E16: =CONCATENATE(B16,"-",C16,"-",D16) -> PHE-SC1-0001 | F16: SECURITY CABIN ENLARGED TOILET DETAILS DRAINAGE LAYOUT | G16: MP | H16: 5 | I16: =CONCATENATE(A16,"-",G16,"-",H16) -> UD-MP-5 | J16: 1 | K16: 45915 | L16: R0
A17: UD | B17: PHE | C17: SC1 | D17: 0002 | E17: =CONCATENATE(B17,"-",C17,"-",D17) -> PHE-SC1-0002 | F17: SECURITY CABIN DRAINAGE LAYOUT | G17: MP | H17: 5 | I17: =CONCATENATE(A17,"-",G17,"-",H17) -> UD-MP-5 | J17: 1 | K17: 45915 | L17: R0
