Workbook

Sheet Goals 2026
L1: =SUBTOTAL(3,L19:L1192) -> 1169
B2: 2026 | Design Goals + Billing | G2: Billing [Cr.] | H2: Q1 | I2: Q2 | J2: Q3 | K2: Q4 | L2: Pkgs | M2: Q1 | N2: Q2 | O2: Q3 | P2: Q4 | T2: 2027 Q1 | U2: =213-O4 -> -62 | V2: 237
B4: Project | C4: Phase | D4: Discipline | E4: Design Lead | F4: Description | G4: =SUM(G6+G579) -> 286.58551 | H4: =SUM(H8,H20,H78,H95,H115,H173,H182,H192,H232,H261,H581,H1219,H305,H638,H308,H373,H758,H824,H851,H402,H432,H458,H1315,H877,H484,H508,H538, H528,H1242,H1581,H1193,H1294,H1415,H1437,H1272,H277,H947,H991,H1036,H1481,H1119,H1487,H1514,H1520,H1146,H1459,H1171,H1526,H1532,H1543,H1549,H1576,H1607,H568+H575+H674) -> 115.45647 | I4: =SUM(I8,I20,I78,I95,I115,I173,I182,I192,I232,I261,I581,I1219,I305,I638,I308,I373,I758,I824,I851,I402,I432,I458,I1315,I877,I484,I508,I538, I528,I1242,I1581,I1193,I1294,I1415,I1437,I1272,I277,I947,I991,I1036,I1481,I1119,I1487,I1514,I1520,I1146,I1459,I1171,I1526,I1532,I1543,I1549,I1576,I1607,I568+I575+I674) -> 60.026291 | J4: =SUM(J8,J20,J78,J95,J115,J173,J182,J192,J232,J261,J581,J1219,J305,J638,J308,J373,J758,J824,J851,J402,J432,J458,J1315,J877,J484,J508,J538, J528,J1242,J1581,J1193,J1294,J1415,J1437,J1272,J277,J947,J991,J1036,J1481,J1119,J1487,J1514,J1520,J1146,J1459,J1171,J1526,J1532,J1543,J1549,J1576,J1607,J568+J575+J674) -> 56.528406 | K4: =SUM(K8,K20,K78,K95,K115,K173,K182,K192,K232,K261,K581,K1219,K305,K638,K308,K373,K758,K824,K851,K402,K432,K458,K1315,K877,K484,K508,K538, K528,K1242,K1581,K1193,K1294,K1415,K1437,K1272,K277,K947,K991,K1036,K1481,K1119,K1487,K1514,K1520,K1146,K1459,K1171,K1526,K1532,K1543,K1549,K1576,K1607,K568+K575+K674) -> 54.840694 | L4: =SUM(L8,L20,L78,L95,L115,L173,L182,L192,L232,L261,L581,L1219,L305,L638,L308,L373,L758,L824,L851,L402,L432,L458,L1315,L877,L484,L508,L538, L528,L1242,L1581,L1193,L1294,L1415,L1437,L1272,L277,L947,L991,L1036,L1481,L1119,L1487,L1514,L1520,L1146,L1459,L1171,L1526,L1532,L1543,L1549,L1576,L1607,L568,L575,L674) -> 1143 | M4: =SUM(M8,M20,M78,M93,M95,M115,M173,M182,M192,M232,M261,M581,M1219,M305,M638,M308,M373,M758,M824,M851,M402,M432,M458,M1315,M877,M484,M508,M538, M528,M1242,M1581,M1193,M1294,M1415,M1437,M1272,M277,M947,M991,M1036,M1481,M1119,M1487,M1514,M1520,M1146,M1459,M1171,M1526,M1532,M1543,M1549,M1576,M1607,M568+M575+M674) -> 403 | N4: =SUM(N8,N20,N78,N95,N115,N173,N182,N192,N232,N261,N581,N1219,N305,N638,N308,N373,N758,N824,N851,N402,N432,N458,N1315,N877,N484,N508,N538, N528,N1242,N1581,N1193,N1294,N1415,N1437,N1272,N277,N947,N991,N1036,N1481,N1119,N1487,N1514,N1520,N1146,N1459,N1171,N1526,N1532,N1543,N1549,N1576,N1607,N568+N575+N674) -> 235 | O4: =SUM(O8,O20,O78,O95,O115,O173,O182,O192,O232,O261,O581,O1219,O305,O638,O308,O373,O758,O824,O851,O402,O432,O458,O1315,O877,O484,O508,O538, O528,O1242,O1581,O1193,O1294,O1415,O1437,O1272,O277,O947,O991,O1036,O1481,O1119,O1487,O1514,O1520,O1146,O1459,O1171,O1526,O1532,O1543,O1549,O1576,O1607,O568+O575+O674) -> 275 | P4: =SUM(P8,P20,P78,P95,P115,P173,P182,P192,P232,P261,P581,P1219,P305,P638,P308,P373,P758,P824,P851,P402,P432,P458,P1315,P877,P484,P508,P538, P528,P1242,P1581,P1193,P1294,P1415,P1437,P1272,P277,P947,P991,P1036,P1481,P1119,P1487,P1514,P1520,P1146,P1459,P1171,P1526,P1532,P1543,P1549,P1576,P1607,P568+P575+P674) -> 230 | R4: =IF(SUM(M4:P4)=L4,"T","F") -> T | X4: =M4/(22*3) -> 6.1060606
B6: Ongoing Projects | G6: =SUM(G8,G20,G78,G95,G115,G173,G182,G192,G232,G261,G277,G305,G308,G373,G402,,G432,G458,G484,G508,G528,G538,G568,G575,G93) -> 56.614312 | H6: =SUM(H8,H20,H78,H95,H115,H173,H182,H192,H232,H261,H277,H305,H308,H373,H402,,H432,H458,H484,H508,H528,H538,H568,H575,H93) -> 38.309869 | I6: =SUM(I8,I20,I78,I95,I115,I173,I182,I192,I232,I261,I277,I305,I308,I373,I402,,I432,I458,I484,I508,I528,I538,I568,I575,I93) -> 13.314982 | J6: =SUM(J8,J20,J78,J95,J115,J173,J182,J192,J232,J261,J277,J305,J308,J373,J402,,J432,J458,J484,J508,J528,J538,J568,J575,J93) -> 4.4936784 | K6: =SUM(K8,K20,K78,K95,K115,K173,K182,K192,K232,K261,K277,K305,K308,K373,K402,,K432,K458,K484,K508,K528,K538,K568,K575,K93) -> 0.49578224 | L6: =SUM(L8,L20,L78,L95,L115,L173,L182,L192,L232,L261,L277,L305,L308,L373,L402,,L432,L458,L484,L508,L528,L538,L568,L575,L93) -> 445 | M6: =SUM(M8,M20,M78,M95,M115,M173,M182,M192,M232,M261,M277,M305,M308,M373,M402,,M432,M458,M484,M508,M528,M538,M568,M575,M93) -> 253 | N6: =SUM(N8,N20,N78,N95,N115,N173,N182,N192,N232,N261,N277,N305,N308,N373,N402,,N432,N458,N484,N508,N528,N538,N568,N575,N93) -> 120 | ... P6: =SUM(P8,P20,P78,P95,P115,P173,P182,P192,P232,P261,P277,P305,P308,P373,P402,,P432,P458,P484,P508,P528,P538,P568,P575,P93) -> 10
B8: AtR | C8: Ph 1, 2a, 2b, 2c | F8: Package Release [Complete LoD 350 by Q1] | G8: =SUM(G9,G14,G18) -> 0.4327194 | H8: =SUM(H9,H14,H18) -> 0.4327194 | I8: =SUM(I9,I14,I18) -> 0 | J8: =SUM(J9,J14,J18) -> 0 | K8: =SUM(K9,K14,K18) -> 0 | L8: =SUM(M8:P8) -> 8 | M8: =SUM(M9,M14,M18) -> 8 | N8: =SUM(N9,N14,N18) -> 0 | O8: =SUM(O9,O14,O18) -> 0 | P8: =SUM(P9,P14,P18) -> 0 | R8: =IF(SUM(M8:P8)=L8,"T","F") -> T | T8: 1014 | U8: =T8-1077 -> -63
B9: AtR | C9: Ph 1, 2a, 2b, 2c | D9: Architecture | F9: Package Release [Complete LoD 350 by Q1] | G9: =SUM(G10:G13) -> 0.39703158 | H9: =SUM(H10:H13) -> 0.39703158 | I9: =SUM(I10:I13) -> 0 | J9: =SUM(J10:J13) -> 0 | K9: =SUM(K10:K13) -> 0 | L9: =SUM(M9:P9) -> 4 | M9: =SUM(M10:M13) -> 4 | N9: =SUM(N10:N13) -> 0 | O9: =SUM(O10:O13) -> 0 | P9: =SUM(P10:P13) -> 0 | R9: =IF(SUM(M9:P9)=L9,"T","F") -> T
B10: AtR | C10: Ph 1, 2a, 2b | D10: Architecture | E10: Saji A | F10: Clubhouse + Amenities - Clubhouse—Interiors and Facilities | G10: 0.27 | H10: =IF(M10=1,$G10,"") -> 0.27 | I10: =IF(N10=1,$G10,"") | J10: =IF(O10=1,$G10,"") | K10: =IF(P10=1,$G10,"") | L10: =SUM(M10:P10) -> 1 | M10: 1 | R10: =IF(SUM(M10:P10)=L10,"T","F") -> T
B11: AtR | C11: Ph 1, 2a, 2b | D11: Architecture | E11: Saji A | F11: Clubhouse + Amenities - Community spaces [Staff Lounge, Children play area] | G11: 0.045377036 | H11: =IF(M11=1,$G11,"") -> 0.045377036 | I11: =IF(N11=1,$G11,"") | J11: =IF(O11=1,$G11,"") | K11: =IF(P11=1,$G11,"") | L11: =SUM(M11:P11) -> 1 | M11: 1 | R11: =IF(SUM(M11:P11)=L11,"T","F") -> T
B12: AtR | C12: Ph 2c | D12: Architecture | E12: Saji A | F12: Master Plan - Site MEP | G12: 0.042238262 | H12: =IF(M12=1,$G12,"") -> 0.042238262 | I12: =IF(N12=1,$G12,"") | J12: =IF(O12=1,$G12,"") | K12: =IF(P12=1,$G12,"") | L12: =SUM(M12:P12) -> 1 | M12: 1 | R12: =IF(SUM(M12:P12)=L12,"T","F") -> T
B13: AtR | C13: Ph 2c | D13: Architecture | E13: Saji A | F13: Clubhouse + Amenities - Sporting Facilities | G13: 0.039416284 | H13: =IF(M13=1,$G13,"") -> 0.039416284 | I13: =IF(N13=1,$G13,"") | J13: =IF(O13=1,$G13,"") | K13: =IF(P13=1,$G13,"") | L13: =SUM(M13:P13) -> 1 | M13: 1 | R13: =IF(SUM(M13:P13)=L13,"T","F") -> T
B14: AtR | C14: Ph 1, 2a, 2b, 2c | D14: Structural | F14: Package Release [Complete LoD 350 by Q1] | G14: =SUM(G15:G17) -> 0.021350947 | H14: =SUM(H15:H17) -> 0.021350947 | I14: =SUM(I15:I18) -> 0 | J14: =SUM(J15:J18) -> 0 | K14: =SUM(K15:K18) -> 0 | L14: =SUM(M14:P14) -> 3 | M14: =SUM(M15:M17) -> 3 | N14: =SUM(N15:N17) -> 0 | O14: =SUM(O15:O17) -> 0 | P14: =SUM(P15:P17) -> 0 | R14: =IF(SUM(M14:P14)=L14,"T","F") -> T
B15: AtR | C15: Ph 1, 2a, 2b | D15: Structural | E15: Prakash C | F15: Clubhouse + Amenities - Community spaces [Staff Lounge, Children play area] | G15: 0.0052867303 | H15: =IF(M15=1,$G15,"") -> 0.0052867303 | I15: =IF(N15=1,$G15,"") | J15: =IF(O15=1,$G15,"") | K15: =IF(P15=1,$G15,"") | L15: =SUM(M15:P15) -> 1 | M15: 1 | R15: =IF(SUM(M15:P15)=L15,"T","F") -> T
B16: AtR | C16: Ph 2c | D16: Structural | E16: Prakash C | F16: Master Plan - Site MEP | G16: 0.010861268 | H16: =IF(M16=1,$G16,"") -> 0.010861268 | I16: =IF(N16=1,$G16,"") | J16: =IF(O16=1,$G16,"") | K16: =IF(P16=1,$G16,"") | L16: =SUM(M16:P16) -> 1 | M16: 1 | R16: =IF(SUM(M16:P16)=L16,"T","F") -> T
B17: AtR | C17: Ph 2c | D17: Structural | E17: Prakash C | F17: Clubhouse + Amenities - Sporting Facilities | G17: 0.0052029495 | H17: =IF(M17=1,$G17,"") -> 0.0052029495 | I17: =IF(N17=1,$G17,"") | J17: =IF(O17=1,$G17,"") | K17: =IF(P17=1,$G17,"") | L17: =SUM(M17:P17) -> 1 | M17: 1 | R17: =IF(SUM(M17:P17)=L17,"T","F") -> T
B18: AtR | C18: Ph 1, 2a, 2b, 2c | D18: MEP | F18: Package Release [Complete LoD 350 by Q1] | G18: =SUM(G19:G19) -> 0.014336873 | H18: =SUM(H19:H19) -> 0.014336873 | I18: =SUM(I19:I19) -> 0 | J18: =SUM(J19:J19) -> 0 | K18: =SUM(K19:K19) -> 0 | L18: =SUM(M18:P18) -> 1 | M18: =SUM(M19:M19) -> 1 | N18: =SUM(N19:N19) -> 0 | O18: =SUM(O19:O19) -> 0 | P18: =SUM(P19:P19) -> 0 | R18: =IF(SUM(M18:P18)=L18,"T","F") -> T
B19: AtR | C19: Ph 2c | D19: MEP | E19: Gagan | F19: Master Plan - Site MEP | G19: 0.014336873 | H19: =IF(M19=1,$G19,"") -> 0.014336873 | I19: =IF(N19=1,$G19,"") | J19: =IF(O19=1,$G19,"") | K19: =IF(P19=1,$G19,"") | L19: =SUM(M19:P19) -> 1 | M19: 1 | R19: =IF(SUM(M19:P19)=L19,"T","F") -> T
B20: AtR | C20: Ph 3 | F20: Package Release [Complete LoD 350 by Q1] | G20: =SUM(G21,G41,G61,G71) -> 3.2133416 | H20: =SUM(H21,H41,H61,H71) -> 2.5304736 | I20: =SUM(I21,I41,I61,I71) -> 0.68286799 | J20: =SUM(J21,J41,J61,J71) -> 0 | K20: =SUM(K21,K41,K61,K71) -> 0 | L20: =SUM(M20:P20) -> 53 | M20: =SUM(M21,M41,M61,M71) -> 42 | N20: =SUM(N21,N41,N61,N71) -> 11 | O20: =SUM(O21,O41,O61,O71) -> 0 | P20: =SUM(P21,P41,P61,P71) -> 0 | R20: =IF(SUM(M20:P20)=L20,"T","F") -> T
B21: AtR | C21: Ph 3 | D21: Architecture | F21: Package Release [Complete LoD 350 by Q1] | G21: =SUM(G22:G40) -> 2.2814903 | H21: =SUM(H22:H40) -> 1.8087698 | I21: =SUM(I22:I40) -> 0.47272049 | J21: =SUM(J22:J40) -> 0 | K21: =SUM(K22:K40) -> 0 | L21: =SUM(M21:P21) -> 19 | M21: =SUM(M22:M40) -> 15 | N21: =SUM(N22:N40) -> 4 | O21: =SUM(O22:O40) -> 0 | P21: =SUM(P22:P40) -> 0 | Q21: =SUM(Q22:Q40) -> 0 | R21: =IF(SUM(M21:P21)=L21,"T","F") -> T
B22: AtR | C22: Ph 3 | D22: Architecture | E22: Saji A | F22: Contract + Design brief | G22: 0.27398367 | H22: =IF(M22=1,$G22,"") -> 0.27398367 | I22: =IF(N22=1,$G22,"") | J22: =IF(O22=1,$G22,"") | K22: =IF(P22=1,$G22,"") | L22: =SUM(M22:P22) -> 1 | M22: 1 | R22: =IF(SUM(M22:P22)=L22,"T","F") -> T
B23: AtR | C23: Ph 3 | D23: Architecture | E23: Saji A | F23: Schematic Concept | G23: 0.27398367 | H23: =IF(M23=1,$G23,"") -> 0.27398367 | I23: =IF(N23=1,$G23,"") | J23: =IF(O23=1,$G23,"") | K23: =IF(P23=1,$G23,"") | L23: =SUM(M23:P23) -> 1 | M23: 1 | R23: =IF(SUM(M23:P23)=L23,"T","F") -> T
B24: AtR | C24: Ph 3 | D24: Architecture | E24: Saji A | F24: Approvals | G24: 0.13699183 | H24: =IF(M24=1,$G24,"") -> 0.13699183 | I24: =IF(N24=1,$G24,"") | J24: =IF(O24=1,$G24,"") | K24: =IF(P24=1,$G24,"") | L24: =SUM(M24:P24) -> 1 | M24: 1 | R24: =IF(SUM(M24:P24)=L24,"T","F") -> T
B25: AtR | C25: Ph 3 | D25: Architecture | E25: Saji A | F25: Pre Construction Set | G25: 0.27398367 | H25: =IF(M25=1,$G25,"") -> 0.27398367 | I25: =IF(N25=1,$G25,"") | J25: =IF(O25=1,$G25,"") | K25: =IF(P25=1,$G25,"") | L25: =SUM(M25:P25) -> 1 | M25: 1 | R25: =IF(SUM(M25:P25)=L25,"T","F") -> T
B26: AtR | C26: Ph 3 | D26: Architecture | E26: Saji A | F26: Home Products - V45 Default and it's variants | G26: 0.36 | H26: =IF(M26=1,$G26,"") -> 0.36 | I26: =IF(N26=1,$G26,"") | J26: =IF(O26=1,$G26,"") | K26: =IF(P26=1,$G26,"") | L26: =SUM(M26:P26) -> 1 | M26: 1 | R26: =IF(SUM(M26:P26)=L26,"T","F") -> T
B27: AtR | C27: Ph 3 | D27: Architecture | E27: Saji A | F27: Home Products - V80 Default and it's variants | G27: 0.36 | H27: =IF(M27=1,$G27,"") | I27: =IF(N27=1,$G27,"") -> 0.36 | J27: =IF(O27=1,$G27,"") | K27: =IF(P27=1,$G27,"") | L27: =SUM(N27:P27) -> 1 | N27: 1 | R27: =IF(SUM(N27:P27)=L27,"T","F") -> T
B28: AtR | C28: Ph 3 | D28: Architecture | E28: Saji A | F28: Villa Block 33 - Foundations and Sub-Grade Structure | G28: 0.043982696 | H28: =IF(M28=1,$G28,"") -> 0.043982696 | I28: =IF(N28=1,$G28,"") | J28: =IF(O28=1,$G28,"") | K28: =IF(P28=1,$G28,"") | L28: =SUM(M28:P28) -> 1 | M28: 1 | R28: =IF(SUM(M28:P28)=L28,"T","F") -> T
B29: AtR | C29: Ph 3 | D29: Architecture | E29: Saji A | F29: Villa Block 34 - Foundations and Sub-Grade Structure | G29: 0.043982696 | H29: =IF(M29=1,$G29,"") -> 0.043982696 | I29: =IF(N29=1,$G29,"") | J29: =IF(O29=1,$G29,"") | K29: =IF(P29=1,$G29,"") | L29: =SUM(M29:P29) -> 1 | M29: 1 | R29: =IF(SUM(M29:P29)=L29,"T","F") -> T
B30: AtR | C30: Ph 3 | D30: Architecture | E30: Saji A | F30: Villa Block 29 - Foundations and Sub-Grade Structure | G30: 0.065974043 | H30: =IF(M30=1,$G30,"") -> 0.065974043 | L30: =SUM(M30:P30) -> 1 | M30: 1
B31: AtR | C31: Ph 3 | D31: Architecture | E31: Saji A | F31: Villa Block 29 - Building Envelope + Plot Development | G31: 0.065974043 | H31: =IF(M31=1,$G31,"") -> 0.065974043 | I31: =IF(N31=1,$G31,"") | J31: =IF(O31=1,$G31,"") | K31: =IF(P31=1,$G31,"") | L31: =SUM(M31:P31) -> 1 | M31: 1 | R31: =IF(SUM(M31:P31)=L31,"T","F") -> T
B32: AtR | C32: Ph 3 | D32: Architecture | E32: Saji A | F32: Villa Block 30 - Foundations and Sub-Grade Structure | G32: 0.065974043 | H32: =IF(M32=1,$G32,"") -> 0.065974043 | L32: =SUM(M32:P32) -> 1 | M32: 1
B33: AtR | C33: Ph 3 | D33: Architecture | E33: Saji A | F33: Villa Block 30 - Building Envelope + Plot Development | G33: 0.065974043 | H33: =IF(M33=1,$G33,"") -> 0.065974043 | I33: =IF(N33=1,$G33,"") | J33: =IF(O33=1,$G33,"") | K33: =IF(P33=1,$G33,"") | L33: =SUM(M33:P33) -> 1 | M33: 1 | R33: =IF(SUM(M33:P33)=L33,"T","F") -> T
B34: AtR | C34: Ph 3 | D34: Architecture | E34: Saji A | F34: Villa Block 31 - Building Envelope + Plot Development | G34: 0.014660899 | H34: =IF(M34=1,$G34,"") -> 0.014660899 | I34: =IF(N34=1,$G34,"") | J34: =IF(O34=1,$G34,"") | K34: =IF(P34=1,$G34,"") | L34: =SUM(M34:P34) -> 1 | M34: 1 | R34: =IF(SUM(M34:P34)=L34,"T","F") -> T
B35: AtR | C35: Ph 3 | D35: Architecture | E35: Saji A | F35: Villa Block 32 - Building Envelope + Plot Development | G35: 0.029321797 | H35: =IF(M35=1,$G35,"") -> 0.029321797 | I35: =IF(N35=1,$G35,"") | J35: =IF(O35=1,$G35,"") | K35: =IF(P35=1,$G35,"") | L35: =SUM(M35:P35) -> 1 | M35: 1 | R35: =IF(SUM(M35:P35)=L35,"T","F") -> T
B36: AtR | C36: Ph 3 | D36: Architecture | E36: Saji A | F36: Villa Block 33 - Building Envelope + Plot Development | G36: 0.043982696 | H36: =IF(M36=1,$G36,"") | I36: =IF(N36=1,$G36,"") -> 0.043982696 | J36: =IF(O36=1,$G36,"") | K36: =IF(P36=1,$G36,"") | L36: =SUM(M36:P36) -> 1 | N36: 1 | R36: =IF(SUM(M36:P36)=L36,"T","F") -> T
B37: AtR | C37: Ph 3 | D37: Architecture | E37: Saji A | F37: Villa Block 34 - Building Envelope + Plot Development | G37: 0.043982696 | H37: =IF(M37=1,$G37,"") -> 0.043982696 | I37: =IF(N37=1,$G37,"") | J37: =IF(O37=1,$G37,"") | K37: =IF(P37=1,$G37,"") | L37: =SUM(M37:P37) -> 1 | M37: 1 | R37: =IF(SUM(M37:P37)=L37,"T","F") -> T
B38: AtR | C38: Ph 3 | D38: Architecture | E38: Saji A | F38: Master Plan - Master Plan | G38: 0.05 | H38: =IF(M38=1,$G38,"") -> 0.05 | I38: =IF(N38=1,$G38,"") | J38: =IF(O38=1,$G38,"") | K38: =IF(P38=1,$G38,"") | L38: =SUM(M38:P38) -> 1 | M38: 1 | R38: =IF(SUM(M38:P38)=L38,"T","F") -> T
B39: AtR | C39: Ph 3 | D39: Architecture | E39: Saji A | F39: Site Development - 02 Road Works | G39: 0.05 | H39: =IF(M39=1,$G39,"") | I39: =IF(N39=1,$G39,"") -> 0.05 | J39: =IF(O39=1,$G39,"") | K39: =IF(P39=1,$G39,"") | L39: =SUM(M39:P39) -> 1 | N39: 1 | R39: =IF(SUM(M39:P39)=L39,"T","F") -> T
B40: AtR | C40: Ph 3 | D40: Architecture | E40: Saji A | F40: Site Development - 06 Landscape | G40: 0.018737796 | H40: =IF(M40=1,$G40,"") | I40: =IF(N40=1,$G40,"") -> 0.018737796 | J40: =IF(O40=1,$G40,"") | K40: =IF(P40=1,$G40,"") | L40: =SUM(M40:P40) -> 1 | N40: 1 | R40: =IF(SUM(M40:P40)=L40,"T","F") -> T
B41: AtR | C41: Ph 3 | D41: Structural | F41: Package Release [Complete LoD 350 by Q1] | G41: =SUM(G42:G60) -> 0.43466801 | H41: =SUM(H42:H60) -> 0.35597209 | I41: =SUM(I42:I60) -> 0.07869592 | J41: =SUM(J42:J60) -> 0 | K41: =SUM(K42:K60) -> 0 | L41: =SUM(M41:P41) -> 19 | M41: =SUM(M42:M60) -> 15 | N41: =SUM(N42:N60) -> 4 | O41: =SUM(O42:O60) -> 0 | P41: =SUM(P42:P60) -> 0 | R41: =IF(SUM(M41:P41)=L41,"T","F") -> T
B42: AtR | C42: Ph 3 | D42: Structural | E42: Prakash C | F42: Schematic Concept | G42: 0.093421604 | H42: =IF(M42=1,$G42,"") -> 0.093421604 | I42: =IF(N42=1,$G42,"") | J42: =IF(O42=1,$G42,"") | K42: =IF(P42=1,$G42,"") | L42: =SUM(M42:P42) -> 1 | M42: 1 | R42: =IF(SUM(M42:P42)=L42,"T","F") -> T
B43: AtR | C43: Ph 3 | D43: Structural | E43: Prakash C | F43: Pre Construction Set | G43: 0.093421604 | H43: =IF(M43=1,$G43,"") -> 0.093421604 | I43: =IF(N43=1,$G43,"") | J43: =IF(O43=1,$G43,"") | K43: =IF(P43=1,$G43,"") | L43: =SUM(M43:P43) -> 1 | M43: 1 | R43: =IF(SUM(M43:P43)=L43,"T","F") -> T
...

Sheet Smry
B4: Design Lead | D4: Project | F4: Phase | H4: Pkgs [2026] | I4: Q1 | J4: Q2 | K4: Q3 | L4: Q4 | N4: Billing [2026] | O4: Q1 | P4: Q2 | Q4: Q3 | R4: Q4
B8: Total Packages | H8: =SUM(I8+J8+K8+L8) -> 1143 | I8: =SUM(I10+I19+I62+I100+I110+I124+I140+I147+I155) -> 403 | J8: =SUM(J10+J19+J62+J100+J110+J124+J140+J147+J155) -> 235 | K8: =SUM(K10+K19+K62+K100+K110+K124+K140+K147+K155) -> 275 | L8: =SUM(L10+L19+L62+L100+L110+L124+L140+L147+L155) -> 230 | N8: =SUM(O8+P8+Q8+R8) -> 287.21484 | O8: =SUM(O10+O19+O62+O100+O110+O124+O140+O147+O155) -> 115.81945 | P8: =SUM(P10+P19+P62+P100+P110+P124+P140+P147+P155) -> 60.026291 | Q8: =SUM(Q10+Q19+Q62+Q100+Q110+Q124+Q140+Q147+Q155) -> 56.528406 | R8: =SUM(R10+R19+R62+R100+R110+R124+R140+R147+R155) -> 54.840694
B10: Saji A | H10: =SUM(I10:L10) -> 60 | I10: =SUM(I12:I17) -> 45 | J10: =SUM(J12:J17) -> 7 | K10: =SUM(K12:K17) -> 5 | L10: =SUM(L12:L17) -> 3 | N10: =SUM(O10:R10) -> 39.650772 | O10: =SUM(O12:O17) -> 12.655551 | P10: =SUM(P12:P17) -> 6.5577205 | Q10: =SUM(Q12:Q17) -> 8.83 | R10: =SUM(R12:R17) -> 11.6075
B12: Saji A | D12: AtR | F12: Ph 1, 2a, 2b | H12: =SUM(I12:L12) -> 2 | I12: =SUMIFS('Goals 2026'!M:M,'Goals 2026'!B:B,Smry!D12,'Goals 2026'!C:C,Smry!F12,'Goals 2026'!E:E,Smry!$B$10) -> 2 | J12: =SUMIFS('Goals 2026'!N:N,'Goals 2026'!B:B,Smry!D12,'Goals 2026'!C:C,Smry!F12,'Goals 2026'!E:E,Smry!$B$10) -> 0 | K12: =SUMIFS('Goals 2026'!O:O,'Goals 2026'!B:B,Smry!D12,'Goals 2026'!C:C,Smry!F12,'Goals 2026'!E:E,Smry!$B$10) -> 0 | L12: =SUMIFS('Goals 2026'!P:P,'Goals 2026'!B:B,Smry!D12,'Goals 2026'!C:C,Smry!F12,'Goals 2026'!E:E,Smry!$B$10) -> 0 | N12: =SUM(O12:R12) -> 0.31537704 | O12: =SUMIFS('Goals 2026'!H:H,'Goals 2026'!B:B,Smry!D12,'Goals 2026'!C:C,Smry!F12,'Goals 2026'!E:E,Smry!$B$10) -> 0.31537704 | P12: =SUMIFS('Goals 2026'!I:I,'Goals 2026'!B:B,Smry!D12,'Goals 2026'!C:C,Smry!F12,'Goals 2026'!E:E,Smry!$B$10) -> 0 | Q12: =SUMIFS('Goals 2026'!J:J,'Goals 2026'!B:B,Smry!D12,'Goals 2026'!C:C,Smry!F12,'Goals 2026'!E:E,Smry!$B$10) -> 0 | R12: =SUMIFS('Goals 2026'!K:K,'Goals 2026'!B:B,Smry!D12,'Goals 2026'!C:C,Smry!F12,'Goals 2026'!E:E,Smry!$B$10) -> 0
B13: Saji A | D13: AtR | F13: Ph 2c | H13: =SUM(I13:L13) -> 2 | I13: =SUMIFS('Goals 2026'!M:M,'Goals 2026'!B:B,Smry!D13,'Goals 2026'!C:C,Smry!F13,'Goals 2026'!E:E,Smry!$B$10) -> 2 | J13: =SUMIFS('Goals 2026'!N:N,'Goals 2026'!B:B,Smry!D13,'Goals 2026'!C:C,Smry!F13,'Goals 2026'!E:E,Smry!$B$10) -> 0 | K13: =SUMIFS('Goals 2026'!O:O,'Goals 2026'!B:B,Smry!D13,'Goals 2026'!C:C,Smry!F13,'Goals 2026'!E:E,Smry!$B$10) -> 0 | L13: =SUMIFS('Goals 2026'!P:P,'Goals 2026'!B:B,Smry!D13,'Goals 2026'!C:C,Smry!F13,'Goals 2026'!E:E,Smry!$B$10) -> 0 | N13: =SUM(O13:R13) -> 0.081654546 | O13: =SUMIFS('Goals 2026'!H:H,'Goals 2026'!B:B,Smry!D13,'Goals 2026'!C:C,Smry!F13,'Goals 2026'!E:E,Smry!$B$10) -> 0.081654546 | P13: =SUMIFS('Goals 2026'!I:I,'Goals 2026'!B:B,Smry!D13,'Goals 2026'!C:C,Smry!F13,'Goals 2026'!E:E,Smry!$B$10) -> 0 | Q13: =SUMIFS('Goals 2026'!J:J,'Goals 2026'!B:B,Smry!D13,'Goals 2026'!C:C,Smry!F13,'Goals 2026'!E:E,Smry!$B$10) -> 0 | R13: =SUMIFS('Goals 2026'!K:K,'Goals 2026'!B:B,Smry!D13,'Goals 2026'!C:C,Smry!F13,'Goals 2026'!E:E,Smry!$B$10) -> 0
B14: Saji A | D14: AtR | F14: Ph 3 | H14: =SUM(I14:L14) -> 19 | I14: =SUMIFS('Goals 2026'!M:M,'Goals 2026'!B:B,Smry!D14,'Goals 2026'!C:C,Smry!F14,'Goals 2026'!E:E,Smry!$B$10) -> 15 | J14: =SUMIFS('Goals 2026'!N:N,'Goals 2026'!B:B,Smry!D14,'Goals 2026'!C:C,Smry!F14,'Goals 2026'!E:E,Smry!$B$10) -> 4 | K14: =SUMIFS('Goals 2026'!O:O,'Goals 2026'!B:B,Smry!D14,'Goals 2026'!C:C,Smry!F14,'Goals 2026'!E:E,Smry!$B$10) -> 0 | L14: =SUMIFS('Goals 2026'!P:P,'Goals 2026'!B:B,Smry!D14,'Goals 2026'!C:C,Smry!F14,'Goals 2026'!E:E,Smry!$B$10) -> 0 | N14: =SUM(O14:R14) -> 2.2814903 | O14: =SUMIFS('Goals 2026'!H:H,'Goals 2026'!B:B,Smry!D14,'Goals 2026'!C:C,Smry!F14,'Goals 2026'!E:E,Smry!$B$10) -> 1.8087698 | P14: =SUMIFS('Goals 2026'!I:I,'Goals 2026'!B:B,Smry!D14,'Goals 2026'!C:C,Smry!F14,'Goals 2026'!E:E,Smry!$B$10) -> 0.47272049 | Q14: =SUMIFS('Goals 2026'!J:J,'Goals 2026'!B:B,Smry!D14,'Goals 2026'!C:C,Smry!F14,'Goals 2026'!E:E,Smry!$B$10) -> 0 | R14: =SUMIFS('Goals 2026'!K:K,'Goals 2026'!B:B,Smry!D14,'Goals 2026'!C:C,Smry!F14,'Goals 2026'!E:E,Smry!$B$10) -> 0
B15: Saji A | D15: PoaRR-Res | F15: Res | H15: =SUM(I15:L15) -> 8 | I15: =SUMIFS('Goals 2026'!M:M,'Goals 2026'!B:B,Smry!D15,'Goals 2026'!C:C,Smry!F15,'Goals 2026'!E:E,Smry!$B$10) -> 8 | J15: =SUMIFS('Goals 2026'!N:N,'Goals 2026'!B:B,Smry!D15,'Goals 2026'!C:C,Smry!F15,'Goals 2026'!E:E,Smry!$B$10) -> 0 | K15: =SUMIFS('Goals 2026'!O:O,'Goals 2026'!B:B,Smry!D15,'Goals 2026'!C:C,Smry!F15,'Goals 2026'!E:E,Smry!$B$10) -> 0 | L15: =SUMIFS('Goals 2026'!P:P,'Goals 2026'!B:B,Smry!D15,'Goals 2026'!C:C,Smry!F15,'Goals 2026'!E:E,Smry!$B$10) -> 0 | N15: =SUM(O15:R15) -> 3.3659 | O15: =SUMIFS('Goals 2026'!H:H,'Goals 2026'!B:B,Smry!D15,'Goals 2026'!C:C,Smry!F15,'Goals 2026'!E:E,Smry!$B$10) -> 3.3659 | P15: =SUMIFS('Goals 2026'!I:I,'Goals 2026'!B:B,Smry!D15,'Goals 2026'!C:C,Smry!F15,'Goals 2026'!E:E,Smry!$B$10) -> 0 | Q15: =SUMIFS('Goals 2026'!J:J,'Goals 2026'!B:B,Smry!D15,'Goals 2026'!C:C,Smry!F15,'Goals 2026'!E:E,Smry!$B$10) -> 0 | R15: =SUMIFS('Goals 2026'!K:K,'Goals 2026'!B:B,Smry!D15,'Goals 2026'!C:C,Smry!F15,'Goals 2026'!E:E,Smry!$B$10) -> 0
B16: Saji A | D16: PoaRR-T08 | F16: T08 | H16: =SUM(I16:L16) -> 23 | I16: =SUMIFS('Goals 2026'!M:M,'Goals 2026'!B:B,Smry!D16,'Goals 2026'!C:C,Smry!F16,'Goals 2026'!E:E,Smry!$B$10) -> 18 | J16: =SUMIFS('Goals 2026'!N:N,'Goals 2026'!B:B,Smry!D16,'Goals 2026'!C:C,Smry!F16,'Goals 2026'!E:E,Smry!$B$10) -> 2 | K16: =SUMIFS('Goals 2026'!O:O,'Goals 2026'!B:B,Smry!D16,'Goals 2026'!C:C,Smry!F16,'Goals 2026'!E:E,Smry!$B$10) -> 3 | L16: =SUMIFS('Goals 2026'!P:P,'Goals 2026'!B:B,Smry!D16,'Goals 2026'!C:C,Smry!F16,'Goals 2026'!E:E,Smry!$B$10) -> 0 | N16: =SUM(O16:R16) -> 7.30385 | O16: =SUMIFS('Goals 2026'!H:H,'Goals 2026'!B:B,Smry!D16,'Goals 2026'!C:C,Smry!F16,'Goals 2026'!E:E,Smry!$B$10) -> 7.08385 | P16: =SUMIFS('Goals 2026'!I:I,'Goals 2026'!B:B,Smry!D16,'Goals 2026'!C:C,Smry!F16,'Goals 2026'!E:E,Smry!$B$10) -> 0.12 | Q16: =SUMIFS('Goals 2026'!J:J,'Goals 2026'!B:B,Smry!D16,'Goals 2026'!C:C,Smry!F16,'Goals 2026'!E:E,Smry!$B$10) -> 0.1 | R16: =SUMIFS('Goals 2026'!K:K,'Goals 2026'!B:B,Smry!D16,'Goals 2026'!C:C,Smry!F16,'Goals 2026'!E:E,Smry!$B$10) -> 0
B17: Saji A | D17: TR Mills | F17: TR Mills | H17: =SUM(I17:L17) -> 6 | I17: =SUMIFS('Goals 2026'!M:M,'Goals 2026'!B:B,Smry!D17,'Goals 2026'!C:C,Smry!F17,'Goals 2026'!E:E,Smry!$B$10) -> 0 | J17: =SUMIFS('Goals 2026'!N:N,'Goals 2026'!B:B,Smry!D17,'Goals 2026'!C:C,Smry!F17,'Goals 2026'!E:E,Smry!$B$10) -> 1 | K17: =SUMIFS('Goals 2026'!O:O,'Goals 2026'!B:B,Smry!D17,'Goals 2026'!C:C,Smry!F17,'Goals 2026'!E:E,Smry!$B$10) -> 2 | L17: =SUMIFS('Goals 2026'!P:P,'Goals 2026'!B:B,Smry!D17,'Goals 2026'!C:C,Smry!F17,'Goals 2026'!E:E,Smry!$B$10) -> 3 | N17: =SUM(O17:R17) -> 26.3025 | O17: =SUMIFS('Goals 2026'!H:H,'Goals 2026'!B:B,Smry!D17,'Goals 2026'!C:C,Smry!F17,'Goals 2026'!E:E,Smry!$B$10) -> 0 | P17: =SUMIFS('Goals 2026'!I:I,'Goals 2026'!B:B,Smry!D17,'Goals 2026'!C:C,Smry!F17,'Goals 2026'!E:E,Smry!$B$10) -> 5.965 | Q17: =SUMIFS('Goals 2026'!J:J,'Goals 2026'!B:B,Smry!D17,'Goals 2026'!C:C,Smry!F17,'Goals 2026'!E:E,Smry!$B$10) -> 8.73 | R17: =SUMIFS('Goals 2026'!K:K,'Goals 2026'!B:B,Smry!D17,'Goals 2026'!C:C,Smry!F17,'Goals 2026'!E:E,Smry!$B$10) -> 11.6075
B19: Prakash C | H19: =SUM(I19:L19) -> 309 | I19: =SUM(I21:I60) -> 114 | J19: =SUM(J21:J60) -> 64 | K19: =SUM(K21:K60) -> 72 | L19: =SUM(L21:L60) -> 59 | N19: =SUM(O19:R19) -> 54.59763 | O19: =SUM(O21:O60) -> 21.01135 | P19: =SUM(P21:P60) -> 12.567651 | Q19: =SUM(Q21:Q60) -> 10.472304 | R19: =SUM(R21:R60) -> 10.546325
B21: Prakash C | D21: AtR | F21: Ph 1, 2a, 2b | H21: =SUM(I21:L21) -> 1 | I21: =SUMIFS('Goals 2026'!M:M,'Goals 2026'!B:B,Smry!D21,'Goals 2026'!C:C,Smry!F21,'Goals 2026'!E:E,Smry!$B$19) -> 1 | J21: =SUMIFS('Goals 2026'!N:N,'Goals 2026'!B:B,Smry!D21,'Goals 2026'!C:C,Smry!F21,'Goals 2026'!E:E,Smry!$B$19) -> 0 | K21: =SUMIFS('Goals 2026'!O:O,'Goals 2026'!B:B,Smry!D21,'Goals 2026'!C:C,Smry!F21,'Goals 2026'!E:E,Smry!$B$19) -> 0 | L21: =SUMIFS('Goals 2026'!P:P,'Goals 2026'!B:B,Smry!D21,'Goals 2026'!C:C,Smry!F21,'Goals 2026'!E:E,Smry!$B$19) -> 0 | N21: =SUM(O21:R21) -> 0.0052867303 | O21: =SUMIFS('Goals 2026'!H:H,'Goals 2026'!B:B,Smry!D21,'Goals 2026'!C:C,Smry!F21,'Goals 2026'!E:E,Smry!$B$19) -> 0.0052867303 | P21: =SUMIFS('Goals 2026'!I:I,'Goals 2026'!B:B,Smry!D21,'Goals 2026'!C:C,Smry!F21,'Goals 2026'!E:E,Smry!$B$19) -> 0 | Q21: =SUMIFS('Goals 2026'!J:J,'Goals 2026'!B:B,Smry!D21,'Goals 2026'!C:C,Smry!F21,'Goals 2026'!E:E,Smry!$B$19) -> 0 | R21: =SUMIFS('Goals 2026'!K:K,'Goals 2026'!B:B,Smry!D21,'Goals 2026'!C:C,Smry!F21,'Goals 2026'!E:E,Smry!$B$19) -> 0
B22: Prakash C | D22: AtR | F22: Ph 2c | H22: =SUM(I22:L22) -> 2 | I22: =SUMIFS('Goals 2026'!M:M,'Goals 2026'!B:B,Smry!D22,'Goals 2026'!C:C,Smry!F22,'Goals 2026'!E:E,Smry!$B$19) -> 2 | J22: =SUMIFS('Goals 2026'!N:N,'Goals 2026'!B:B,Smry!D22,'Goals 2026'!C:C,Smry!F22,'Goals 2026'!E:E,Smry!$B$19) -> 0 | K22: =SUMIFS('Goals 2026'!O:O,'Goals 2026'!B:B,Smry!D22,'Goals 2026'!C:C,Smry!F22,'Goals 2026'!E:E,Smry!$B$19) -> 0 | L22: =SUMIFS('Goals 2026'!P:P,'Goals 2026'!B:B,Smry!D22,'Goals 2026'!C:C,Smry!F22,'Goals 2026'!E:E,Smry!$B$19) -> 0 | N22: =SUM(O22:R22) -> 0.016064217 | O22: =SUMIFS('Goals 2026'!H:H,'Goals 2026'!B:B,Smry!D22,'Goals 2026'!C:C,Smry!F22,'Goals 2026'!E:E,Smry!$B$19) -> 0.016064217 | P22: =SUMIFS('Goals 2026'!I:I,'Goals 2026'!B:B,Smry!D22,'Goals 2026'!C:C,Smry!F22,'Goals 2026'!E:E,Smry!$B$19) -> 0 | Q22: =SUMIFS('Goals 2026'!J:J,'Goals 2026'!B:B,Smry!D22,'Goals 2026'!C:C,Smry!F22,'Goals 2026'!E:E,Smry!$B$19) -> 0 | R22: =SUMIFS('Goals 2026'!K:K,'Goals 2026'!B:B,Smry!D22,'Goals 2026'!C:C,Smry!F22,'Goals 2026'!E:E,Smry!$B$19) -> 0
B23: Prakash C | D23: AtR | F23: Ph 3 | H23: =SUM(I23:L23) -> 19 | I23: =SUMIFS('Goals 2026'!M:M,'Goals 2026'!B:B,Smry!D23,'Goals 2026'!C:C,Smry!F23,'Goals 2026'!E:E,Smry!$B$19) -> 15 | J23: =SUMIFS('Goals 2026'!N:N,'Goals 2026'!B:B,Smry!D23,'Goals 2026'!C:C,Smry!F23,'Goals 2026'!E:E,Smry!$B$19) -> 4 | K23: =SUMIFS('Goals 2026'!O:O,'Goals 2026'!B:B,Smry!D23,'Goals 2026'!C:C,Smry!F23,'Goals 2026'!E:E,Smry!$B$19) -> 0 | L23: =SUMIFS('Goals 2026'!P:P,'Goals 2026'!B:B,Smry!D23,'Goals 2026'!C:C,Smry!F23,'Goals 2026'!E:E,Smry!$B$19) -> 0 | N23: =SUM(O23:R23) -> 0.43466801 | O23: =SUMIFS('Goals 2026'!H:H,'Goals 2026'!B:B,Smry!D23,'Goals 2026'!C:C,Smry!F23,'Goals 2026'!E:E,Smry!$B$19) -> 0.35597209 | P23: =SUMIFS('Goals 2026'!I:I,'Goals 2026'!B:B,Smry!D23,'Goals 2026'!C:C,Smry!F23,'Goals 2026'!E:E,Smry!$B$19) -> 0.07869592 | Q23: =SUMIFS('Goals 2026'!J:J,'Goals 2026'!B:B,Smry!D23,'Goals 2026'!C:C,Smry!F23,'Goals 2026'!E:E,Smry!$B$19) -> 0 | R23: =SUMIFS('Goals 2026'!K:K,'Goals 2026'!B:B,Smry!D23,'Goals 2026'!C:C,Smry!F23,'Goals 2026'!E:E,Smry!$B$19) -> 0
B24: Prakash C | D24: AtR - C | F24: Com | H24: =SUM(I24:L24) -> 6 | I24: =SUMIFS('Goals 2026'!M:M,'Goals 2026'!B:B,Smry!D24,'Goals 2026'!C:C,Smry!F24,'Goals 2026'!E:E,Smry!$B$19) -> 4 | J24: =SUMIFS('Goals 2026'!N:N,'Goals 2026'!B:B,Smry!D24,'Goals 2026'!C:C,Smry!F24,'Goals 2026'!E:E,Smry!$B$19) -> 1 | K24: =SUMIFS('Goals 2026'!O:O,'Goals 2026'!B:B,Smry!D24,'Goals 2026'!C:C,Smry!F24,'Goals 2026'!E:E,Smry!$B$19) -> 1 | L24: =SUMIFS('Goals 2026'!P:P,'Goals 2026'!B:B,Smry!D24,'Goals 2026'!C:C,Smry!F24,'Goals 2026'!E:E,Smry!$B$19) -> 0 | N24: =SUM(O24:R24) -> 0.80123917 | O24: =SUMIFS('Goals 2026'!H:H,'Goals 2026'!B:B,Smry!D24,'Goals 2026'!C:C,Smry!F24,'Goals 2026'!E:E,Smry!$B$19) -> 0.4138985 | P24: =SUMIFS('Goals 2026'!I:I,'Goals 2026'!B:B,Smry!D24,'Goals 2026'!C:C,Smry!F24,'Goals 2026'!E:E,Smry!$B$19) -> 0.25822711 | Q24: =SUMIFS('Goals 2026'!J:J,'Goals 2026'!B:B,Smry!D24,'Goals 2026'!C:C,Smry!F24,'Goals 2026'!E:E,Smry!$B$19) -> 0.12911356 | R24: =SUMIFS('Goals 2026'!K:K,'Goals 2026'!B:B,Smry!D24,'Goals 2026'!C:C,Smry!F24,'Goals 2026'!E:E,Smry!$B$19) -> 0
B25: Prakash C | D25: PoaRR-Res | F25: Res | H25: =SUM(I25:L25) -> 3 | I25: =SUMIFS('Goals 2026'!M:M,'Goals 2026'!B:B,Smry!D25,'Goals 2026'!C:C,Smry!F25,'Goals 2026'!E:E,Smry!$B$19) -> 3 | J25: =SUMIFS('Goals 2026'!N:N,'Goals 2026'!B:B,Smry!D25,'Goals 2026'!C:C,Smry!F25,'Goals 2026'!E:E,Smry!$B$19) -> 0 | K25: =SUMIFS('Goals 2026'!O:O,'Goals 2026'!B:B,Smry!D25,'Goals 2026'!C:C,Smry!F25,'Goals 2026'!E:E,Smry!$B$19) -> 0 | L25: =SUMIFS('Goals 2026'!P:P,'Goals 2026'!B:B,Smry!D25,'Goals 2026'!C:C,Smry!F25,'Goals 2026'!E:E,Smry!$B$19) -> 0 | N25: =SUM(O25:R25) -> 0.36 | O25: =SUMIFS('Goals 2026'!H:H,'Goals 2026'!B:B,Smry!D25,'Goals 2026'!C:C,Smry!F25,'Goals 2026'!E:E,Smry!$B$19) -> 0.36 | P25: =SUMIFS('Goals 2026'!I:I,'Goals 2026'!B:B,Smry!D25,'Goals 2026'!C:C,Smry!F25,'Goals 2026'!E:E,Smry!$B$19) -> 0 | Q25: =SUMIFS('Goals 2026'!J:J,'Goals 2026'!B:B,Smry!D25,'Goals 2026'!C:C,Smry!F25,'Goals 2026'!E:E,Smry!$B$19) -> 0 | R25: =SUMIFS('Goals 2026'!K:K,'Goals 2026'!B:B,Smry!D25,'Goals 2026'!C:C,Smry!F25,'Goals 2026'!E:E,Smry!$B$19) -> 0
B26: Prakash C | D26: PoaRR-T08 | F26: T08 | H26: =SUM(I26:L26) -> 8 | I26: =SUMIFS('Goals 2026'!M:M,'Goals 2026'!B:B,Smry!D26,'Goals 2026'!C:C,Smry!F26,'Goals 2026'!E:E,Smry!$B$19) -> 8 | J26: =SUMIFS('Goals 2026'!N:N,'Goals 2026'!B:B,Smry!D26,'Goals 2026'!C:C,Smry!F26,'Goals 2026'!E:E,Smry!$B$19) -> 0 | K26: =SUMIFS('Goals 2026'!O:O,'Goals 2026'!B:B,Smry!D26,'Goals 2026'!C:C,Smry!F26,'Goals 2026'!E:E,Smry!$B$19) -> 0 | L26: =SUMIFS('Goals 2026'!P:P,'Goals 2026'!B:B,Smry!D26,'Goals 2026'!C:C,Smry!F26,'Goals 2026'!E:E,Smry!$B$19) -> 0 | N26: =SUM(O26:R26) -> 2.1 | O26: =SUMIFS('Goals 2026'!H:H,'Goals 2026'!B:B,Smry!D26,'Goals 2026'!C:C,Smry!F26,'Goals 2026'!E:E,Smry!$B$19) -> 2.1 | P26: =SUMIFS('Goals 2026'!I:I,'Goals 2026'!B:B,Smry!D26,'Goals 2026'!C:C,Smry!F26,'Goals 2026'!E:E,Smry!$B$19) -> 0 | Q26: =SUMIFS('Goals 2026'!J:J,'Goals 2026'!B:B,Smry!D26,'Goals 2026'!C:C,Smry!F26,'Goals 2026'!E:E,Smry!$B$19) -> 0 | R26: =SUMIFS('Goals 2026'!K:K,'Goals 2026'!B:B,Smry!D26,'Goals 2026'!C:C,Smry!F26,'Goals 2026'!E:E,Smry!$B$19) -> 0
B27: Prakash C | D27: ITQE-Ph1 | F27: Ph 1 | H27: =SUM(I27:L27) -> 3 | I27: =SUMIFS('Goals 2026'!M:M,'Goals 2026'!B:B,Smry!D27,'Goals 2026'!C:C,Smry!F27,'Goals 2026'!E:E,Smry!$B$19) -> 3 | J27: =SUMIFS('Goals 2026'!N:N,'Goals 2026'!B:B,Smry!D27,'Goals 2026'!C:C,Smry!F27,'Goals 2026'!E:E,Smry!$B$19) -> 0 | K27: =SUMIFS('Goals 2026'!O:O,'Goals 2026'!B:B,Smry!D27,'Goals 2026'!C:C,Smry!F27,'Goals 2026'!E:E,Smry!$B$19) -> 0 | L27: =SUMIFS('Goals 2026'!P:P,'Goals 2026'!B:B,Smry!D27,'Goals 2026'!C:C,Smry!F27,'Goals 2026'!E:E,Smry!$B$19) -> 0 | N27: =SUM(O27:R27) -> 0.084072168 | O27: =SUMIFS('Goals 2026'!H:H,'Goals 2026'!B:B,Smry!D27,'Goals 2026'!C:C,Smry!F27,'Goals 2026'!E:E,Smry!$B$19) -> 0.084072168 | P27: =SUMIFS('Goals 2026'!I:I,'Goals 2026'!B:B,Smry!D27,'Goals 2026'!C:C,Smry!F27,'Goals 2026'!E:E,Smry!$B$19) -> 0 | Q27: =SUMIFS('Goals 2026'!J:J,'Goals 2026'!B:B,Smry!D27,'Goals 2026'!C:C,Smry!F27,'Goals 2026'!E:E,Smry!$B$19) -> 0 | R27: =SUMIFS('Goals 2026'!K:K,'Goals 2026'!B:B,Smry!D27,'Goals 2026'!C:C,Smry!F27,'Goals 2026'!E:E,Smry!$B$19) -> 0
B28: Prakash C | D28: ITQE-Ph2a | F28: Ph 2a | H28: =SUM(I28:L28) -> 3 | I28: =SUMIFS('Goals 2026'!M:M,'Goals 2026'!B:B,Smry!D28,'Goals 2026'!C:C,Smry!F28,'Goals 2026'!E:E,Smry!$B$19) -> 3 | J28: =SUMIFS('Goals 2026'!N:N,'Goals 2026'!B:B,Smry!D28,'Goals 2026'!C:C,Smry!F28,'Goals 2026'!E:E,Smry!$B$19) -> 0 | K28: =SUMIFS('Goals 2026'!O:O,'Goals 2026'!B:B,Smry!D28,'Goals 2026'!C:C,Smry!F28,'Goals 2026'!E:E,Smry!$B$19) -> 0 | L28: =SUMIFS('Goals 2026'!P:P,'Goals 2026'!B:B,Smry!D28,'Goals 2026'!C:C,Smry!F28,'Goals 2026'!E:E,Smry!$B$19) -> 0 | N28: =SUM(O28:R28) -> 0.16918995 | O28: =SUMIFS('Goals 2026'!H:H,'Goals 2026'!B:B,Smry!D28,'Goals 2026'!C:C,Smry!F28,'Goals 2026'!E:E,Smry!$B$19) -> 0.16918995 | P28: =SUMIFS('Goals 2026'!I:I,'Goals 2026'!B:B,Smry!D28,'Goals 2026'!C:C,Smry!F28,'Goals 2026'!E:E,Smry!$B$19) -> 0 | Q28: =SUMIFS('Goals 2026'!J:J,'Goals 2026'!B:B,Smry!D28,'Goals 2026'!C:C,Smry!F28,'Goals 2026'!E:E,Smry!$B$19) -> 0 | R28: =SUMIFS('Goals 2026'!K:K,'Goals 2026'!B:B,Smry!D28,'Goals 2026'!C:C,Smry!F28,'Goals 2026'!E:E,Smry!$B$19) -> 0
B29: Prakash C | D29: ITQE-Ph2b | F29: Ph 2b | H29: =SUM(I29:L29) -> 16 | I29: =SUMIFS('Goals 2026'!M:M,'Goals 2026'!B:B,Smry!D29,'Goals 2026'!C:C,Smry!F29,'Goals 2026'!E:E,Smry!$B$19) -> 11 | J29: =SUMIFS('Goals 2026'!N:N,'Goals 2026'!B:B,Smry!D29,'Goals 2026'!C:C,Smry!F29,'Goals 2026'!E:E,Smry!$B$19) -> 3 | K29: =SUMIFS('Goals 2026'!O:O,'Goals 2026'!B:B,Smry!D29,'Goals 2026'!C:C,Smry!F29,'Goals 2026'!E:E,Smry!$B$19) -> 2 | L29: =SUMIFS('Goals 2026'!P:P,'Goals 2026'!B:B,Smry!D29,'Goals 2026'!C:C,Smry!F29,'Goals 2026'!E:E,Smry!$B$19) -> 0 | N29: =SUM(O29:R29) -> 1.397 | O29: =SUMIFS('Goals 2026'!H:H,'Goals 2026'!B:B,Smry!D29,'Goals 2026'!C:C,Smry!F29,'Goals 2026'!E:E,Smry!$B$19) -> 1.12 | P29: =SUMIFS('Goals 2026'!I:I,'Goals 2026'!B:B,Smry!D29,'Goals 2026'!C:C,Smry!F29,'Goals 2026'!E:E,Smry!$B$19) -> 0.27 | Q29: =SUMIFS('Goals 2026'!J:J,'Goals 2026'!B:B,Smry!D29,'Goals 2026'!C:C,Smry!F29,'Goals 2026'!E:E,Smry!$B$19) -> 0.007 | R29: =SUMIFS('Goals 2026'!K:K,'Goals 2026'!B:B,Smry!D29,'Goals 2026'!C:C,Smry!F29,'Goals 2026'!E:E,Smry!$B$19) -> 0
B30: Prakash C | D30: ItQE-Ph2c [T9] | F30: Ph 2c | H30: =SUM(I30:L30) -> 9 | I30: =SUMIFS('Goals 2026'!M:M,'Goals 2026'!B:B,Smry!D30,'Goals 2026'!C:C,Smry!F30,'Goals 2026'!E:E,Smry!$B$19) -> 4 | J30: =SUMIFS('Goals 2026'!N:N,'Goals 2026'!B:B,Smry!D30,'Goals 2026'!C:C,Smry!F30,'Goals 2026'!E:E,Smry!$B$19) -> 3 | K30: =SUMIFS('Goals 2026'!O:O,'Goals 2026'!B:B,Smry!D30,'Goals 2026'!C:C,Smry!F30,'Goals 2026'!E:E,Smry!$B$19) -> 2 | L30: =SUMIFS('Goals 2026'!P:P,'Goals 2026'!B:B,Smry!D30,'Goals 2026'!C:C,Smry!F30,'Goals 2026'!E:E,Smry!$B$19) -> 0 | N30: =SUM(O30:R30) -> 0.57936247 | O30: =SUMIFS('Goals 2026'!H:H,'Goals 2026'!B:B,Smry!D30,'Goals 2026'!C:C,Smry!F30,'Goals 2026'!E:E,Smry!$B$19) -> 0.28480034 | P30: =SUMIFS('Goals 2026'!I:I,'Goals 2026'!B:B,Smry!D30,'Goals 2026'!C:C,Smry!F30,'Goals 2026'!E:E,Smry!$B$19) -> 0.17656641 | Q30: =SUMIFS('Goals 2026'!J:J,'Goals 2026'!B:B,Smry!D30,'Goals 2026'!C:C,Smry!F30,'Goals 2026'!E:E,Smry!$B$19) -> 0.11799572 | R30: =SUMIFS('Goals 2026'!K:K,'Goals 2026'!B:B,Smry!D30,'Goals 2026'!C:C,Smry!F30,'Goals 2026'!E:E,Smry!$B$19) -> 0
B31: Prakash C | D31: ItQE-Ph3a [T10-12 & 31 Villas] | F31: Ph 3a | H31: =SUM(I31:L31) -> 26 | I31: =SUMIFS('Goals 2026'!M:M,'Goals 2026'!B:B,Smry!D31,'Goals 2026'!C:C,Smry!F31,'Goals 2026'!E:E,Smry!$B$19) -> 2 | J31: =SUMIFS('Goals 2026'!N:N,'Goals 2026'!B:B,Smry!D31,'Goals 2026'!C:C,Smry!F31,'Goals 2026'!E:E,Smry!$B$19) -> 4 | K31: =SUMIFS('Goals 2026'!O:O,'Goals 2026'!B:B,Smry!D31,'Goals 2026'!C:C,Smry!F31,'Goals 2026'!E:E,Smry!$B$19) -> 11 | L31: =SUMIFS('Goals 2026'!P:P,'Goals 2026'!B:B,Smry!D31,'Goals 2026'!C:C,Smry!F31,'Goals 2026'!E:E,Smry!$B$19) -> 9 | N31: =SUM(O31:R31) -> 6.0390319 | O31: =SUMIFS('Goals 2026'!H:H,'Goals 2026'!B:B,Smry!D31,'Goals 2026'!C:C,Smry!F31,'Goals 2026'!E:E,Smry!$B$19) -> 3.2578975 | P31: =SUMIFS('Goals 2026'!I:I,'Goals 2026'!B:B,Smry!D31,'Goals 2026'!C:C,Smry!F31,'Goals 2026'!E:E,Smry!$B$19) -> 0.61867009 | Q31: =SUMIFS('Goals 2026'!J:J,'Goals 2026'!B:B,Smry!D31,'Goals 2026'!C:C,Smry!F31,'Goals 2026'!E:E,Smry!$B$19) -> 1.2870246 | R31: =SUMIFS('Goals 2026'!K:K,'Goals 2026'!B:B,Smry!D31,'Goals 2026'!C:C,Smry!F31,'Goals 2026'!E:E,Smry!$B$19) -> 0.87543981
B32: Prakash C | D32: ITQE-T05 | F32: T05 | H32: =SUM(I32:L32) -> 1 | I32: =SUMIFS('Goals 2026'!M:M,'Goals 2026'!B:B,Smry!D32,'Goals 2026'!C:C,Smry!F32,'Goals 2026'!E:E,Smry!$B$19) -> 0 | J32: =SUMIFS('Goals 2026'!N:N,'Goals 2026'!B:B,Smry!D32,'Goals 2026'!C:C,Smry!F32,'Goals 2026'!E:E,Smry!$B$19) -> 1 | K32: =SUMIFS('Goals 2026'!O:O,'Goals 2026'!B:B,Smry!D32,'Goals 2026'!C:C,Smry!F32,'Goals 2026'!E:E,Smry!$B$19) -> 0 | L32: =SUMIFS('Goals 2026'!P:P,'Goals 2026'!B:B,Smry!D32,'Goals 2026'!C:C,Smry!F32,'Goals 2026'!E:E,Smry!$B$19) -> 0 | N32: =SUM(O32:R32) -> 0.04 | O32: =SUMIFS('Goals 2026'!H:H,'Goals 2026'!B:B,Smry!D32,'Goals 2026'!C:C,Smry!F32,'Goals 2026'!E:E,Smry!$B$19) -> 0 | P32: =SUMIFS('Goals 2026'!I:I,'Goals 2026'!B:B,Smry!D32,'Goals 2026'!C:C,Smry!F32,'Goals 2026'!E:E,Smry!$B$19) -> 0.04 | Q32: =SUMIFS('Goals 2026'!J:J,'Goals 2026'!B:B,Smry!D32,'Goals 2026'!C:C,Smry!F32,'Goals 2026'!E:E,Smry!$B$19) -> 0 | R32: =SUMIFS('Goals 2026'!K:K,'Goals 2026'!B:B,Smry!D32,'Goals 2026'!C:C,Smry!F32,'Goals 2026'!E:E,Smry!$B$19) -> 0
... B60: Prakash C | D60: DonaPaula | F60: DP | H60: =SUM(I60:L60) -> 26 | I60: =SUMIFS('Goals 2026'!M:M,'Goals 2026'!B:B,Smry!D60,'Goals 2026'!C:C,Smry!F60,'Goals 2026'!E:E,Smry!$B$19) -> 2 | J60: =SUMIFS('Goals 2026'!N:N,'Goals 2026'!B:B,Smry!D60,'Goals 2026'!C:C,Smry!F60,'Goals 2026'!E:E,Smry!$B$19) -> 1 | K60: =SUMIFS('Goals 2026'!O:O,'Goals 2026'!B:B,Smry!D60,'Goals 2026'!C:C,Smry!F60,'Goals 2026'!E:E,Smry!$B$19) -> 8 | L60: =SUMIFS('Goals 2026'!P:P,'Goals 2026'!B:B,Smry!D60,'Goals 2026'!C:C,Smry!F60,'Goals 2026'!E:E,Smry!$B$19) -> 15 | N60: =SUM(O60:R60) -> 1.3982982 | O60: =SUMIFS('Goals 2026'!H:H,'Goals 2026'!B:B,Smry!D60,'Goals 2026'!C:C,Smry!F60,'Goals 2026'!E:E,Smry!$B$19) -> 0.62984501 | P60: =SUMIFS('Goals 2026'!I:I,'Goals 2026'!B:B,Smry!D60,'Goals 2026'!C:C,Smry!F60,'Goals 2026'!E:E,Smry!$B$19) -> 0.09 | Q60: =SUMIFS('Goals 2026'!J:J,'Goals 2026'!B:B,Smry!D60,'Goals 2026'!C:C,Smry!F60,'Goals 2026'!E:E,Smry!$B$19) -> 0.32685348 | R60: =SUMIFS('Goals 2026'!K:K,'Goals 2026'!B:B,Smry!D60,'Goals 2026'!C:C,Smry!F60,'Goals 2026'!E:E,Smry!$B$19) -> 0.35159975
B62: Gagan | H62: =SUM(I62:L62) -> 436 | I62: =SUM(I64:I98) -> 127 | J62: =SUM(J64:J98) -> 92 | K62: =SUM(K64:K98) -> 122 | L62: =SUM(L64:L98) -> 95 | N62: =SUM(O62:R62) -> 64.837967 | O62: =SUM(O64:O98) -> 18.674601 | P62: =SUM(P64:P98) -> 11.051107 | Q62: =SUM(Q64:Q98) -> 19.8534 | R62: =SUM(R64:R98) -> 15.258859
B64: Gagan | D64: AtR | F64: Ph 2c | H64: =SUM(I64:L64) -> 1 | I64: =SUMIFS('Goals 2026'!M:M,'Goals 2026'!B:B,Smry!D64,'Goals 2026'!C:C,Smry!F64,'Goals 2026'!E:E,Smry!$B$62) -> 1 | J64: =SUMIFS('Goals 2026'!N:N,'Goals 2026'!B:B,Smry!D64,'Goals 2026'!C:C,Smry!F64,'Goals 2026'!E:E,Smry!$B$62) -> 0 | K64: =SUMIFS('Goals 2026'!O:O,'Goals 2026'!B:B,Smry!D64,'Goals 2026'!C:C,Smry!F64,'Goals 2026'!E:E,Smry!$B$62) -> 0 | L64: =SUMIFS('Goals 2026'!P:P,'Goals 2026'!B:B,Smry!D64,'Goals 2026'!C:C,Smry!F64,'Goals 2026'!E:E,Smry!$B$62) -> 0 | N64: =SUM(O64:R64) -> 0.014336873 | O64: =SUMIFS('Goals 2026'!H:H,'Goals 2026'!B:B,Smry!D64,'Goals 2026'!C:C,Smry!F64,'Goals 2026'!E:E,Smry!$B$62) -> 0.014336873 | P64: =SUMIFS('Goals 2026'!I:I,'Goals 2026'!B:B,Smry!D64,'Goals 2026'!C:C,Smry!F64,'Goals 2026'!E:E,Smry!$B$62) -> 0 | Q64: =SUMIFS('Goals 2026'!J:J,'Goals 2026'!B:B,Smry!D64,'Goals 2026'!C:C,Smry!F64,'Goals 2026'!E:E,Smry!$B$62) -> 0 | R64: =SUMIFS('Goals 2026'!K:K,'Goals 2026'!B:B,Smry!D64,'Goals 2026'!C:C,Smry!F64,'Goals 2026'!E:E,Smry!$B$62) -> 0
B65: Gagan | D65: AtR | F65: Ph 3 | H65: =SUM(I65:L65) -> 15 | I65: =SUMIFS('Goals 2026'!M:M,'Goals 2026'!B:B,Smry!D65,'Goals 2026'!C:C,Smry!F65,'Goals 2026'!E:E,Smry!$B$62) -> 12 | J65: =SUMIFS('Goals 2026'!N:N,'Goals 2026'!B:B,Smry!D65,'Goals 2026'!C:C,Smry!F65,'Goals 2026'!E:E,Smry!$B$62) -> 3 | K65: =SUMIFS('Goals 2026'!O:O,'Goals 2026'!B:B,Smry!D65,'Goals 2026'!C:C,Smry!F65,'Goals 2026'!E:E,Smry!$B$62) -> 0 | L65: =SUMIFS('Goals 2026'!P:P,'Goals 2026'!B:B,Smry!D65,'Goals 2026'!C:C,Smry!F65,'Goals 2026'!E:E,Smry!$B$62) -> 0 | N65: =SUM(O65:R65) -> 0.49718334 | O65: =SUMIFS('Goals 2026'!H:H,'Goals 2026'!B:B,Smry!D65,'Goals 2026'!C:C,Smry!F65,'Goals 2026'!E:E,Smry!$B$62) -> 0.36573176 | P65: =SUMIFS('Goals 2026'!I:I,'Goals 2026'!B:B,Smry!D65,'Goals 2026'!C:C,Smry!F65,'Goals 2026'!E:E,Smry!$B$62) -> 0.13145158 | Q65: =SUMIFS('Goals 2026'!J:J,'Goals 2026'!B:B,Smry!D65,'Goals 2026'!C:C,Smry!F65,'Goals 2026'!E:E,Smry!$B$62) -> 0 | R65: =SUMIFS('Goals 2026'!K:K,'Goals 2026'!B:B,Smry!D65,'Goals 2026'!C:C,Smry!F65,'Goals 2026'!E:E,Smry!$B$62) -> 0
B66: Gagan | D66: AtR - C | F66: Com | H66: =SUM(I66:L66) -> 2 | I66: =SUMIFS('Goals 2026'!M:M,'Goals 2026'!B:B,Smry!D66,'Goals 2026'!C:C,Smry!F66,'Goals 2026'!E:E,Smry!$B$62) -> 2 | J66: =SUMIFS('Goals 2026'!N:N,'Goals 2026'!B:B,Smry!D66,'Goals 2026'!C:C,Smry!F66,'Goals 2026'!E:E,Smry!$B$62) -> 0 | K66: =SUMIFS('Goals 2026'!O:O,'Goals 2026'!B:B,Smry!D66,'Goals 2026'!C:C,Smry!F66,'Goals 2026'!E:E,Smry!$B$62) -> 0 | L66: =SUMIFS('Goals 2026'!P:P,'Goals 2026'!B:B,Smry!D66,'Goals 2026'!C:C,Smry!F66,'Goals 2026'!E:E,Smry!$B$62) -> 0 | N66: =SUM(O66:R66) -> 0.16750548 | O66: =SUMIFS('Goals 2026'!H:H,'Goals 2026'!B:B,Smry!D66,'Goals 2026'!C:C,Smry!F66,'Goals 2026'!E:E,Smry!$B$62) -> 0.16750548 | P66: =SUMIFS('Goals 2026'!I:I,'Goals 2026'!B:B,Smry!D66,'Goals 2026'!C:C,Smry!F66,'Goals 2026'!E:E,Smry!$B$62) -> 0 | Q66: =SUMIFS('Goals 2026'!J:J,'Goals 2026'!B:B,Smry!D66,'Goals 2026'!C:C,Smry!F66,'Goals 2026'!E:E,Smry!$B$62) -> 0 | R66: =SUMIFS('Goals 2026'!K:K,'Goals 2026'!B:B,Smry!D66,'Goals 2026'!C:C,Smry!F66,'Goals 2026'!E:E,Smry!$B$62) -> 0
B67: Gagan | D67: PoaRR-Res | F67: Res | H67: =SUM(I67:L67) -> 4 | I67: =SUMIFS('Goals 2026'!M:M,'Goals 2026'!B:B,Smry!D67,'Goals 2026'!C:C,Smry!F67,'Goals 2026'!E:E,Smry!$B$62) -> 4 | J67: =SUMIFS('Goals 2026'!N:N,'Goals 2026'!B:B,Smry!D67,'Goals 2026'!C:C,Smry!F67,'Goals 2026'!E:E,Smry!$B$62) -> 0 | K67: =SUMIFS('Goals 2026'!O:O,'Goals 2026'!B:B,Smry!D67,'Goals 2026'!C:C,Smry!F67,'Goals 2026'!E:E,Smry!$B$62) -> 0 | L67: =SUMIFS('Goals 2026'!P:P,'Goals 2026'!B:B,Smry!D67,'Goals 2026'!C:C,Smry!F67,'Goals 2026'!E:E,Smry!$B$62) -> 0 | N67: =SUM(O67:R67) -> 0.4032745 | O67: =SUMIFS('Goals 2026'!H:H,'Goals 2026'!B:B,Smry!D67,'Goals 2026'!C:C,Smry!F67,'Goals 2026'!E:E,Smry!$B$62) -> 0.4032745 | P67: =SUMIFS('Goals 2026'!I:I,'Goals 2026'!B:B,Smry!D67,'Goals 2026'!C:C,Smry!F67,'Goals 2026'!E:E,Smry!$B$62) -> 0 | Q67: =SUMIFS('Goals 2026'!J:J,'Goals 2026'!B:B,Smry!D67,'Goals 2026'!C:C,Smry!F67,'Goals 2026'!E:E,Smry!$B$62) -> 0 | R67: =SUMIFS('Goals 2026'!K:K,'Goals 2026'!B:B,Smry!D67,'Goals 2026'!C:C,Smry!F67,'Goals 2026'!E:E,Smry!$B$62) -> 0
B68: Gagan | D68: PoaRR-T08 | F68: T08 | H68: =SUM(I68:L68) -> 23 | I68: =SUMIFS('Goals 2026'!M:M,'Goals 2026'!B:B,Smry!D68,'Goals 2026'!C:C,Smry!F68,'Goals 2026'!E:E,Smry!$B$62) -> 3 | J68: =SUMIFS('Goals 2026'!N:N,'Goals 2026'!B:B,Smry!D68,'Goals 2026'!C:C,Smry!F68,'Goals 2026'!E:E,Smry!$B$62) -> 9 | K68: =SUMIFS('Goals 2026'!O:O,'Goals 2026'!B:B,Smry!D68,'Goals 2026'!C:C,Smry!F68,'Goals 2026'!E:E,Smry!$B$62) -> 11 | L68: =SUMIFS('Goals 2026'!P:P,'Goals 2026'!B:B,Smry!D68,'Goals 2026'!C:C,Smry!F68,'Goals 2026'!E:E,Smry!$B$62) -> 0 | N68: =SUM(O68:R68) -> 1.28828 | O68: =SUMIFS('Goals 2026'!H:H,'Goals 2026'!B:B,Smry!D68,'Goals 2026'!C:C,Smry!F68,'Goals 2026'!E:E,Smry!$B$62) -> 0.14 | P68: =SUMIFS('Goals 2026'!I:I,'Goals 2026'!B:B,Smry!D68,'Goals 2026'!C:C,Smry!F68,'Goals 2026'!E:E,Smry!$B$62) -> 0.65548 | Q68: =SUMIFS('Goals 2026'!J:J,'Goals 2026'!B:B,Smry!D68,'Goals 2026'!C:C,Smry!F68,'Goals 2026'!E:E,Smry!$B$62) -> 0.4928 | R68: =SUMIFS('Goals 2026'!K:K,'Goals 2026'!B:B,Smry!D68,'Goals 2026'!C:C,Smry!F68,'Goals 2026'!E:E,Smry!$B$62) -> 0
B69: Gagan | D69: ITQE-Ph2b | F69: Ph 2b | H69: =SUM(I69:L69) -> 3 | I69: =SUMIFS('Goals 2026'!M:M,'Goals 2026'!B:B,Smry!D69,'Goals 2026'!C:C,Smry!F69,'Goals 2026'!E:E,Smry!$B$62) -> 2 | J69: =SUMIFS('Goals 2026'!N:N,'Goals 2026'!B:B,Smry!D69,'Goals 2026'!C:C,Smry!F69,'Goals 2026'!E:E,Smry!$B$62) -> 0 | K69: =SUMIFS('Goals 2026'!O:O,'Goals 2026'!B:B,Smry!D69,'Goals 2026'!C:C,Smry!F69,'Goals 2026'!E:E,Smry!$B$62) -> 1 | L69: =SUMIFS('Goals 2026'!P:P,'Goals 2026'!B:B,Smry!D69,'Goals 2026'!C:C,Smry!F69,'Goals 2026'!E:E,Smry!$B$62) -> 0 | N69: =SUM(O69:R69) -> 0.049857313 | O69: =SUMIFS('Goals 2026'!H:H,'Goals 2026'!B:B,Smry!D69,'Goals 2026'!C:C,Smry!F69,'Goals 2026'!E:E,Smry!$B$62) -> 0.031655887 | P69: =SUMIFS('Goals 2026'!I:I,'Goals 2026'!B:B,Smry!D69,'Goals 2026'!C:C,Smry!F69,'Goals 2026'!E:E,Smry!$B$62) -> 0 | Q69: =SUMIFS('Goals 2026'!J:J,'Goals 2026'!B:B,Smry!D69,'Goals 2026'!C:C,Smry!F69,'Goals 2026'!E:E,Smry!$B$62) -> 0.018201425 | R69: =SUMIFS('Goals 2026'!K:K,'Goals 2026'!B:B,Smry!D69,'Goals 2026'!C:C,Smry!F69,'Goals 2026'!E:E,Smry!$B$62) -> 0
B70: Gagan | D70: ItQE-Ph2c [T9] | F70: Ph 2c | H70: =SUM(I70:L70) -> 6 | I70: =SUMIFS('Goals 2026'!M:M,'Goals 2026'!B:B,Smry!D70,'Goals 2026'!C:C,Smry!F70,'Goals 2026'!E:E,Smry!$B$62) -> 2 | J70: =SUMIFS('Goals 2026'!N:N,'Goals 2026'!B:B,Smry!D70,'Goals 2026'!C:C,Smry!F70,'Goals 2026'!E:E,Smry!$B$62) -> 3 | K70: =SUMIFS('Goals 2026'!O:O,'Goals 2026'!B:B,Smry!D70,'Goals 2026'!C:C,Smry!F70,'Goals 2026'!E:E,Smry!$B$62) -> 1 | L70: =SUMIFS('Goals 2026'!P:P,'Goals 2026'!B:B,Smry!D70,'Goals 2026'!C:C,Smry!F70,'Goals 2026'!E:E,Smry!$B$62) -> 0 | N70: =SUM(O70:R70) -> 0.14769089 | O70: =SUMIFS('Goals 2026'!H:H,'Goals 2026'!B:B,Smry!D70,'Goals 2026'!C:C,Smry!F70,'Goals 2026'!E:E,Smry!$B$62) -> 0.04712278 | P70: =SUMIFS('Goals 2026'!I:I,'Goals 2026'!B:B,Smry!D70,'Goals 2026'!C:C,Smry!F70,'Goals 2026'!E:E,Smry!$B$62) -> 0.08426778 | Q70: =SUMIFS('Goals 2026'!J:J,'Goals 2026'!B:B,Smry!D70,'Goals 2026'!C:C,Smry!F70,'Goals 2026'!E:E,Smry!$B$62) -> 0.016300333 | R70: =SUMIFS('Goals 2026'!K:K,'Goals 2026'!B:B,Smry!D70,'Goals 2026'!C:C,Smry!F70,'Goals 2026'!E:E,Smry!$B$62) -> 0
B71: Gagan | D71: ItQE-Ph3a [T10-12 & 31 Villas] | F71: Ph 3a | H71: =SUM(I71:L71) -> 23 | I71: =SUMIFS('Goals 2026'!M:M,'Goals 2026'!B:B,Smry!D71,'Goals 2026'!C:C,Smry!F71,'Goals 2026'!E:E,Smry!$B$62) -> 5 | J71: =SUMIFS('Goals 2026'!N:N,'Goals 2026'!B:B,Smry!D71,'Goals 2026'!C:C,Smry!F71,'Goals 2026'!E:E,Smry!$B$62) -> 2 | K71: =SUMIFS('Goals 2026'!O:O,'Goals 2026'!B:B,Smry!D71,'Goals 2026'!C:C,Smry!F71,'Goals 2026'!E:E,Smry!$B$62) -> 9 | L71: =SUMIFS('Goals 2026'!P:P,'Goals 2026'!B:B,Smry!D71,'Goals 2026'!C:C,Smry!F71,'Goals 2026'!E:E,Smry!$B$62) -> 7 | N71: =SUM(O71:R71) -> 2.9539608 | O71: =SUMIFS('Goals 2026'!H:H,'Goals 2026'!B:B,Smry!D71,'Goals 2026'!C:C,Smry!F71,'Goals 2026'!E:E,Smry!$B$62) -> 2.1646138 | P71: =SUMIFS('Goals 2026'!I:I,'Goals 2026'!B:B,Smry!D71,'Goals 2026'!C:C,Smry!F71,'Goals 2026'!E:E,Smry!$B$62) -> 0.10236453 | Q71: =SUMIFS('Goals 2026'!J:J,'Goals 2026'!B:B,Smry!D71,'Goals 2026'!C:C,Smry!F71,'Goals 2026'!E:E,Smry!$B$62) -> 0.40148764 | R71: =SUMIFS('Goals 2026'!K:K,'Goals 2026'!B:B,Smry!D71,'Goals 2026'!C:C,Smry!F71,'Goals 2026'!E:E,Smry!$B$62) -> 0.28549481
B72: Gagan | D72: OTR-Ph01 | F72: Ph 1 | H72: =SUM(I72:L72) -> 1 | I72: =SUMIFS('Goals 2026'!M:M,'Goals 2026'!B:B,Smry!D72,'Goals 2026'!C:C,Smry!F72,'Goals 2026'!E:E,Smry!$B$62) -> 1 | J72: =SUMIFS('Goals 2026'!N:N,'Goals 2026'!B:B,Smry!D72,'Goals 2026'!C:C,Smry!F72,'Goals 2026'!E:E,Smry!$B$62) -> 0 | K72: =SUMIFS('Goals 2026'!O:O,'Goals 2026'!B:B,Smry!D72,'Goals 2026'!C:C,Smry!F72,'Goals 2026'!E:E,Smry!$B$62) -> 0 | L72: =SUMIFS('Goals 2026'!P:P,'Goals 2026'!B:B,Smry!D72,'Goals 2026'!C:C,Smry!F72,'Goals 2026'!E:E,Smry!$B$62) -> 0 | N72: =SUM(O72:R72) -> 0.04 | O72: =SUMIFS('Goals 2026'!H:H,'Goals 2026'!B:B,Smry!D72,'Goals 2026'!C:C,Smry!F72,'Goals 2026'!E:E,Smry!$B$62) -> 0.04 | P72: =SUMIFS('Goals 2026'!I:I,'Goals 2026'!B:B,Smry!D72,'Goals 2026'!C:C,Smry!F72,'Goals 2026'!E:E,Smry!$B$62) -> 0 | Q72: =SUMIFS('Goals 2026'!J:J,'Goals 2026'!B:B,Smry!D72,'Goals 2026'!C:C,Smry!F72,'Goals 2026'!E:E,Smry!$B$62) -> 0 | R72: =SUMIFS('Goals 2026'!K:K,'Goals 2026'!B:B,Smry!D72,'Goals 2026'!C:C,Smry!F72,'Goals 2026'!E:E,Smry!$B$62) -> 0
B73: Gagan | D73: TuiG | F73: TuiG | H73: =SUM(I73:L73) -> 6 | I73: =SUMIFS('Goals 2026'!M:M,'Goals 2026'!B:B,Smry!D73,'Goals 2026'!C:C,Smry!F73,'Goals 2026'!E:E,Smry!$B$62) -> 4 | J73: =SUMIFS('Goals 2026'!N:N,'Goals 2026'!B:B,Smry!D73,'Goals 2026'!C:C,Smry!F73,'Goals 2026'!E:E,Smry!$B$62) -> 2 | K73: =SUMIFS('Goals 2026'!O:O,'Goals 2026'!B:B,Smry!D73,'Goals 2026'!C:C,Smry!F73,'Goals 2026'!E:E,Smry!$B$62) -> 0 | L73: =SUMIFS('Goals 2026'!P:P,'Goals 2026'!B:B,Smry!D73,'Goals 2026'!C:C,Smry!F73,'Goals 2026'!E:E,Smry!$B$62) -> 0 | N73: =SUM(O73:R73) -> 0.49857202 | O73: =SUMIFS('Goals 2026'!H:H,'Goals 2026'!B:B,Smry!D73,'Goals 2026'!C:C,Smry!F73,'Goals 2026'!E:E,Smry!$B$62) -> 0.32421104 | P73: =SUMIFS('Goals 2026'!I:I,'Goals 2026'!B:B,Smry!D73,'Goals 2026'!C:C,Smry!F73,'Goals 2026'!E:E,Smry!$B$62) -> 0.17436098 | Q73: =SUMIFS('Goals 2026'!J:J,'Goals 2026'!B:B,Smry!D73,'Goals 2026'!C:C,Smry!F73,'Goals 2026'!E:E,Smry!$B$62) -> 0 | R73: =SUMIFS('Goals 2026'!K:K,'Goals 2026'!B:B,Smry!D73,'Goals 2026'!C:C,Smry!F73,'Goals 2026'!E:E,Smry!$B$62) -> 0
B74: Gagan | D74: DBTW | F74: DBTW | H74: =SUM(I74:L74) -> 11 | I74: =SUMIFS('Goals 2026'!M:M,'Goals 2026'!B:B,Smry!D74,'Goals 2026'!C:C,Smry!F74,'Goals 2026'!E:E,Smry!$B$62) -> 1 | J74: =SUMIFS('Goals 2026'!N:N,'Goals 2026'!B:B,Smry!D74,'Goals 2026'!C:C,Smry!F74,'Goals 2026'!E:E,Smry!$B$62) -> 1 | K74: =SUMIFS('Goals 2026'!O:O,'Goals 2026'!B:B,Smry!D74,'Goals 2026'!C:C,Smry!F74,'Goals 2026'!E:E,Smry!$B$62) -> 1 | L74: =SUMIFS('Goals 2026'!P:P,'Goals 2026'!B:B,Smry!D74,'Goals 2026'!C:C,Smry!F74,'Goals 2026'!E:E,Smry!$B$62) -> 8 | N74: =SUM(O74:R74) -> 0.53636436 | O74: =SUMIFS('Goals 2026'!H:H,'Goals 2026'!B:B,Smry!D74,'Goals 2026'!C:C,Smry!F74,'Goals 2026'!E:E,Smry!$B$62) -> 0.036853335 | P74: =SUMIFS('Goals 2026'!I:I,'Goals 2026'!B:B,Smry!D74,'Goals 2026'!C:C,Smry!F74,'Goals 2026'!E:E,Smry!$B$62) -> 0.12284445 | Q74: =SUMIFS('Goals 2026'!J:J,'Goals 2026'!B:B,Smry!D74,'Goals 2026'!C:C,Smry!F74,'Goals 2026'!E:E,Smry!$B$62) -> 0.10269917 | R74: =SUMIFS('Goals 2026'!K:K,'Goals 2026'!B:B,Smry!D74,'Goals 2026'!C:C,Smry!F74,'Goals 2026'!E:E,Smry!$B$62) -> 0.2739674
B75: Gagan | D75: SftW | F75: SftW | H75: =SUM(I75:L75) -> 3 | I75: =SUMIFS('Goals 2026'!M:M,'Goals 2026'!B:B,Smry!D75,'Goals 2026'!C:C,Smry!F75,'Goals 2026'!E:E,Smry!$B$62) -> 2 | J75: =SUMIFS('Goals 2026'!N:N,'Goals 2026'!B:B,Smry!D75,'Goals 2026'!C:C,Smry!F75,'Goals 2026'!E:E,Smry!$B$62) -> 1 | K75: =SUMIFS('Goals 2026'!O:O,'Goals 2026'!B:B,Smry!D75,'Goals 2026'!C:C,Smry!F75,'Goals 2026'!E:E,Smry!$B$62) -> 0 | L75: =SUMIFS('Goals 2026'!P:P,'Goals 2026'!B:B,Smry!D75,'Goals 2026'!C:C,Smry!F75,'Goals 2026'!E:E,Smry!$B$62) -> 0 | N75: =SUM(O75:R75) -> 0.064478719 | O75: =SUMIFS('Goals 2026'!H:H,'Goals 2026'!B:B,Smry!D75,'Goals 2026'!C:C,Smry!F75,'Goals 2026'!E:E,Smry!$B$62) -> 0.021397858 | P75: =SUMIFS('Goals 2026'!I:I,'Goals 2026'!B:B,Smry!D75,'Goals 2026'!C:C,Smry!F75,'Goals 2026'!E:E,Smry!$B$62) -> 0.043080861 | Q75: =SUMIFS('Goals 2026'!J:J,'Goals 2026'!B:B,Smry!D75,'Goals 2026'!C:C,Smry!F75,'Goals 2026'!E:E,Smry!$B$62) -> 0 | R75: =SUMIFS('Goals 2026'!K:K,'Goals 2026'!B:B,Smry!D75,'Goals 2026'!C:C,Smry!F75,'Goals 2026'!E:E,Smry!$B$62) -> 0
... B98: Gagan | D98: DonaPaula | F98: DP | H98: =SUM(I98:L98) -> 30 | I98: =SUMIFS('Goals 2026'!M:M,'Goals 2026'!B:B,Smry!D98,'Goals 2026'!C:C,Smry!F98,'Goals 2026'!E:E,Smry!$B$62) -> 5 | J98: =SUMIFS('Goals 2026'!N:N,'Goals 2026'!B:B,Smry!D98,'Goals 2026'!C:C,Smry!F98,'Goals 2026'!E:E,Smry!$B$62) -> 3 | K98: =SUMIFS('Goals 2026'!O:O,'Goals 2026'!B:B,Smry!D98,'Goals 2026'!C:C,Smry!F98,'Goals 2026'!E:E,Smry!$B$62) -> 12 | L98: =SUMIFS('Goals 2026'!P:P,'Goals 2026'!B:B,Smry!D98,'Goals 2026'!C:C,Smry!F98,'Goals 2026'!E:E,Smry!$B$62) -> 10 | N98: =SUM(O98:R98) -> 1.1097676 | O98: =SUMIFS('Goals 2026'!H:H,'Goals 2026'!B:B,Smry!D98,'Goals 2026'!C:C,Smry!F98,'Goals 2026'!E:E,Smry!$B$62) -> 0.45 | P98: =SUMIFS('Goals 2026'!I:I,'Goals 2026'!B:B,Smry!D98,'Goals 2026'!C:C,Smry!F98,'Goals 2026'!E:E,Smry!$B$62) -> 0.25 | Q98: =SUMIFS('Goals 2026'!J:J,'Goals 2026'!B:B,Smry!D98,'Goals 2026'!C:C,Smry!F98,'Goals 2026'!E:E,Smry!$B$62) -> 0.32451895 | R98: =SUMIFS('Goals 2026'!K:K,'Goals 2026'!B:B,Smry!D98,'Goals 2026'!C:C,Smry!F98,'Goals 2026'!E:E,Smry!$B$62) -> 0.085248666
J99: =SUMIFS('Goals 2026'!N:N,'Goals 2026'!B:B,Smry!D99,'Goals 2026'!C:C,Smry!F99,'Goals 2026'!E:E,Smry!$B$62) -> 0
B100: Naveen Y | H100: =SUM(I100:L100) -> 87 | I100: =SUM(I102:I108) -> 24 | J100: =SUM(J102:J108) -> 13 | K100: =SUM(K102:K108) -> 22 | L100: =SUM(L102:L108) -> 28 | N100: =SUM(O100:R100) -> 46.454737 | O100: =SUM(O102:O108) -> 23.432421 | P100: =SUM(P102:P108) -> 11.134149 | Q100: =SUM(Q102:Q108) -> 6.1257662 | R100: =SUM(R102:R108) -> 5.7624015
B102: Naveen Y | D102: AtR - C | F102: Com | H102: =SUM(I102:L102) -> 3 | I102: =SUMIFS('Goals 2026'!M:M,'Goals 2026'!B:B,Smry!D102,'Goals 2026'!C:C,Smry!F102,'Goals 2026'!E:E,Smry!$B$100) -> 3 | J102: =SUMIFS('Goals 2026'!N:N,'Goals 2026'!B:B,Smry!D102,'Goals 2026'!C:C,Smry!F102,'Goals 2026'!E:E,Smry!$B$100) -> 0 | K102: =SUMIFS('Goals 2026'!O:O,'Goals 2026'!B:B,Smry!D102,'Goals 2026'!C:C,Smry!F102,'Goals 2026'!E:E,Smry!$B$100) -> 0 | L102: =SUMIFS('Goals 2026'!P:P,'Goals 2026'!B:B,Smry!D102,'Goals 2026'!C:C,Smry!F102,'Goals 2026'!E:E,Smry!$B$100) -> 0 | N102: =SUM(O102:R102) -> 0.36421477 | O102: =SUMIFS('Goals 2026'!H:H,'Goals 2026'!B:B,Smry!D102,'Goals 2026'!C:C,Smry!F102,'Goals 2026'!E:E,Smry!$B$100) -> 0.36421477 | P102: =SUMIFS('Goals 2026'!I:I,'Goals 2026'!B:B,Smry!D102,'Goals 2026'!C:C,Smry!F102,'Goals 2026'!E:E,Smry!$B$100) -> 0 | Q102: =SUMIFS('Goals 2026'!J:J,'Goals 2026'!B:B,Smry!D102,'Goals 2026'!C:C,Smry!F102,'Goals 2026'!E:E,Smry!$B$100) -> 0 | R102: =SUMIFS('Goals 2026'!K:K,'Goals 2026'!B:B,Smry!D102,'Goals 2026'!C:C,Smry!F102,'Goals 2026'!E:E,Smry!$B$100) -> 0
...

Sheet 26Q1 Actuals Smry
B1: Design Lead | C1: Design Packages | D1: 26Q1 Fee | E1: Actuals | F1: Actual Fees | G1: Remarks
D2: =SUM(D3:D115) -> 112.68299 | E2: =SUM(E3:E112) -> 55 | F2: =SUM(F3:F112) -> 3.5166917
B3: Saji | C3: PoaRR [T8-GFC except Penthouse products, T1-7-GFC] [Pkgs 26] | D3: 10.4
B4: Saji | C4: AtR [1,2a,2b,2c-GFC, P3 Structure] [Pkgs 19] | D4: 2.2 | G4: LoD 350 - Clubhouse + Amenities - Clubhouse—Interiors and Facilities
B5: Cijey | C5: itQE [P2a GFC, 2b-Basements, 2c-Foundations/ Parking, P3-Approvals & Exp Homes][Pkgs 12] | D5: 11.71 | G5: Ph2a -LoD 350 - Master Plan | Site Development, LoD 350 -Experience Home + Project Experience [ V35 ], Ph2b - LoD 350 - L25 Default and it's variants, LoD 350 - ISS 5&6 | Structural Slab 01 [Basement] LoD 350 - ISS 7 | Structrural Slab 01 [Basement], Ph 2c - I20, I25 Experience Homes
B6: Cijey | C6: OtR [P1-GFC, Museum-LOD 200][Pkgs 7] | D6: 1.4 | G6: Ph1 - LoD 350 - Individual Homes | V25 Default & its Variant, LoD 350 - Villa Block | Building Envelope + Plot Development, Museum - Lod 100 - Design Brief
B7: Cijey | C7: Homestay NH GFC [Pkgs 4] | D7: 0.78
B8: Cijey | C8: Sarjapur Road [LOD 200, Approval, Experience Homes] [Pkgs 4] | D8: 13.81 | G8: LoD 100 - Contract + Design Brief
B9: Cijey | C9: Meena Sai [LOD 200, Approvals] [Pkgs 2] | D9: 0.11
B10: Cijey | C10: OtR P2 [LOD 200, Approval] [Pkgs 3] | D10: 1.18 | G10: LoD 100 - Contract + Design Brief
B11: Naveen | C11: AtR Commercial [Complete GFCs] [Pkgs 3] | D11: 0.36
B12: Naveen | C12: TMFT P3 [LOD 200, Approvals] [Pkgs 3] | D12: 0.62
B13: Naveen | C13: Sarjapur C [LOD 200, Approvals] [Pkgs 19] | D13: 14.74 | G13: LoD 100 - Contract + Design Brief
B14: Naveen | C14: OtF [LOD 300, Approvals, Marketing and Proj Exp] [Pkgs 6] | D14: 2.75 | G14: LoD 100 - Contract + Design Brief [Commercial]; LoD 200 - Schematic Concept
B15: Naveen | C15: Imagine [LOD 200, Approvals] [Pkgs 3] | D15: 1.61
B16: OP | C16: DbtW [Complete GFCs-except Clubhouse Interiors and Community spaces] [Pkgs 10] | D16: 5.88 | G16: LoD 350 - ISS - Podium Slab, Home Products - I20 and I25 Default and it's variants, Master Plan - Site Development
B17: OP | C17: SftW [Complete GFCs-except Clubhouse Interiors and Community spaces] [Pkgs 09] | D17: 0.85
B18: OP | C18: TuiG [Clubhouse Outdoor and Community Spaces] [Pkgs 3] | D18: 0.33 | G18: LoD 350 - Clubhouse structure & envelope, Sporting facility
B19: OP | C19: LGCE [LOD 200] [Pkgs 2] | D19: 0.38
B20: OP | C20: OtR P2 [Clubhouse LOD 200 and Approvals] [Pkgs 2] | D20: 0.17
B21: OP | C21: Violet Hill [Clubhouse LOD 200] [Pkgs 1] | D21: 0.06 | G21: LoD 200 - Schematic Concept
B22: OP | C22: OtF [Clubhouse LOD 200 and Approvals] [Pkgs 3] | D22: 0.29 | G22: LoD 200 - Schematic Concept - CH
B23: OP | C23: Sarjapur Rd [Clubhouse LOD 200 and Approvals] [Pkgs 2] | D23: 0.51
B24: Manik | C24: Indiranagar Resi GFCs [Pkgs 4] | D24: 0.004
B25: Manik | C25: MT Plano [LOD 200 and Approvals] [Pkgs 8] | D25: 0.7
B26: Manik | C26: Ooty Resi [LOD 200 and Approvals] [Pkgs 26] [ON HOLD]
B27: Manik | C27: OtR-Oota [LOD 200 and Approvals] [Pkgs 3] | D27: 0.15
B29: Atul L | C29: Total Packages [11 Pkgs] | D29: =SUM(D30:D34) -> 0
B30: Atul P | C30: TuiG FKH [V20, V30 and V40] [Pkgs 3] | G30: LoD 350 - V20, V30 and V40
B31: Atul P | C31: Harohalli FKH [V30, V40 and V50] [Pkgs 3] | G31: LoD 350 - V30, V40
B32: Atul P | C32: Violet Hill FKH [P-1 D & P-2 U][Pkgs 2] | G32: LoD 100 - Concept to be finalized for product brochure & walkthrough
B33: Atul P | C33: Shreegaon FKH [V50 C] [Pkgs 1]
B34: Atul P | C34: OTF FKH V50 C and V50 D [Pkgs 2]
B36: Prakash C | C36: AtR Ph 1, 2a, 2b [LOD 350] [Pkgs 1] | D36: 0.01
B37: Prakash C | C37: AtR Ph 2c [LOD 350] [Pkgs 2] | D37: 0.02
B38: Prakash C | C38: AtR Ph 3 [LOD 350] except Villa block 33[Pkgs 15] | D38: 0.36 | E38: 2 | F38: 0.01
B39: Prakash C | C39: AtR - C [LOD 350] [Pkgs 4] | D39: 0.41 | E39: 1 | F39: 0.13
B40: Prakash C | C40: PoaRR-Res [LOD 350] [Pkgs 3] | D40: 0.36
B41: Prakash C | C41: PoaRR-T08 [LOD 350] [Pkgs 8] | D41: 2.1
B42: Prakash C | C42: ITQE-Ph1 [LOD 350] [Pkgs 3] | D42: 0.08 | G42: LoD 350 - Master Plan | Site Development, LoD 350 - Amenities & Facilities | Community spaces
...

Sheet Goal Summary 25Q4
H1: =SUBTOTAL(3,H10:H1427)/2 -> 353 | I1: =SUBTOTAL(3,I10:I1427)/2 -> 0 | J1: =SUBTOTAL(3,J10:J1427)/2 -> 0 | K1: =SUBTOTAL(3,K10:K1427)/2 -> 0 | O1: =SUM(O8) -> 157.0698 | P1: =SUM(P8) -> 0 | Q1: =SUM(Q8) -> 0 | R1: =SUM(R8) -> 0
B2: Design Goals 2026 | H2: Design Packages | I2: Design Packages | J2: Design Packages | K2: Design Packages | O2: Design Fees | P2: Design Fees | Q2: Design Fees | R2: Design Fees
B4: Project Design | H4: Q1 | I4: Q2 | J4: Q3 | K4: Q4 | O4: Q1 | P4: Q2 | Q4: Q3 | R4: Q4
H8: =SUM(H10+H22+H113+H235+H308+H415+H809+H354) -> 582 | I8: =SUM(I10+I22+I113+I235+I308+I415+I809+I354) -> 0 | J8: =SUM(J10+J22+J113+J235+J308+J415+J809+J354) -> 0 | K8: =SUM(K10+K22+K113+K235+K308+K415+K809+K354) -> 0 | O8: =SUM(O10+O22+O113+O235+O308+O415+O809+O354) -> 157.0698 | P8: =SUM(P10+P22+P113+P235+P308+P415+P809+P354) -> 0 | Q8: =SUM(Q10+Q22+Q113+Q235+Q308+Q415+Q809+Q354) -> 0 | R8: =SUM(R10+R22+R113+R235+R308+R415+R809+R354) -> 0
B10: Atul | C10: Design [FKH, Units] | D10: Architecture | H10: =SUM(H12+H19) -> 16 | O10: =SUM(O12+O19) -> 0.45
B12: FKH | C12: [Experience Homes] | H12: =SUM(H13:H17) -> 10 | O12: =SUM(O13:O17) -> 0
B13: Saji | C13: TuiG | D13: Architecture | H13: 3
B14: Saji | C14: Harohalli | D14: Architecture | H14: 2
C15: Violet Hill | D15: Architecture | H15: 1
C16: Shreegaon | D16: Architecture | H16: 2
C17: One Tiny Flower | D17: Architecture | H17: 2
B19: Individual Units GFC | H19: =SUM(H20:H20) -> 6 | O19: =SUM(O20:O20) -> 0.45
C20: Units - Personalised | D20: Architecture | H20: 6 | O20: 0.45
B22: Cijey | C22: Design [ITQE | Srjp | NH | OTR] | D22: Architecture | H22: =SUM(H24+H55+H63+H70+H84+H90+H101+H105+H110+H66+H94) -> 65 | O22: =SUM(O24+O55+O63+O70+O84+O90+O101+O105+O110+O66+O94) -> 51.697725
B24: ITQE | H24: =COUNTA(H25:H53) -> 29 | O24: =SUM(O25:O53) -> 7.6
C25: ITQE Ph 1 | D25: Architecture | H25: Amenities & Facilities | Clubhouse—Interiors and Facilities | O25: 0.26
