Workbook

Sheet Summary
F1: Packages Summary
C3: 0059 | Pursuit of a Radical Rhapsody | Tower 8 | F3: Total | G3: Released Till Date | H3: Released Till Dec 23 | I3: Balance | K3: AR | M3: Planned Packages CY 24 | N3: Q1 | O3: Q2 | P3: Q3 | Q3: Q4 | R3: Actual Packages CY 24 | S3: Q1 | T3: Q2 | U3: Q3 | V3: Q4 | X3: Planned Packages CY 25 | Y3: Q1 | Z3: Q2 | AA3: Q3 | AB3: Q4 | AC3: Actual Packages CY 25 | AD3: Q1 | AE3: Q2 | AF3: Q3 | AG3: Q4 | AI3: Planned Packages CY 26 | AJ3: Q1 | AK3: Q2 | AL3: Q3 | AM3: Q4 | AN3: Actual Packages CY 26 | AO3: Q1 | AP3: Q2 | AQ3: Q3 | AR3: Q4 | AT3: ST | AV3: Planned Packages CY 24 | AW3: Q1 | AX3: Q2 | AY3: Q3 | AZ3: Q4 | BA3: Actual Packages CY 24 | BB3: Q1 | BC3: Q2 | BD3: Q3 | BE3: Q4 | BG3: Planned Packages CY 25 | BH3: Q1 | BI3: Q2 | BJ3: Q3 | BK3: Q4 | BL3: Actual Packages CY 25 | BM3: Q1 | BN3: Q2 | BO3: Q3 | BP3: Q4 | BR3: Planned Packages CY 26 | BS3: Q1 | BT3: Q2 | BU3: Q3 | BV3: Q4 | BW3: Actual Packages CY 26 | BX3: Q1 | BY3: Q2 | BZ3: Q3 | CA3: Q4 | CC3: MEP | CE3: Planned Packages CY 24 | CF3: Q1 | CG3: Q2 | CH3: Q3 | CI3: Q4 | CJ3: Actual Packages CY 24 | CK3: Q1 | CL3: Q2 | CM3: Q3 | CN3: Q4 | CP3: Planned Packages CY 25 | CQ3: Q1 | CR3: Q2 | CS3: Q3 | CT3: Q4 | CU3: Actual Packages CY 25 | CV3: Q1 | CW3: Q2 | CX3: Q3 | CY3: Q4 | DA3: Planned Packages CY 26 | DB3: Q1 | DC3: Q2 | DD3: Q3 | DE3: Q4 | DF3: Actual Packages CY 26 | DG3: Q1 | DH3: Q2 | DI3: Q3 | DJ3: Q4 | DL3: UDLS | DN3: Planned Packages CY 24 | DO3: Q1 | DP3: Q2 | DQ3: Q3 | DR3: Q4 | DS3: Actual Packages CY 24 | DT3: Q1 | DU3: Q2 | DV3: Q3 | DW3: Q4 | DY3: Planned Packages CY 25 | DZ3: Q1 | EA3: Q2 | EB3: Q3 | EC3: Q4 | ED3: Actual Packages CY 25 | EE3: Q1 | EF3: Q2 | EG3: Q3 | EH3: Q4 | EJ3: Planned Packages CY 26 | EK3: Q1 | EL3: Q2 | EM3: Q3 | EN3: Q4 | EO3: Actual Packages CY 26 | EP3: Q1 | EQ3: Q2 | ER3: Q3 | ES3: Q4
C4: Design Packages | F4: =F9+F49+F92 -> 94 | G4: =G9+G49+G92 -> 32 | H4: =H9+H49+H92 -> 23 | I4: =I9+I49+I92 -> 62 | M4: =COUNTIF(M17,"=✔")+COUNTIF(M23,"=✔")+COUNTIF(M30,"=✔")+COUNTIF(M52:M61,"=✔")+COUNTIF(M11,"=✔")+COUNTIF(M39,"=✔")+COUNTIF(M64:M67,"=✔")+COUNTIF(M80:M83,"=✔")+COUNTIF(M86:M90,"=✔")+COUNTIF(M70:M77,"=✔")+COUNTIF(M95,"=✔") -> 28 | N4: =COUNTIF(N17,"=✔")+COUNTIF(N23,"=✔")+COUNTIF(N30,"=✔")+COUNTIF(N52:N61,"=✔")+COUNTIF(N11,"=✔")+COUNTIF(N39,"=✔")+COUNTIF(N64:N67,"=✔")+COUNTIF(N80:N83,"=✔")+COUNTIF(N86:N90,"=✔")+COUNTIF(N70:N77,"=✔")+COUNTIF(N95,"=✔") -> 14 | O4: =COUNTIF(O17,"=✔")+COUNTIF(O23,"=✔")+COUNTIF(O30,"=✔")+COUNTIF(O52:O61,"=✔")+COUNTIF(O11,"=✔")+COUNTIF(O39,"=✔")+COUNTIF(O64:O67,"=✔")+COUNTIF(O80:O83,"=✔")+COUNTIF(O86:O90,"=✔")+COUNTIF(O70:O77,"=✔")+COUNTIF(O95,"=✔") -> 6 | P4: =COUNTIF(P17,"=✔")+COUNTIF(P23,"=✔")+COUNTIF(P30,"=✔")+COUNTIF(P52:P61,"=✔")+COUNTIF(P11,"=✔")+COUNTIF(P39,"=✔")+COUNTIF(P64:P67,"=✔")+COUNTIF(P80:P83,"=✔")+COUNTIF(P86:P90,"=✔")+COUNTIF(P70:P77,"=✔")+COUNTIF(P95,"=✔") -> 3 | Q4: =COUNTIF(Q17,"=✔")+COUNTIF(Q23,"=✔")+COUNTIF(Q30,"=✔")+COUNTIF(Q52:Q61,"=✔")+COUNTIF(Q11,"=✔")+COUNTIF(Q39,"=✔")+COUNTIF(Q64:Q67,"=✔")+COUNTIF(Q80:Q83,"=✔")+COUNTIF(Q86:Q90,"=✔")+COUNTIF(Q70:Q77,"=✔")+COUNTIF(Q95,"=✔") -> 5 | R4: =COUNTIF(R17,"=✔")+COUNTIF(R23,"=✔")+COUNTIF(R30,"=✔")+COUNTIF(R52:R61,"=✔")+COUNTIF(R11,"=✔")+COUNTIF(R39,"=✔")+COUNTIF(R64:R67,"=✔")+COUNTIF(R80:R83,"=✔")+COUNTIF(R86:R90,"=✔")+COUNTIF(R70:R77,"=✔")+COUNTIF(R95,"=✔") -> 1 | S4: =COUNTIF(S17,"=✔")+COUNTIF(S23,"=✔")+COUNTIF(S30,"=✔")+COUNTIF(S52:S61,"=✔")+COUNTIF(S11,"=✔")+COUNTIF(S39,"=✔")+COUNTIF(S64:S67,"=✔")+COUNTIF(S80:S83,"=✔")+COUNTIF(S86:S90,"=✔")+COUNTIF(S70:S77,"=✔")+COUNTIF(S95,"=✔") -> 0 | T4: =COUNTIF(T17,"=✔")+COUNTIF(T23,"=✔")+COUNTIF(T30,"=✔")+COUNTIF(T52:T61,"=✔")+COUNTIF(T11,"=✔")+COUNTIF(T39,"=✔")+COUNTIF(T64:T67,"=✔")+COUNTIF(T80:T83,"=✔")+COUNTIF(T86:T90,"=✔")+COUNTIF(T70:T77,"=✔")+COUNTIF(T95,"=✔") -> 1 | ... V4: =COUNTIF(V17,"=✔")+COUNTIF(V23,"=✔")+COUNTIF(V30,"=✔")+COUNTIF(V52:V61,"=✔")+COUNTIF(V11,"=✔")+COUNTIF(V39,"=✔")+COUNTIF(V64:V67,"=✔")+COUNTIF(V80:V83,"=✔")+COUNTIF(V86:V90,"=✔")+COUNTIF(V70:V77,"=✔")+COUNTIF(V95,"=✔") -> 0 | X4: =COUNTIF(X17,"=✔")+COUNTIF(X23,"=✔")+COUNTIF(X30,"=✔")+COUNTIF(X52:X61,"=✔")+COUNTIF(X11,"=✔")+COUNTIF(X39,"=✔")+COUNTIF(X64:X67,"=✔")+COUNTIF(X80:X83,"=✔")+COUNTIF(X86:X90,"=✔")+COUNTIF(X70:X77,"=✔")+COUNTIF(X95,"=✔") -> 0 | Y4: =COUNTIF(Y17,"=✔")+COUNTIF(Y23,"=✔")+COUNTIF(Y30,"=✔")+COUNTIF(Y52:Y61,"=✔")+COUNTIF(Y11,"=✔")+COUNTIF(Y39,"=✔")+COUNTIF(Y64:Y67,"=✔")+COUNTIF(Y80:Y83,"=✔")+COUNTIF(Y86:Y90,"=✔")+COUNTIF(Y70:Y77,"=✔")+COUNTIF(Y95,"=✔") -> 0 | Z4: =COUNTIF(Z17,"=✔")+COUNTIF(Z23,"=✔")+COUNTIF(Z30,"=✔")+COUNTIF(Z52:Z61,"=✔")+COUNTIF(Z11,"=✔")+COUNTIF(Z39,"=✔")+COUNTIF(Z64:Z67,"=✔")+COUNTIF(Z80:Z83,"=✔")+COUNTIF(Z86:Z90,"=✔")+COUNTIF(Z70:Z77,"=✔")+COUNTIF(Z95,"=✔") -> 0 | AA4: =COUNTIF(AA17,"=✔")+COUNTIF(AA23,"=✔")+COUNTIF(AA30,"=✔")+COUNTIF(AA52:AA61,"=✔")+COUNTIF(AA11,"=✔")+COUNTIF(AA39,"=✔")+COUNTIF(AA64:AA67,"=✔")+COUNTIF(AA80:AA83,"=✔")+COUNTIF(AA86:AA90,"=✔")+COUNTIF(AA70:AA77,"=✔")+COUNTIF(AA95,"=✔") -> 0 | AB4: =COUNTIF(AB17,"=✔")+COUNTIF(AB23,"=✔")+COUNTIF(AB30,"=✔")+COUNTIF(AB52:AB61,"=✔")+COUNTIF(AB11,"=✔")+COUNTIF(AB39,"=✔")+COUNTIF(AB64:AB67,"=✔")+COUNTIF(AB80:AB83,"=✔")+COUNTIF(AB86:AB90,"=✔")+COUNTIF(AB70:AB77,"=✔")+COUNTIF(AB95,"=✔") -> 0 | AC4: =COUNTIF(AC17,"=✔")+COUNTIF(AC23,"=✔")+COUNTIF(AC30,"=✔")+COUNTIF(AC52:AC61,"=✔")+COUNTIF(AC11,"=✔")+COUNTIF(AC39,"=✔")+COUNTIF(AC64:AC67,"=✔")+COUNTIF(AC80:AC83,"=✔")+COUNTIF(AC86:AC90,"=✔")+COUNTIF(AC70:AC77,"=✔")+COUNTIF(AC95,"=✔") -> 0 | AD4: =COUNTIF(AD17,"=✔")+COUNTIF(AD23,"=✔")+COUNTIF(AD30,"=✔")+COUNTIF(AD52:AD61,"=✔")+COUNTIF(AD11,"=✔")+COUNTIF(AD39,"=✔")+COUNTIF(AD64:AD67,"=✔")+COUNTIF(AD80:AD83,"=✔")+COUNTIF(AD86:AD90,"=✔")+COUNTIF(AD70:AD77,"=✔")+COUNTIF(AD95,"=✔") -> 0 | AE4: =COUNTIF(AE17,"=✔")+COUNTIF(AE23,"=✔")+COUNTIF(AE30,"=✔")+COUNTIF(AE52:AE61,"=✔")+COUNTIF(AE11,"=✔")+COUNTIF(AE39,"=✔")+COUNTIF(AE64:AE67,"=✔")+COUNTIF(AE80:AE83,"=✔")+COUNTIF(AE86:AE90,"=✔")+COUNTIF(AE70:AE77,"=✔")+COUNTIF(AE95,"=✔") -> 0 | ... AG4: =COUNTIF(AG17,"=✔")+COUNTIF(AG23,"=✔")+COUNTIF(AG30,"=✔")+COUNTIF(AG52:AG61,"=✔")+COUNTIF(AG11,"=✔")+COUNTIF(AG39,"=✔")+COUNTIF(AG64:AG67,"=✔")+COUNTIF(AG80:AG83,"=✔")+COUNTIF(AG86:AG90,"=✔")+COUNTIF(AG70:AG77,"=✔")+COUNTIF(AG95,"=✔") -> 0 | AI4: =COUNTIF(AI17,"=✔")+COUNTIF(AI23,"=✔")+COUNTIF(AI30,"=✔")+COUNTIF(AI52:AI61,"=✔")+COUNTIF(AI11,"=✔")+COUNTIF(AI39,"=✔")+COUNTIF(AI64:AI67,"=✔")+COUNTIF(AI80:AI83,"=✔")+COUNTIF(AI86:AI90,"=✔")+COUNTIF(AI70:AI77,"=✔")+COUNTIF(AI95,"=✔") -> 0 | AJ4: =COUNTIF(AJ17,"=✔")+COUNTIF(AJ23,"=✔")+COUNTIF(AJ30,"=✔")+COUNTIF(AJ52:AJ61,"=✔")+COUNTIF(AJ11,"=✔")+COUNTIF(AJ39,"=✔")+COUNTIF(AJ64:AJ67,"=✔")+COUNTIF(AJ80:AJ83,"=✔")+COUNTIF(AJ86:AJ90,"=✔")+COUNTIF(AJ70:AJ77,"=✔")+COUNTIF(AJ95,"=✔") -> 0 | AK4: =COUNTIF(AK17,"=✔")+COUNTIF(AK23,"=✔")+COUNTIF(AK30,"=✔")+COUNTIF(AK52:AK61,"=✔")+COUNTIF(AK11,"=✔")+COUNTIF(AK39,"=✔")+COUNTIF(AK64:AK67,"=✔")+COUNTIF(AK80:AK83,"=✔")+COUNTIF(AK86:AK90,"=✔")+COUNTIF(AK70:AK77,"=✔")+COUNTIF(AK95,"=✔") -> 0 | AL4: =COUNTIF(AL17,"=✔")+COUNTIF(AL23,"=✔")+COUNTIF(AL30,"=✔")+COUNTIF(AL52:AL61,"=✔")+COUNTIF(AL11,"=✔")+COUNTIF(AL39,"=✔")+COUNTIF(AL64:AL67,"=✔")+COUNTIF(AL80:AL83,"=✔")+COUNTIF(AL86:AL90,"=✔")+COUNTIF(AL70:AL77,"=✔")+COUNTIF(AL95,"=✔") -> 0 | AM4: =COUNTIF(AM17,"=✔")+COUNTIF(AM23,"=✔")+COUNTIF(AM30,"=✔")+COUNTIF(AM52:AM61,"=✔")+COUNTIF(AM11,"=✔")+COUNTIF(AM39,"=✔")+COUNTIF(AM64:AM67,"=✔")+COUNTIF(AM80:AM83,"=✔")+COUNTIF(AM86:AM90,"=✔")+COUNTIF(AM70:AM77,"=✔")+COUNTIF(AM95,"=✔") -> 0 | AN4: =COUNTIF(AN17,"=✔")+COUNTIF(AN23,"=✔")+COUNTIF(AN30,"=✔")+COUNTIF(AN52:AN61,"=✔")+COUNTIF(AN11,"=✔")+COUNTIF(AN39,"=✔")+COUNTIF(AN64:AN67,"=✔")+COUNTIF(AN80:AN83,"=✔")+COUNTIF(AN86:AN90,"=✔")+COUNTIF(AN70:AN77,"=✔")+COUNTIF(AN95,"=✔") -> 0 | AO4: =COUNTIF(AO17,"=✔")+COUNTIF(AO23,"=✔")+COUNTIF(AO30,"=✔")+COUNTIF(AO52:AO61,"=✔")+COUNTIF(AO11,"=✔")+COUNTIF(AO39,"=✔")+COUNTIF(AO64:AO67,"=✔")+COUNTIF(AO80:AO83,"=✔")+COUNTIF(AO86:AO90,"=✔")+COUNTIF(AO70:AO77,"=✔")+COUNTIF(AO95,"=✔") -> 0 | AP4: =COUNTIF(AP17,"=✔")+COUNTIF(AP23,"=✔")+COUNTIF(AP30,"=✔")+COUNTIF(AP52:AP61,"=✔")+COUNTIF(AP11,"=✔")+COUNTIF(AP39,"=✔")+COUNTIF(AP64:AP67,"=✔")+COUNTIF(AP80:AP83,"=✔")+COUNTIF(AP86:AP90,"=✔")+COUNTIF(AP70:AP77,"=✔")+COUNTIF(AP95,"=✔") -> 0 | ... AR4: =COUNTIF(AR17,"=✔")+COUNTIF(AR23,"=✔")+COUNTIF(AR30,"=✔")+COUNTIF(AR52:AR61,"=✔")+COUNTIF(AR11,"=✔")+COUNTIF(AR39,"=✔")+COUNTIF(AR64:AR67,"=✔")+COUNTIF(AR80:AR83,"=✔")+COUNTIF(AR86:AR90,"=✔")+COUNTIF(AR70:AR77,"=✔")+COUNTIF(AR95,"=✔") -> 0 | AV4: =COUNTIF(AV17,"=✔")+COUNTIF(AV23,"=✔")+COUNTIF(AV30,"=✔")+COUNTIF(AV52:AV61,"=✔")+COUNTIF(AV11,"=✔")+COUNTIF(AV39,"=✔")+COUNTIF(AV64:AV67,"=✔")+COUNTIF(AV80:AV83,"=✔")+COUNTIF(AV86:AV90,"=✔")+COUNTIF(AV70:AV77,"=✔")+COUNTIF(AV95,"=✔") -> 8 | AW4: =COUNTIF(AW17,"=✔")+COUNTIF(AW23,"=✔")+COUNTIF(AW30,"=✔")+COUNTIF(AW52:AW61,"=✔")+COUNTIF(AW11,"=✔")+COUNTIF(AW39,"=✔")+COUNTIF(AW64:AW67,"=✔")+COUNTIF(AW80:AW83,"=✔")+COUNTIF(AW86:AW90,"=✔")+COUNTIF(AW70:AW77,"=✔")+COUNTIF(AW95,"=✔") -> 0 | AX4: =COUNTIF(AX17,"=✔")+COUNTIF(AX23,"=✔")+COUNTIF(AX30,"=✔")+COUNTIF(AX52:AX61,"=✔")+COUNTIF(AX11,"=✔")+COUNTIF(AX39,"=✔")+COUNTIF(AX64:AX67,"=✔")+COUNTIF(AX80:AX83,"=✔")+COUNTIF(AX86:AX90,"=✔")+COUNTIF(AX70:AX77,"=✔")+COUNTIF(AX95,"=✔") -> 0 | AY4: =COUNTIF(AY17,"=✔")+COUNTIF(AY23,"=✔")+COUNTIF(AY30,"=✔")+COUNTIF(AY52:AY61,"=✔")+COUNTIF(AY11,"=✔")+COUNTIF(AY39,"=✔")+COUNTIF(AY64:AY67,"=✔")+COUNTIF(AY80:AY83,"=✔")+COUNTIF(AY86:AY90,"=✔")+COUNTIF(AY70:AY77,"=✔")+COUNTIF(AY95,"=✔") -> 3 | AZ4: =COUNTIF(AZ17,"=✔")+COUNTIF(AZ23,"=✔")+COUNTIF(AZ30,"=✔")+COUNTIF(AZ52:AZ61,"=✔")+COUNTIF(AZ11,"=✔")+COUNTIF(AZ39,"=✔")+COUNTIF(AZ64:AZ67,"=✔")+COUNTIF(AZ80:AZ83,"=✔")+COUNTIF(AZ86:AZ90,"=✔")+COUNTIF(AZ70:AZ77,"=✔")+COUNTIF(AZ95,"=✔") -> 5 | BA4: =COUNTIF(BA17,"=✔")+COUNTIF(BA23,"=✔")+COUNTIF(BA30,"=✔")+COUNTIF(BA52:BA61,"=✔")+COUNTIF(BA11,"=✔")+COUNTIF(BA39,"=✔")+COUNTIF(BA64:BA67,"=✔")+COUNTIF(BA80:BA83,"=✔")+COUNTIF(BA86:BA90,"=✔")+COUNTIF(BA70:BA77,"=✔")+COUNTIF(BA95,"=✔") -> 0 | BB4: =COUNTIF(BB17,"=✔")+COUNTIF(BB23,"=✔")+COUNTIF(BB30,"=✔")+COUNTIF(BB52:BB61,"=✔")+COUNTIF(BB11,"=✔")+COUNTIF(BB39,"=✔")+COUNTIF(BB64:BB67,"=✔")+COUNTIF(BB80:BB83,"=✔")+COUNTIF(BB86:BB90,"=✔")+COUNTIF(BB70:BB77,"=✔")+COUNTIF(BB95,"=✔") -> 0 | BC4: =COUNTIF(BC17,"=✔")+COUNTIF(BC23,"=✔")+COUNTIF(BC30,"=✔")+COUNTIF(BC52:BC61,"=✔")+COUNTIF(BC11,"=✔")+COUNTIF(BC39,"=✔")+COUNTIF(BC64:BC67,"=✔")+COUNTIF(BC80:BC83,"=✔")+COUNTIF(BC86:BC90,"=✔")+COUNTIF(BC70:BC77,"=✔")+COUNTIF(BC95,"=✔") -> 0 | ... CA4: =COUNTIF(CA17,"=✔")+COUNTIF(CA23,"=✔")+COUNTIF(CA30,"=✔")+COUNTIF(CA52:CA61,"=✔")+COUNTIF(CA11,"=✔")+COUNTIF(CA39,"=✔")+COUNTIF(CA64:CA67,"=✔")+COUNTIF(CA80:CA83,"=✔")+COUNTIF(CA86:CA90,"=✔")+COUNTIF(CA70:CA77,"=✔")+COUNTIF(CA95,"=✔") -> 0 | CE4: =COUNTIF(CE17,"=✔")+COUNTIF(CE23,"=✔")+COUNTIF(CE30,"=✔")+COUNTIF(CE52:CE61,"=✔")+COUNTIF(CE11,"=✔")+COUNTIF(CE39,"=✔")+COUNTIF(CE64:CE67,"=✔")+COUNTIF(CE80:CE83,"=✔")+COUNTIF(CE86:CE90,"=✔")+COUNTIF(CE70:CE77,"=✔")+COUNTIF(CE95,"=✔") -> 20 | CF4: =COUNTIF(CF17,"=✔")+COUNTIF(CF23,"=✔")+COUNTIF(CF30,"=✔")+COUNTIF(CF52:CF61,"=✔")+COUNTIF(CF11,"=✔")+COUNTIF(CF39,"=✔")+COUNTIF(CF64:CF67,"=✔")+COUNTIF(CF80:CF83,"=✔")+COUNTIF(CF86:CF90,"=✔")+COUNTIF(CF70:CF77,"=✔")+COUNTIF(CF95,"=✔") -> 0 | CG4: =COUNTIF(CG17,"=✔")+COUNTIF(CG23,"=✔")+COUNTIF(CG30,"=✔")+COUNTIF(CG52:CG61,"=✔")+COUNTIF(CG11,"=✔")+COUNTIF(CG39,"=✔")+COUNTIF(CG64:CG67,"=✔")+COUNTIF(CG80:CG83,"=✔")+COUNTIF(CG86:CG90,"=✔")+COUNTIF(CG70:CG77,"=✔")+COUNTIF(CG95,"=✔") -> 0 | CH4: =COUNTIF(CH17,"=✔")+COUNTIF(CH23,"=✔")+COUNTIF(CH30,"=✔")+COUNTIF(CH52:CH61,"=✔")+COUNTIF(CH11,"=✔")+COUNTIF(CH39,"=✔")+COUNTIF(CH64:CH67,"=✔")+COUNTIF(CH80:CH83,"=✔")+COUNTIF(CH86:CH90,"=✔")+COUNTIF(CH70:CH77,"=✔")+COUNTIF(CH95,"=✔") -> 10 | CI4: =COUNTIF(CI17,"=✔")+COUNTIF(CI23,"=✔")+COUNTIF(CI30,"=✔")+COUNTIF(CI52:CI61,"=✔")+COUNTIF(CI11,"=✔")+COUNTIF(CI39,"=✔")+COUNTIF(CI64:CI67,"=✔")+COUNTIF(CI80:CI83,"=✔")+COUNTIF(CI86:CI90,"=✔")+COUNTIF(CI70:CI77,"=✔")+COUNTIF(CI95,"=✔") -> 10 | CJ4: =COUNTIF(CJ17,"=✔")+COUNTIF(CJ23,"=✔")+COUNTIF(CJ30,"=✔")+COUNTIF(CJ52:CJ61,"=✔")+COUNTIF(CJ11,"=✔")+COUNTIF(CJ39,"=✔")+COUNTIF(CJ64:CJ67,"=✔")+COUNTIF(CJ80:CJ83,"=✔")+COUNTIF(CJ86:CJ90,"=✔")+COUNTIF(CJ70:CJ77,"=✔")+COUNTIF(CJ95,"=✔") -> 2 | CK4: =COUNTIF(CK17,"=✔")+COUNTIF(CK23,"=✔")+COUNTIF(CK30,"=✔")+COUNTIF(CK52:CK61,"=✔")+COUNTIF(CK11,"=✔")+COUNTIF(CK39,"=✔")+COUNTIF(CK64:CK67,"=✔")+COUNTIF(CK80:CK83,"=✔")+COUNTIF(CK86:CK90,"=✔")+COUNTIF(CK70:CK77,"=✔")+COUNTIF(CK95,"=✔") -> 0 | CL4: =COUNTIF(CL17,"=✔")+COUNTIF(CL23,"=✔")+COUNTIF(CL30,"=✔")+COUNTIF(CL52:CL61,"=✔")+COUNTIF(CL11,"=✔")+COUNTIF(CL39,"=✔")+COUNTIF(CL64:CL67,"=✔")+COUNTIF(CL80:CL83,"=✔")+COUNTIF(CL86:CL90,"=✔")+COUNTIF(CL70:CL77,"=✔")+COUNTIF(CL95,"=✔") -> 0 | ... DJ4: =COUNTIF(DJ17,"=✔")+COUNTIF(DJ23,"=✔")+COUNTIF(DJ30,"=✔")+COUNTIF(DJ52:DJ61,"=✔")+COUNTIF(DJ11,"=✔")+COUNTIF(DJ39,"=✔")+COUNTIF(DJ64:DJ67,"=✔")+COUNTIF(DJ80:DJ83,"=✔")+COUNTIF(DJ86:DJ90,"=✔")+COUNTIF(DJ70:DJ77,"=✔")+COUNTIF(DJ95,"=✔") -> 0 | DN4: =COUNTIF(DN17,"=✔")+COUNTIF(DN23,"=✔")+COUNTIF(DN30,"=✔")+COUNTIF(DN52:DN61,"=✔")+COUNTIF(DN11,"=✔")+COUNTIF(DN39,"=✔")+COUNTIF(DN64:DN67,"=✔")+COUNTIF(DN80:DN83,"=✔")+COUNTIF(DN86:DN90,"=✔")+COUNTIF(DN70:DN77,"=✔")+COUNTIF(DN95,"=✔") -> 13 | DO4: =COUNTIF(DO17,"=✔")+COUNTIF(DO23,"=✔")+COUNTIF(DO30,"=✔")+COUNTIF(DO52:DO61,"=✔")+COUNTIF(DO11,"=✔")+COUNTIF(DO39,"=✔")+COUNTIF(DO64:DO67,"=✔")+COUNTIF(DO80:DO83,"=✔")+COUNTIF(DO86:DO90,"=✔")+COUNTIF(DO70:DO77,"=✔")+COUNTIF(DO95,"=✔") -> 4 | DP4: =COUNTIF(DP17,"=✔")+COUNTIF(DP23,"=✔")+COUNTIF(DP30,"=✔")+COUNTIF(DP52:DP61,"=✔")+COUNTIF(DP11,"=✔")+COUNTIF(DP39,"=✔")+COUNTIF(DP64:DP67,"=✔")+COUNTIF(DP80:DP83,"=✔")+COUNTIF(DP86:DP90,"=✔")+COUNTIF(DP70:DP77,"=✔")+COUNTIF(DP95,"=✔") -> 2 | DQ4: =COUNTIF(DQ17,"=✔")+COUNTIF(DQ23,"=✔")+COUNTIF(DQ30,"=✔")+COUNTIF(DQ52:DQ61,"=✔")+COUNTIF(DQ11,"=✔")+COUNTIF(DQ39,"=✔")+COUNTIF(DQ64:DQ67,"=✔")+COUNTIF(DQ80:DQ83,"=✔")+COUNTIF(DQ86:DQ90,"=✔")+COUNTIF(DQ70:DQ77,"=✔")+COUNTIF(DQ95,"=✔") -> 2 | DR4: =COUNTIF(DR17,"=✔")+COUNTIF(DR23,"=✔")+COUNTIF(DR30,"=✔")+COUNTIF(DR52:DR61,"=✔")+COUNTIF(DR11,"=✔")+COUNTIF(DR39,"=✔")+COUNTIF(DR64:DR67,"=✔")+COUNTIF(DR80:DR83,"=✔")+COUNTIF(DR86:DR90,"=✔")+COUNTIF(DR70:DR77,"=✔")+COUNTIF(DR95,"=✔") -> 5 | DS4: =COUNTIF(DS17,"=✔")+COUNTIF(DS23,"=✔")+COUNTIF(DS30,"=✔")+COUNTIF(DS52:DS61,"=✔")+COUNTIF(DS11,"=✔")+COUNTIF(DS39,"=✔")+COUNTIF(DS64:DS67,"=✔")+COUNTIF(DS80:DS83,"=✔")+COUNTIF(DS86:DS90,"=✔")+COUNTIF(DS70:DS77,"=✔")+COUNTIF(DS95,"=✔") -> 3 | DT4: =COUNTIF(DT17,"=✔")+COUNTIF(DT23,"=✔")+COUNTIF(DT30,"=✔")+COUNTIF(DT52:DT61,"=✔")+COUNTIF(DT11,"=✔")+COUNTIF(DT39,"=✔")+COUNTIF(DT64:DT67,"=✔")+COUNTIF(DT80:DT83,"=✔")+COUNTIF(DT86:DT90,"=✔")+COUNTIF(DT70:DT77,"=✔")+COUNTIF(DT95,"=✔") -> 0 | DU4: =COUNTIF(DU17,"=✔")+COUNTIF(DU23,"=✔")+COUNTIF(DU30,"=✔")+COUNTIF(DU52:DU61,"=✔")+COUNTIF(DU11,"=✔")+COUNTIF(DU39,"=✔")+COUNTIF(DU64:DU67,"=✔")+COUNTIF(DU80:DU83,"=✔")+COUNTIF(DU86:DU90,"=✔")+COUNTIF(DU70:DU77,"=✔")+COUNTIF(DU95,"=✔") -> 0 | ... ES4: =COUNTIF(ES17,"=✔")+COUNTIF(ES23,"=✔")+COUNTIF(ES30,"=✔")+COUNTIF(ES52:ES61,"=✔")+COUNTIF(ES11,"=✔")+COUNTIF(ES39,"=✔")+COUNTIF(ES64:ES67,"=✔")+COUNTIF(ES80:ES83,"=✔")+COUNTIF(ES86:ES90,"=✔")+COUNTIF(ES70:ES77,"=✔")+COUNTIF(ES95,"=✔") -> 0
C5: Design Fees
C9: DESIGN | F9: =F11+F17+F23+F30+F39 -> 16 | G9: =G11+G17+G23+G30+G39 -> 16 | H9: =H11+H17+H23+H30+H39 -> 16 | I9: =I11+I17+I23+I30+I39 -> 0
C11: 1 | D11: Contract + Design Brief | F11: =COUNTIF('Design Fee'!AU11,">0")+COUNTIF('Design Fee'!EO11,">0")+COUNTIF('Design Fee'!II11,">0")+COUNTIF('Design Fee'!ME11,">0") -> 1 | G11: =COUNTIF('Design Fee'!AX11,">0")+COUNTIF('Design Fee'!ER11,">0")+COUNTIF('Design Fee'!IL11,">0")+COUNTIF('Design Fee'!MF11,">0") -> 1 | H11: =COUNTIF('Design Fee'!AY11,">0")+COUNTIF('Design Fee'!ES11,">0")+COUNTIF('Design Fee'!IM11,">0")+COUNTIF('Design Fee'!MG11,">0") -> 1 | I11: =F11-G11 -> 0 | K11: =IF('Design Fee'!AU11>0,"✔","-") -> ✔ | M11: =IF('Design Fee'!AZ11>0,"✔","-") -> - | N11: =IF('Design Fee'!BA11>0,"✔","-") -> - | O11: =IF('Design Fee'!BB11>0,"✔","-") -> - | P11: =IF('Design Fee'!BC11>0,"✔","-") -> - | Q11: =IF('Design Fee'!BD11>0,"✔","-") -> - | R11: =IF('Design Fee'!BF11>0,"✔","-") -> - | S11: =IF('Design Fee'!BG11>0,"✔","-") -> - | T11: =IF('Design Fee'!BH11>0,"✔","-") -> - | U11: =IF('Design Fee'!BI11>0,"✔","-") -> - | V11: =IF('Design Fee'!BJ11>0,"✔","-") -> - | X11: =IF('Design Fee'!CE11>0,"✔","-") -> - | Y11: =IF('Design Fee'!CF11>0,"✔","-") -> - | Z11: =IF('Design Fee'!CG11>0,"✔","-") -> - | AA11: =IF('Design Fee'!CH11>0,"✔","-") -> - | AB11: =IF('Design Fee'!CI11>0,"✔","-") -> - | AC11: =IF('Design Fee'!CK11>0,"✔","-") -> - | AD11: =IF('Design Fee'!CL11>0,"✔","-") -> - | AE11: =IF('Design Fee'!CM11>0,"✔","-") -> - | AF11: =IF('Design Fee'!CN11>0,"✔","-") -> - | AG11: =IF('Design Fee'!CO11>0,"✔","-") -> - | AI11: =IF('Design Fee'!DJ11>0,"✔","-") -> - | AJ11: =IF('Design Fee'!DK11>0,"✔","-") -> - | AK11: =IF('Design Fee'!DL11>0,"✔","-") -> - | AL11: =IF('Design Fee'!DM11>0,"✔","-") -> - | AM11: =IF('Design Fee'!DN11>0,"✔","-") -> - | AN11: =IF('Design Fee'!DP11>0,"✔","-") -> - | AO11: =IF('Design Fee'!DQ11>0,"✔","-") -> - | AP11: =IF('Design Fee'!DR11>0,"✔","-") -> - | AQ11: =IF('Design Fee'!DS11>0,"✔","-") -> - | AR11: =IF('Design Fee'!DT11>0,"✔","-") -> - | AT11: =IF('Design Fee'!EO11>0,"✔","-") -> - | AV11: =IF('Design Fee'!ET11>0,"✔","-") -> - | AW11: =IF('Design Fee'!EU11>0,"✔","-") -> - | AX11: =IF('Design Fee'!EV11>0,"✔","-") -> - | AY11: =IF('Design Fee'!EW11>0,"✔","-") -> - | AZ11: =IF('Design Fee'!EX11>0,"✔","-") -> - | BA11: =IF('Design Fee'!EZ11>0,"✔","-") -> - | BB11: =IF('Design Fee'!FA11>0,"✔","-") -> - | BC11: =IF('Design Fee'!FB11>0,"✔","-") -> - | BD11: =IF('Design Fee'!FC11>0,"✔","-") -> - | BE11: =IF('Design Fee'!FD11>0,"✔","-") -> - | BG11: =IF('Design Fee'!FY11>0,"✔","-") -> - | BH11: =IF('Design Fee'!FZ11>0,"✔","-") -> - | BI11: =IF('Design Fee'!GA11>0,"✔","-") -> - | BJ11: =IF('Design Fee'!GB11>0,"✔","-") -> - | BK11: =IF('Design Fee'!GC11>0,"✔","-") -> - | BL11: =IF('Design Fee'!GE11>0,"✔","-") -> - | BM11: =IF('Design Fee'!GF11>0,"✔","-") -> - | BN11: =IF('Design Fee'!GG11>0,"✔","-") -> - | BO11: =IF('Design Fee'!GH11>0,"✔","-") -> - | BP11: =IF('Design Fee'!GI11>0,"✔","-") -> - | BR11: =IF('Design Fee'!HD11>0,"✔","-") -> - | BS11: =IF('Design Fee'!HE11>0,"✔","-") -> - | BT11: =IF('Design Fee'!HF11>0,"✔","-") -> - | BU11: =IF('Design Fee'!HG11>0,"✔","-") -> - | BV11: =IF('Design Fee'!HH11>0,"✔","-") -> - | BW11: =IF('Design Fee'!HJ11>0,"✔","-") -> - | BX11: =IF('Design Fee'!HK11>0,"✔","-") -> - | BY11: =IF('Design Fee'!HL11>0,"✔","-") -> - | BZ11: =IF('Design Fee'!HM11>0,"✔","-") -> - | CA11: =IF('Design Fee'!HN11>0,"✔","-") -> - | CC11: =IF('Design Fee'!II11>0,"✔","-") -> - | CE11: =IF('Design Fee'!IN11>0,"✔","-") -> - | CF11: =IF('Design Fee'!IO11>0,"✔","-") -> - | CG11: =IF('Design Fee'!IP11>0,"✔","-") -> - | CH11: =IF('Design Fee'!IQ11>0,"✔","-") -> - | CI11: =IF('Design Fee'!IR11>0,"✔","-") -> - | CJ11: =IF('Design Fee'!IT11>0,"✔","-") -> - | CK11: =IF('Design Fee'!IU11>0,"✔","-") -> - | CL11: =IF('Design Fee'!IV11>0,"✔","-") -> - | CM11: =IF('Design Fee'!IW11>0,"✔","-") -> - | CN11: =IF('Design Fee'!IX11>0,"✔","-") -> - | CP11: =IF('Design Fee'!JS11>0,"✔","-") -> - | CQ11: =IF('Design Fee'!JT11>0,"✔","-") -> - | CR11: =IF('Design Fee'!JU11>0,"✔","-") -> - | CS11: =IF('Design Fee'!JV11>0,"✔","-") -> - | CT11: =IF('Design Fee'!JW11>0,"✔","-") -> - | CU11: =IF('Design Fee'!JY11>0,"✔","-") -> - | CV11: =IF('Design Fee'!JZ11>0,"✔","-") -> - | CW11: =IF('Design Fee'!KA11>0,"✔","-") -> - | CX11: =IF('Design Fee'!KB11>0,"✔","-") -> - | CY11: =IF('Design Fee'!KC11>0,"✔","-") -> - | DA11: =IF('Design Fee'!KX11>0,"✔","-") -> - | DB11: =IF('Design Fee'!KY11>0,"✔","-") -> - | DC11: =IF('Design Fee'!KZ11>0,"✔","-") -> - | DD11: =IF('Design Fee'!LA11>0,"✔","-") -> - | DE11: =IF('Design Fee'!LB11>0,"✔","-") -> - | DF11: =IF('Design Fee'!LD11>0,"✔","-") -> - | DG11: =IF('Design Fee'!LE11>0,"✔","-") -> - | DH11: =IF('Design Fee'!LF11>0,"✔","-") -> - | DI11: =IF('Design Fee'!LG11>0,"✔","-") -> - | DJ11: =IF('Design Fee'!LH11>0,"✔","-") -> - | DL11: =IF('Design Fee'!MC11>0,"✔","-") -> - | DN11: =IF('Design Fee'!MH11>0,"✔","-") -> - | DO11: =IF('Design Fee'!MI11>0,"✔","-") -> - | DP11: =IF('Design Fee'!MJ11>0,"✔","-") -> - | DQ11: =IF('Design Fee'!MK11>0,"✔","-") -> - | DR11: =IF('Design Fee'!ML11>0,"✔","-") -> - | DS11: =IF('Design Fee'!MN11>0,"✔","-") -> - | DT11: =IF('Design Fee'!MO11>0,"✔","-") -> - | DU11: =IF('Design Fee'!MP11>0,"✔","-") -> - | DV11: =IF('Design Fee'!MQ11>0,"✔","-") -> - | DW11: =IF('Design Fee'!MR11>0,"✔","-") -> - | DY11: =IF('Design Fee'!NM11>0,"✔","-") -> - | DZ11: =IF('Design Fee'!NN11>0,"✔","-") -> - | EA11: =IF('Design Fee'!NO11>0,"✔","-") -> - | EB11: =IF('Design Fee'!NP11>0,"✔","-") -> - | EC11: =IF('Design Fee'!NQ11>0,"✔","-") -> - | ED11: =IF('Design Fee'!NS11>0,"✔","-") -> - | EE11: =IF('Design Fee'!NT11>0,"✔","-") -> - | EF11: =IF('Design Fee'!NU11>0,"✔","-") -> - | EG11: =IF('Design Fee'!NV11>0,"✔","-") -> - | EH11: =IF('Design Fee'!NW11>0,"✔","-") -> - | EJ11: =IF('Design Fee'!OR11>0,"✔","-") -> - | EK11: =IF('Design Fee'!OS11>0,"✔","-") -> - | EL11: =IF('Design Fee'!OT11>0,"✔","-") -> - | EM11: =IF('Design Fee'!OU11>0,"✔","-") -> - | EN11: =IF('Design Fee'!OV11>0,"✔","-") -> - | EO11: =IF('Design Fee'!OX11>0,"✔","-") -> - | EP11: =IF('Design Fee'!OY11>0,"✔","-") -> - | EQ11: =IF('Design Fee'!OZ11>0,"✔","-") -> - | ER11: =IF('Design Fee'!PA11>0,"✔","-") -> - | ES11: =IF('Design Fee'!PB11>0,"✔","-") -> -
C12: 1 | D12: Vision Statement | K12: =IF('Design Fee'!AU12>0,"✔","-") -> - | M12: =IF('Design Fee'!AZ12>0,"✔","-") -> - | N12: =IF('Design Fee'!BA12>0,"✔","-") -> - | O12: =IF('Design Fee'!BB12>0,"✔","-") -> - | P12: =IF('Design Fee'!BC12>0,"✔","-") -> - | Q12: =IF('Design Fee'!BD12>0,"✔","-") -> - | R12: =IF('Design Fee'!BF12>0,"✔","-") -> - | S12: =IF('Design Fee'!BG12>0,"✔","-") -> - | T12: =IF('Design Fee'!BH12>0,"✔","-") -> - | U12: =IF('Design Fee'!BI12>0,"✔","-") -> - | V12: =IF('Design Fee'!BJ12>0,"✔","-") -> - | X12: =IF('Design Fee'!CE12>0,"✔","-") -> - | Y12: =IF('Design Fee'!CF12>0,"✔","-") -> - | Z12: =IF('Design Fee'!CG12>0,"✔","-") -> - | AA12: =IF('Design Fee'!CH12>0,"✔","-") -> - | AB12: =IF('Design Fee'!CI12>0,"✔","-") -> - | AC12: =IF('Design Fee'!CK12>0,"✔","-") -> - | AD12: =IF('Design Fee'!CL12>0,"✔","-") -> - | AE12: =IF('Design Fee'!CM12>0,"✔","-") -> - | AF12: =IF('Design Fee'!CN12>0,"✔","-") -> - | AG12: =IF('Design Fee'!CO12>0,"✔","-") -> - | AI12: =IF('Design Fee'!DJ12>0,"✔","-") -> - | AJ12: =IF('Design Fee'!DK12>0,"✔","-") -> - | AK12: =IF('Design Fee'!DL12>0,"✔","-") -> - | AL12: =IF('Design Fee'!DM12>0,"✔","-") -> - | AM12: =IF('Design Fee'!DN12>0,"✔","-") -> - | AN12: =IF('Design Fee'!DP12>0,"✔","-") -> - | AO12: =IF('Design Fee'!DQ12>0,"✔","-") -> - | AP12: =IF('Design Fee'!DR12>0,"✔","-") -> - | AQ12: =IF('Design Fee'!DS12>0,"✔","-") -> - | AR12: =IF('Design Fee'!DT12>0,"✔","-") -> - | AT12: =IF('Design Fee'!EO12>0,"✔","-") -> - | AV12: =IF('Design Fee'!ET12>0,"✔","-") -> - | AW12: =IF('Design Fee'!EU12>0,"✔","-") -> - | AX12: =IF('Design Fee'!EV12>0,"✔","-") -> - | AY12: =IF('Design Fee'!EW12>0,"✔","-") -> - | AZ12: =IF('Design Fee'!EX12>0,"✔","-") -> - | BA12: =IF('Design Fee'!EZ12>0,"✔","-") -> - | BB12: =IF('Design Fee'!FA12>0,"✔","-") -> - | BC12: =IF('Design Fee'!FB12>0,"✔","-") -> - | BD12: =IF('Design Fee'!FC12>0,"✔","-") -> - | BE12: =IF('Design Fee'!FD12>0,"✔","-") -> - | BG12: =IF('Design Fee'!FY12>0,"✔","-") -> - | BH12: =IF('Design Fee'!FZ12>0,"✔","-") -> - | BI12: =IF('Design Fee'!GA12>0,"✔","-") -> - | BJ12: =IF('Design Fee'!GB12>0,"✔","-") -> - | BK12: =IF('Design Fee'!GC12>0,"✔","-") -> - | BL12: =IF('Design Fee'!GE12>0,"✔","-") -> - | BM12: =IF('Design Fee'!GF12>0,"✔","-") -> - | BN12: =IF('Design Fee'!GG12>0,"✔","-") -> - | BO12: =IF('Design Fee'!GH12>0,"✔","-") -> - | BP12: =IF('Design Fee'!GI12>0,"✔","-") -> - | BR12: =IF('Design Fee'!HD12>0,"✔","-") -> - | BS12: =IF('Design Fee'!HE12>0,"✔","-") -> - | BT12: =IF('Design Fee'!HF12>0,"✔","-") -> - | BU12: =IF('Design Fee'!HG12>0,"✔","-") -> - | BV12: =IF('Design Fee'!HH12>0,"✔","-") -> - | BW12: =IF('Design Fee'!HJ12>0,"✔","-") -> - | BX12: =IF('Design Fee'!HK12>0,"✔","-") -> - | BY12: =IF('Design Fee'!HL12>0,"✔","-") -> - | BZ12: =IF('Design Fee'!HM12>0,"✔","-") -> - | CA12: =IF('Design Fee'!HN12>0,"✔","-") -> - | CC12: =IF('Design Fee'!II12>0,"✔","-") -> - | CE12: =IF('Design Fee'!IN12>0,"✔","-") -> - | CF12: =IF('Design Fee'!IO12>0,"✔","-") -> - | CG12: =IF('Design Fee'!IP12>0,"✔","-") -> - | CH12: =IF('Design Fee'!IQ12>0,"✔","-") -> - | CI12: =IF('Design Fee'!IR12>0,"✔","-") -> - | CJ12: =IF('Design Fee'!IT12>0,"✔","-") -> - | CK12: =IF('Design Fee'!IU12>0,"✔","-") -> - | CL12: =IF('Design Fee'!IV12>0,"✔","-") -> - | CM12: =IF('Design Fee'!IW12>0,"✔","-") -> - | CN12: =IF('Design Fee'!IX12>0,"✔","-") -> - | CP12: =IF('Design Fee'!JS12>0,"✔","-") -> - | CQ12: =IF('Design Fee'!JT12>0,"✔","-") -> - | CR12: =IF('Design Fee'!JU12>0,"✔","-") -> - | CS12: =IF('Design Fee'!JV12>0,"✔","-") -> - | CT12: =IF('Design Fee'!JW12>0,"✔","-") -> - | CU12: =IF('Design Fee'!JY12>0,"✔","-") -> - | CV12: =IF('Design Fee'!JZ12>0,"✔","-") -> - | CW12: =IF('Design Fee'!KA12>0,"✔","-") -> - | CX12: =IF('Design Fee'!KB12>0,"✔","-") -> - | CY12: =IF('Design Fee'!KC12>0,"✔","-") -> - | DA12: =IF('Design Fee'!KX12>0,"✔","-") -> - | DB12: =IF('Design Fee'!KY12>0,"✔","-") -> - | DC12: =IF('Design Fee'!KZ12>0,"✔","-") -> - | DD12: =IF('Design Fee'!LA12>0,"✔","-") -> - | DE12: =IF('Design Fee'!LB12>0,"✔","-") -> - | DF12: =IF('Design Fee'!LD12>0,"✔","-") -> - | DG12: =IF('Design Fee'!LE12>0,"✔","-") -> - | DH12: =IF('Design Fee'!LF12>0,"✔","-") -> - | DI12: =IF('Design Fee'!LG12>0,"✔","-") -> - | DJ12: =IF('Design Fee'!LH12>0,"✔","-") -> - | DL12: =IF('Design Fee'!MC12>0,"✔","-") -> - | DN12: =IF('Design Fee'!MH12>0,"✔","-") -> - | DO12: =IF('Design Fee'!MI12>0,"✔","-") -> - | DP12: =IF('Design Fee'!MJ12>0,"✔","-") -> - | DQ12: =IF('Design Fee'!MK12>0,"✔","-") -> - | DR12: =IF('Design Fee'!ML12>0,"✔","-") -> - | DS12: =IF('Design Fee'!MN12>0,"✔","-") -> - | DT12: =IF('Design Fee'!MO12>0,"✔","-") -> - | DU12: =IF('Design Fee'!MP12>0,"✔","-") -> - | DV12: =IF('Design Fee'!MQ12>0,"✔","-") -> - | DW12: =IF('Design Fee'!MR12>0,"✔","-") -> - | DY12: =IF('Design Fee'!NM12>0,"✔","-") -> - | DZ12: =IF('Design Fee'!NN12>0,"✔","-") -> - | EA12: =IF('Design Fee'!NO12>0,"✔","-") -> - | EB12: =IF('Design Fee'!NP12>0,"✔","-") -> - | EC12: =IF('Design Fee'!NQ12>0,"✔","-") -> - | ED12: =IF('Design Fee'!NS12>0,"✔","-") -> - | EE12: =IF('Design Fee'!NT12>0,"✔","-") -> - | EF12: =IF('Design Fee'!NU12>0,"✔","-") -> - | EG12: =IF('Design Fee'!NV12>0,"✔","-") -> - | EH12: =IF('Design Fee'!NW12>0,"✔","-") -> - | EJ12: =IF('Design Fee'!OR12>0,"✔","-") -> - | EK12: =IF('Design Fee'!OS12>0,"✔","-") -> - | EL12: =IF('Design Fee'!OT12>0,"✔","-") -> - | EM12: =IF('Design Fee'!OU12>0,"✔","-") -> - | EN12: =IF('Design Fee'!OV12>0,"✔","-") -> - | EO12: =IF('Design Fee'!OX12>0,"✔","-") -> - | EP12: =IF('Design Fee'!OY12>0,"✔","-") -> - | EQ12: =IF('Design Fee'!OZ12>0,"✔","-") -> - | ER12: =IF('Design Fee'!PA12>0,"✔","-") -> - | ES12: =IF('Design Fee'!PB12>0,"✔","-") -> -
C13: 2 | D13: Land - Topographical Survey with information as per defined standard, | K13: =IF('Design Fee'!AU13>0,"✔","-") -> - | M13: =IF('Design Fee'!AZ13>0,"✔","-") -> - | N13: =IF('Design Fee'!BA13>0,"✔","-") -> - | O13: =IF('Design Fee'!BB13>0,"✔","-") -> - | P13: =IF('Design Fee'!BC13>0,"✔","-") -> - | Q13: =IF('Design Fee'!BD13>0,"✔","-") -> - | R13: =IF('Design Fee'!BF13>0,"✔","-") -> - | S13: =IF('Design Fee'!BG13>0,"✔","-") -> - | T13: =IF('Design Fee'!BH13>0,"✔","-") -> - | U13: =IF('Design Fee'!BI13>0,"✔","-") -> - | V13: =IF('Design Fee'!BJ13>0,"✔","-") -> - | X13: =IF('Design Fee'!CE13>0,"✔","-") -> - | Y13: =IF('Design Fee'!CF13>0,"✔","-") -> - | Z13: =IF('Design Fee'!CG13>0,"✔","-") -> - | AA13: =IF('Design Fee'!CH13>0,"✔","-") -> - | AB13: =IF('Design Fee'!CI13>0,"✔","-") -> - | AC13: =IF('Design Fee'!CK13>0,"✔","-") -> - | AD13: =IF('Design Fee'!CL13>0,"✔","-") -> - | AE13: =IF('Design Fee'!CM13>0,"✔","-") -> - | AF13: =IF('Design Fee'!CN13>0,"✔","-") -> - | AG13: =IF('Design Fee'!CO13>0,"✔","-") -> - | AI13: =IF('Design Fee'!DJ13>0,"✔","-") -> - | AJ13: =IF('Design Fee'!DK13>0,"✔","-") -> - | AK13: =IF('Design Fee'!DL13>0,"✔","-") -> - | AL13: =IF('Design Fee'!DM13>0,"✔","-") -> - | AM13: =IF('Design Fee'!DN13>0,"✔","-") -> - | AN13: =IF('Design Fee'!DP13>0,"✔","-") -> - | AO13: =IF('Design Fee'!DQ13>0,"✔","-") -> - | AP13: =IF('Design Fee'!DR13>0,"✔","-") -> - | AQ13: =IF('Design Fee'!DS13>0,"✔","-") -> - | AR13: =IF('Design Fee'!DT13>0,"✔","-") -> - | AT13: =IF('Design Fee'!EO13>0,"✔","-") -> - | AV13: =IF('Design Fee'!ET13>0,"✔","-") -> - | AW13: =IF('Design Fee'!EU13>0,"✔","-") -> - | AX13: =IF('Design Fee'!EV13>0,"✔","-") -> - | AY13: =IF('Design Fee'!EW13>0,"✔","-") -> - | AZ13: =IF('Design Fee'!EX13>0,"✔","-") -> - | BA13: =IF('Design Fee'!EZ13>0,"✔","-") -> - | BB13: =IF('Design Fee'!FA13>0,"✔","-") -> - | BC13: =IF('Design Fee'!FB13>0,"✔","-") -> - | BD13: =IF('Design Fee'!FC13>0,"✔","-") -> - | BE13: =IF('Design Fee'!FD13>0,"✔","-") -> - | BG13: =IF('Design Fee'!FY13>0,"✔","-") -> - | BH13: =IF('Design Fee'!FZ13>0,"✔","-") -> - | BI13: =IF('Design Fee'!GA13>0,"✔","-") -> - | BJ13: =IF('Design Fee'!GB13>0,"✔","-") -> - | BK13: =IF('Design Fee'!GC13>0,"✔","-") -> - | BL13: =IF('Design Fee'!GE13>0,"✔","-") -> - | BM13: =IF('Design Fee'!GF13>0,"✔","-") -> - | BN13: =IF('Design Fee'!GG13>0,"✔","-") -> - | BO13: =IF('Design Fee'!GH13>0,"✔","-") -> - | BP13: =IF('Design Fee'!GI13>0,"✔","-") -> - | BR13: =IF('Design Fee'!HD13>0,"✔","-") -> - | BS13: =IF('Design Fee'!HE13>0,"✔","-") -> - | BT13: =IF('Design Fee'!HF13>0,"✔","-") -> - | BU13: =IF('Design Fee'!HG13>0,"✔","-") -> - | BV13: =IF('Design Fee'!HH13>0,"✔","-") -> - | BW13: =IF('Design Fee'!HJ13>0,"✔","-") -> - | BX13: =IF('Design Fee'!HK13>0,"✔","-") -> - | BY13: =IF('Design Fee'!HL13>0,"✔","-") -> - | BZ13: =IF('Design Fee'!HM13>0,"✔","-") -> - | CA13: =IF('Design Fee'!HN13>0,"✔","-") -> - | CC13: =IF('Design Fee'!II13>0,"✔","-") -> - | CE13: =IF('Design Fee'!IN13>0,"✔","-") -> - | CF13: =IF('Design Fee'!IO13>0,"✔","-") -> - | CG13: =IF('Design Fee'!IP13>0,"✔","-") -> - | CH13: =IF('Design Fee'!IQ13>0,"✔","-") -> - | CI13: =IF('Design Fee'!IR13>0,"✔","-") -> - | CJ13: =IF('Design Fee'!IT13>0,"✔","-") -> - | CK13: =IF('Design Fee'!IU13>0,"✔","-") -> - | CL13: =IF('Design Fee'!IV13>0,"✔","-") -> - | CM13: =IF('Design Fee'!IW13>0,"✔","-") -> - | CN13: =IF('Design Fee'!IX13>0,"✔","-") -> - | CP13: =IF('Design Fee'!JS13>0,"✔","-") -> - | CQ13: =IF('Design Fee'!JT13>0,"✔","-") -> - | CR13: =IF('Design Fee'!JU13>0,"✔","-") -> - | CS13: =IF('Design Fee'!JV13>0,"✔","-") -> - | CT13: =IF('Design Fee'!JW13>0,"✔","-") -> - | CU13: =IF('Design Fee'!JY13>0,"✔","-") -> - | CV13: =IF('Design Fee'!JZ13>0,"✔","-") -> - | CW13: =IF('Design Fee'!KA13>0,"✔","-") -> - | CX13: =IF('Design Fee'!KB13>0,"✔","-") -> - | CY13: =IF('Design Fee'!KC13>0,"✔","-") -> - | DA13: =IF('Design Fee'!KX13>0,"✔","-") -> - | DB13: =IF('Design Fee'!KY13>0,"✔","-") -> - | DC13: =IF('Design Fee'!KZ13>0,"✔","-") -> - | DD13: =IF('Design Fee'!LA13>0,"✔","-") -> - | DE13: =IF('Design Fee'!LB13>0,"✔","-") -> - | DF13: =IF('Design Fee'!LD13>0,"✔","-") -> - | DG13: =IF('Design Fee'!LE13>0,"✔","-") -> - | DH13: =IF('Design Fee'!LF13>0,"✔","-") -> - | DI13: =IF('Design Fee'!LG13>0,"✔","-") -> - | DJ13: =IF('Design Fee'!LH13>0,"✔","-") -> - | DL13: =IF('Design Fee'!MC13>0,"✔","-") -> - | DN13: =IF('Design Fee'!MH13>0,"✔","-") -> - | DO13: =IF('Design Fee'!MI13>0,"✔","-") -> - | DP13: =IF('Design Fee'!MJ13>0,"✔","-") -> - | DQ13: =IF('Design Fee'!MK13>0,"✔","-") -> - | DR13: =IF('Design Fee'!ML13>0,"✔","-") -> - | DS13: =IF('Design Fee'!MN13>0,"✔","-") -> - | DT13: =IF('Design Fee'!MO13>0,"✔","-") -> - | DU13: =IF('Design Fee'!MP13>0,"✔","-") -> - | DV13: =IF('Design Fee'!MQ13>0,"✔","-") -> - | DW13: =IF('Design Fee'!MR13>0,"✔","-") -> - | DY13: =IF('Design Fee'!NM13>0,"✔","-") -> - | DZ13: =IF('Design Fee'!NN13>0,"✔","-") -> - | EA13: =IF('Design Fee'!NO13>0,"✔","-") -> - | EB13: =IF('Design Fee'!NP13>0,"✔","-") -> - | EC13: =IF('Design Fee'!NQ13>0,"✔","-") -> - | ED13: =IF('Design Fee'!NS13>0,"✔","-") -> - | EE13: =IF('Design Fee'!NT13>0,"✔","-") -> - | EF13: =IF('Design Fee'!NU13>0,"✔","-") -> - | EG13: =IF('Design Fee'!NV13>0,"✔","-") -> - | EH13: =IF('Design Fee'!NW13>0,"✔","-") -> - | EJ13: =IF('Design Fee'!OR13>0,"✔","-") -> - | EK13: =IF('Design Fee'!OS13>0,"✔","-") -> - | EL13: =IF('Design Fee'!OT13>0,"✔","-") -> - | EM13: =IF('Design Fee'!OU13>0,"✔","-") -> - | EN13: =IF('Design Fee'!OV13>0,"✔","-") -> - | EO13: =IF('Design Fee'!OX13>0,"✔","-") -> - | EP13: =IF('Design Fee'!OY13>0,"✔","-") -> - | EQ13: =IF('Design Fee'!OZ13>0,"✔","-") -> - | ER13: =IF('Design Fee'!PA13>0,"✔","-") -> - | ES13: =IF('Design Fee'!PB13>0,"✔","-") -> -
C14: 3 | D14: Zoning & Development Regulations | K14: =IF('Design Fee'!AU14>0,"✔","-") -> - | M14: =IF('Design Fee'!AZ14>0,"✔","-") -> - | N14: =IF('Design Fee'!BA14>0,"✔","-") -> - | O14: =IF('Design Fee'!BB14>0,"✔","-") -> - | P14: =IF('Design Fee'!BC14>0,"✔","-") -> - | Q14: =IF('Design Fee'!BD14>0,"✔","-") -> - | R14: =IF('Design Fee'!BF14>0,"✔","-") -> - | S14: =IF('Design Fee'!BG14>0,"✔","-") -> - | T14: =IF('Design Fee'!BH14>0,"✔","-") -> - | U14: =IF('Design Fee'!BI14>0,"✔","-") -> - | V14: =IF('Design Fee'!BJ14>0,"✔","-") -> - | X14: =IF('Design Fee'!CE14>0,"✔","-") -> - | Y14: =IF('Design Fee'!CF14>0,"✔","-") -> - | Z14: =IF('Design Fee'!CG14>0,"✔","-") -> - | AA14: =IF('Design Fee'!CH14>0,"✔","-") -> - | AB14: =IF('Design Fee'!CI14>0,"✔","-") -> - | AC14: =IF('Design Fee'!CK14>0,"✔","-") -> - | AD14: =IF('Design Fee'!CL14>0,"✔","-") -> - | AE14: =IF('Design Fee'!CM14>0,"✔","-") -> - | AF14: =IF('Design Fee'!CN14>0,"✔","-") -> - | AG14: =IF('Design Fee'!CO14>0,"✔","-") -> - | AI14: =IF('Design Fee'!DJ14>0,"✔","-") -> - | AJ14: =IF('Design Fee'!DK14>0,"✔","-") -> - | AK14: =IF('Design Fee'!DL14>0,"✔","-") -> - | AL14: =IF('Design Fee'!DM14>0,"✔","-") -> - | AM14: =IF('Design Fee'!DN14>0,"✔","-") -> - | AN14: =IF('Design Fee'!DP14>0,"✔","-") -> - | AO14: =IF('Design Fee'!DQ14>0,"✔","-") -> - | AP14: =IF('Design Fee'!DR14>0,"✔","-") -> - | AQ14: =IF('Design Fee'!DS14>0,"✔","-") -> - | AR14: =IF('Design Fee'!DT14>0,"✔","-") -> - | AT14: =IF('Design Fee'!EO14>0,"✔","-") -> - | AV14: =IF('Design Fee'!ET14>0,"✔","-") -> - | AW14: =IF('Design Fee'!EU14>0,"✔","-") -> - | AX14: =IF('Design Fee'!EV14>0,"✔","-") -> - | AY14: =IF('Design Fee'!EW14>0,"✔","-") -> - | AZ14: =IF('Design Fee'!EX14>0,"✔","-") -> - | BA14: =IF('Design Fee'!EZ14>0,"✔","-") -> - | BB14: =IF('Design Fee'!FA14>0,"✔","-") -> - | BC14: =IF('Design Fee'!FB14>0,"✔","-") -> - | BD14: =IF('Design Fee'!FC14>0,"✔","-") -> - | BE14: =IF('Design Fee'!FD14>0,"✔","-") -> - | BG14: =IF('Design Fee'!FY14>0,"✔","-") -> - | BH14: =IF('Design Fee'!FZ14>0,"✔","-") -> - | BI14: =IF('Design Fee'!GA14>0,"✔","-") -> - | BJ14: =IF('Design Fee'!GB14>0,"✔","-") -> - | BK14: =IF('Design Fee'!GC14>0,"✔","-") -> - | BL14: =IF('Design Fee'!GE14>0,"✔","-") -> - | BM14: =IF('Design Fee'!GF14>0,"✔","-") -> - | BN14: =IF('Design Fee'!GG14>0,"✔","-") -> - | BO14: =IF('Design Fee'!GH14>0,"✔","-") -> - | BP14: =IF('Design Fee'!GI14>0,"✔","-") -> - | BR14: =IF('Design Fee'!HD14>0,"✔","-") -> - | BS14: =IF('Design Fee'!HE14>0,"✔","-") -> - | BT14: =IF('Design Fee'!HF14>0,"✔","-") -> - | BU14: =IF('Design Fee'!HG14>0,"✔","-") -> - | BV14: =IF('Design Fee'!HH14>0,"✔","-") -> - | BW14: =IF('Design Fee'!HJ14>0,"✔","-") -> - | BX14: =IF('Design Fee'!HK14>0,"✔","-") -> - | BY14: =IF('Design Fee'!HL14>0,"✔","-") -> - | BZ14: =IF('Design Fee'!HM14>0,"✔","-") -> - | CA14: =IF('Design Fee'!HN14>0,"✔","-") -> - | CC14: =IF('Design Fee'!II14>0,"✔","-") -> - | CE14: =IF('Design Fee'!IN14>0,"✔","-") -> - | CF14: =IF('Design Fee'!IO14>0,"✔","-") -> - | CG14: =IF('Design Fee'!IP14>0,"✔","-") -> - | CH14: =IF('Design Fee'!IQ14>0,"✔","-") -> - | CI14: =IF('Design Fee'!IR14>0,"✔","-") -> - | CJ14: =IF('Design Fee'!IT14>0,"✔","-") -> - | CK14: =IF('Design Fee'!IU14>0,"✔","-") -> - | CL14: =IF('Design Fee'!IV14>0,"✔","-") -> - | CM14: =IF('Design Fee'!IW14>0,"✔","-") -> - | CN14: =IF('Design Fee'!IX14>0,"✔","-") -> - | CP14: =IF('Design Fee'!JS14>0,"✔","-") -> - | CQ14: =IF('Design Fee'!JT14>0,"✔","-") -> - | CR14: =IF('Design Fee'!JU14>0,"✔","-") -> - | CS14: =IF('Design Fee'!JV14>0,"✔","-") -> - | CT14: =IF('Design Fee'!JW14>0,"✔","-") -> - | CU14: =IF('Design Fee'!JY14>0,"✔","-") -> - | CV14: =IF('Design Fee'!JZ14>0,"✔","-") -> - | CW14: =IF('Design Fee'!KA14>0,"✔","-") -> - | CX14: =IF('Design Fee'!KB14>0,"✔","-") -> - | CY14: =IF('Design Fee'!KC14>0,"✔","-") -> - | DA14: =IF('Design Fee'!KX14>0,"✔","-") -> - | DB14: =IF('Design Fee'!KY14>0,"✔","-") -> - | DC14: =IF('Design Fee'!KZ14>0,"✔","-") -> - | DD14: =IF('Design Fee'!LA14>0,"✔","-") -> - | DE14: =IF('Design Fee'!LB14>0,"✔","-") -> - | DF14: =IF('Design Fee'!LD14>0,"✔","-") -> - | DG14: =IF('Design Fee'!LE14>0,"✔","-") -> - | DH14: =IF('Design Fee'!LF14>0,"✔","-") -> - | DI14: =IF('Design Fee'!LG14>0,"✔","-") -> - | DJ14: =IF('Design Fee'!LH14>0,"✔","-") -> - | DL14: =IF('Design Fee'!MC14>0,"✔","-") -> - | DN14: =IF('Design Fee'!MH14>0,"✔","-") -> - | DO14: =IF('Design Fee'!MI14>0,"✔","-") -> - | DP14: =IF('Design Fee'!MJ14>0,"✔","-") -> - | DQ14: =IF('Design Fee'!MK14>0,"✔","-") -> - | DR14: =IF('Design Fee'!ML14>0,"✔","-") -> - | DS14: =IF('Design Fee'!MN14>0,"✔","-") -> - | DT14: =IF('Design Fee'!MO14>0,"✔","-") -> - | DU14: =IF('Design Fee'!MP14>0,"✔","-") -> - | DV14: =IF('Design Fee'!MQ14>0,"✔","-") -> - | DW14: =IF('Design Fee'!MR14>0,"✔","-") -> - | DY14: =IF('Design Fee'!NM14>0,"✔","-") -> - | DZ14: =IF('Design Fee'!NN14>0,"✔","-") -> - | EA14: =IF('Design Fee'!NO14>0,"✔","-") -> - | EB14: =IF('Design Fee'!NP14>0,"✔","-") -> - | EC14: =IF('Design Fee'!NQ14>0,"✔","-") -> - | ED14: =IF('Design Fee'!NS14>0,"✔","-") -> - | EE14: =IF('Design Fee'!NT14>0,"✔","-") -> - | EF14: =IF('Design Fee'!NU14>0,"✔","-") -> - | EG14: =IF('Design Fee'!NV14>0,"✔","-") -> - | EH14: =IF('Design Fee'!NW14>0,"✔","-") -> - | EJ14: =IF('Design Fee'!OR14>0,"✔","-") -> - | EK14: =IF('Design Fee'!OS14>0,"✔","-") -> - | EL14: =IF('Design Fee'!OT14>0,"✔","-") -> - | EM14: =IF('Design Fee'!OU14>0,"✔","-") -> - | EN14: =IF('Design Fee'!OV14>0,"✔","-") -> - | EO14: =IF('Design Fee'!OX14>0,"✔","-") -> - | EP14: =IF('Design Fee'!OY14>0,"✔","-") -> - | EQ14: =IF('Design Fee'!OZ14>0,"✔","-") -> - | ER14: =IF('Design Fee'!PA14>0,"✔","-") -> - | ES14: =IF('Design Fee'!PB14>0,"✔","-") -> -
C15: 4 | D15: Design Brief | K15: =IF('Design Fee'!AU15>0,"✔","-") -> - | M15: =IF('Design Fee'!AZ15>0,"✔","-") -> - | N15: =IF('Design Fee'!BA15>0,"✔","-") -> - | O15: =IF('Design Fee'!BB15>0,"✔","-") -> - | P15: =IF('Design Fee'!BC15>0,"✔","-") -> - | Q15: =IF('Design Fee'!BD15>0,"✔","-") -> - | R15: =IF('Design Fee'!BF15>0,"✔","-") -> - | S15: =IF('Design Fee'!BG15>0,"✔","-") -> - | T15: =IF('Design Fee'!BH15>0,"✔","-") -> - | U15: =IF('Design Fee'!BI15>0,"✔","-") -> - | V15: =IF('Design Fee'!BJ15>0,"✔","-") -> - | X15: =IF('Design Fee'!CE15>0,"✔","-") -> - | Y15: =IF('Design Fee'!CF15>0,"✔","-") -> - | Z15: =IF('Design Fee'!CG15>0,"✔","-") -> - | AA15: =IF('Design Fee'!CH15>0,"✔","-") -> - | AB15: =IF('Design Fee'!CI15>0,"✔","-") -> - | AC15: =IF('Design Fee'!CK15>0,"✔","-") -> - | AD15: =IF('Design Fee'!CL15>0,"✔","-") -> - | AE15: =IF('Design Fee'!CM15>0,"✔","-") -> - | AF15: =IF('Design Fee'!CN15>0,"✔","-") -> - | AG15: =IF('Design Fee'!CO15>0,"✔","-") -> - | AI15: =IF('Design Fee'!DJ15>0,"✔","-") -> - | AJ15: =IF('Design Fee'!DK15>0,"✔","-") -> - | AK15: =IF('Design Fee'!DL15>0,"✔","-") -> - | AL15: =IF('Design Fee'!DM15>0,"✔","-") -> - | AM15: =IF('Design Fee'!DN15>0,"✔","-") -> - | AN15: =IF('Design Fee'!DP15>0,"✔","-") -> - | AO15: =IF('Design Fee'!DQ15>0,"✔","-") -> - | AP15: =IF('Design Fee'!DR15>0,"✔","-") -> - | AQ15: =IF('Design Fee'!DS15>0,"✔","-") -> - | AR15: =IF('Design Fee'!DT15>0,"✔","-") -> - | AT15: =IF('Design Fee'!EO15>0,"✔","-") -> - | AV15: =IF('Design Fee'!ET15>0,"✔","-") -> - | AW15: =IF('Design Fee'!EU15>0,"✔","-") -> - | AX15: =IF('Design Fee'!EV15>0,"✔","-") -> - | AY15: =IF('Design Fee'!EW15>0,"✔","-") -> - | AZ15: =IF('Design Fee'!EX15>0,"✔","-") -> - | BA15: =IF('Design Fee'!EZ15>0,"✔","-") -> - | BB15: =IF('Design Fee'!FA15>0,"✔","-") -> - | BC15: =IF('Design Fee'!FB15>0,"✔","-") -> - | BD15: =IF('Design Fee'!FC15>0,"✔","-") -> - | BE15: =IF('Design Fee'!FD15>0,"✔","-") -> - | BG15: =IF('Design Fee'!FY15>0,"✔","-") -> - | BH15: =IF('Design Fee'!FZ15>0,"✔","-") -> - | BI15: =IF('Design Fee'!GA15>0,"✔","-") -> - | BJ15: =IF('Design Fee'!GB15>0,"✔","-") -> - | BK15: =IF('Design Fee'!GC15>0,"✔","-") -> - | BL15: =IF('Design Fee'!GE15>0,"✔","-") -> - | BM15: =IF('Design Fee'!GF15>0,"✔","-") -> - | BN15: =IF('Design Fee'!GG15>0,"✔","-") -> - | BO15: =IF('Design Fee'!GH15>0,"✔","-") -> - | BP15: =IF('Design Fee'!GI15>0,"✔","-") -> - | BR15: =IF('Design Fee'!HD15>0,"✔","-") -> - | BS15: =IF('Design Fee'!HE15>0,"✔","-") -> - | BT15: =IF('Design Fee'!HF15>0,"✔","-") -> - | BU15: =IF('Design Fee'!HG15>0,"✔","-") -> - | BV15: =IF('Design Fee'!HH15>0,"✔","-") -> - | BW15: =IF('Design Fee'!HJ15>0,"✔","-") -> - | BX15: =IF('Design Fee'!HK15>0,"✔","-") -> - | BY15: =IF('Design Fee'!HL15>0,"✔","-") -> - | BZ15: =IF('Design Fee'!HM15>0,"✔","-") -> - | CA15: =IF('Design Fee'!HN15>0,"✔","-") -> - | CC15: =IF('Design Fee'!II15>0,"✔","-") -> - | CE15: =IF('Design Fee'!IN15>0,"✔","-") -> - | CF15: =IF('Design Fee'!IO15>0,"✔","-") -> - | CG15: =IF('Design Fee'!IP15>0,"✔","-") -> - | CH15: =IF('Design Fee'!IQ15>0,"✔","-") -> - | CI15: =IF('Design Fee'!IR15>0,"✔","-") -> - | CJ15: =IF('Design Fee'!IT15>0,"✔","-") -> - | CK15: =IF('Design Fee'!IU15>0,"✔","-") -> - | CL15: =IF('Design Fee'!IV15>0,"✔","-") -> - | CM15: =IF('Design Fee'!IW15>0,"✔","-") -> - | CN15: =IF('Design Fee'!IX15>0,"✔","-") -> - | CP15: =IF('Design Fee'!JS15>0,"✔","-") -> - | CQ15: =IF('Design Fee'!JT15>0,"✔","-") -> - | CR15: =IF('Design Fee'!JU15>0,"✔","-") -> - | CS15: =IF('Design Fee'!JV15>0,"✔","-") -> - | CT15: =IF('Design Fee'!JW15>0,"✔","-") -> - | CU15: =IF('Design Fee'!JY15>0,"✔","-") -> - | CV15: =IF('Design Fee'!JZ15>0,"✔","-") -> - | CW15: =IF('Design Fee'!KA15>0,"✔","-") -> - | CX15: =IF('Design Fee'!KB15>0,"✔","-") -> - | CY15: =IF('Design Fee'!KC15>0,"✔","-") -> - | DA15: =IF('Design Fee'!KX15>0,"✔","-") -> - | DB15: =IF('Design Fee'!KY15>0,"✔","-") -> - | DC15: =IF('Design Fee'!KZ15>0,"✔","-") -> - | DD15: =IF('Design Fee'!LA15>0,"✔","-") -> - | DE15: =IF('Design Fee'!LB15>0,"✔","-") -> - | DF15: =IF('Design Fee'!LD15>0,"✔","-") -> - | DG15: =IF('Design Fee'!LE15>0,"✔","-") -> - | DH15: =IF('Design Fee'!LF15>0,"✔","-") -> - | DI15: =IF('Design Fee'!LG15>0,"✔","-") -> - | DJ15: =IF('Design Fee'!LH15>0,"✔","-") -> - | DL15: =IF('Design Fee'!MC15>0,"✔","-") -> - | DN15: =IF('Design Fee'!MH15>0,"✔","-") -> - | DO15: =IF('Design Fee'!MI15>0,"✔","-") -> - | DP15: =IF('Design Fee'!MJ15>0,"✔","-") -> - | DQ15: =IF('Design Fee'!MK15>0,"✔","-") -> - | DR15: =IF('Design Fee'!ML15>0,"✔","-") -> - | DS15: =IF('Design Fee'!MN15>0,"✔","-") -> - | DT15: =IF('Design Fee'!MO15>0,"✔","-") -> - | DU15: =IF('Design Fee'!MP15>0,"✔","-") -> - | DV15: =IF('Design Fee'!MQ15>0,"✔","-") -> - | DW15: =IF('Design Fee'!MR15>0,"✔","-") -> - | DY15: =IF('Design Fee'!NM15>0,"✔","-") -> - | DZ15: =IF('Design Fee'!NN15>0,"✔","-") -> - | EA15: =IF('Design Fee'!NO15>0,"✔","-") -> - | EB15: =IF('Design Fee'!NP15>0,"✔","-") -> - | EC15: =IF('Design Fee'!NQ15>0,"✔","-") -> - | ED15: =IF('Design Fee'!NS15>0,"✔","-") -> - | EE15: =IF('Design Fee'!NT15>0,"✔","-") -> - | EF15: =IF('Design Fee'!NU15>0,"✔","-") -> - | EG15: =IF('Design Fee'!NV15>0,"✔","-") -> - | EH15: =IF('Design Fee'!NW15>0,"✔","-") -> - | EJ15: =IF('Design Fee'!OR15>0,"✔","-") -> - | EK15: =IF('Design Fee'!OS15>0,"✔","-") -> - | EL15: =IF('Design Fee'!OT15>0,"✔","-") -> - | EM15: =IF('Design Fee'!OU15>0,"✔","-") -> - | EN15: =IF('Design Fee'!OV15>0,"✔","-") -> - | EO15: =IF('Design Fee'!OX15>0,"✔","-") -> - | EP15: =IF('Design Fee'!OY15>0,"✔","-") -> - | EQ15: =IF('Design Fee'!OZ15>0,"✔","-") -> - | ER15: =IF('Design Fee'!PA15>0,"✔","-") -> - | ES15: =IF('Design Fee'!PB15>0,"✔","-") -> -
C17: 2 | D17: Schematic Concept | F17: =COUNTIF('Design Fee'!AU17,">0")+COUNTIF('Design Fee'!EO17,">0")+COUNTIF('Design Fee'!II17,">0")+COUNTIF('Design Fee'!ME17,">0") -> 4 | G17: =COUNTIF('Design Fee'!AX17,">0")+COUNTIF('Design Fee'!ER17,">0")+COUNTIF('Design Fee'!IL17,">0")+COUNTIF('Design Fee'!MF17,">0") -> 4 | H17: =COUNTIF('Design Fee'!AY17,">0")+COUNTIF('Design Fee'!ES17,">0")+COUNTIF('Design Fee'!IM17,">0")+COUNTIF('Design Fee'!MG17,">0") -> 4 | I17: =F17-G17 -> 0 | K17: =IF('Design Fee'!AU17>0,"✔","-") -> ✔ | M17: =IF('Design Fee'!AZ17>0,"✔","-") -> - | N17: =IF('Design Fee'!BA17>0,"✔","-") -> - | O17: =IF('Design Fee'!BB17>0,"✔","-") -> - | P17: =IF('Design Fee'!BC17>0,"✔","-") -> - | Q17: =IF('Design Fee'!BD17>0,"✔","-") -> - | R17: =IF('Design Fee'!BF17>0,"✔","-") -> - | S17: =IF('Design Fee'!BG17>0,"✔","-") -> - | T17: =IF('Design Fee'!BH17>0,"✔","-") -> - | U17: =IF('Design Fee'!BI17>0,"✔","-") -> - | V17: =IF('Design Fee'!BJ17>0,"✔","-") -> - | X17: =IF('Design Fee'!CE17>0,"✔","-") -> - | Y17: =IF('Design Fee'!CF17>0,"✔","-") -> - | Z17: =IF('Design Fee'!CG17>0,"✔","-") -> - | AA17: =IF('Design Fee'!CH17>0,"✔","-") -> - | AB17: =IF('Design Fee'!CI17>0,"✔","-") -> - | AC17: =IF('Design Fee'!CK17>0,"✔","-") -> - | AD17: =IF('Design Fee'!CL17>0,"✔","-") -> - | AE17: =IF('Design Fee'!CM17>0,"✔","-") -> - | AF17: =IF('Design Fee'!CN17>0,"✔","-") -> - | AG17: =IF('Design Fee'!CO17>0,"✔","-") -> - | AI17: =IF('Design Fee'!DJ17>0,"✔","-") -> - | AJ17: =IF('Design Fee'!DK17>0,"✔","-") -> - | AK17: =IF('Design Fee'!DL17>0,"✔","-") -> - | AL17: =IF('Design Fee'!DM17>0,"✔","-") -> - | AM17: =IF('Design Fee'!DN17>0,"✔","-") -> - | AN17: =IF('Design Fee'!DP17>0,"✔","-") -> - | AO17: =IF('Design Fee'!DQ17>0,"✔","-") -> - | AP17: =IF('Design Fee'!DR17>0,"✔","-") -> - | AQ17: =IF('Design Fee'!DS17>0,"✔","-") -> - | AR17: =IF('Design Fee'!DT17>0,"✔","-") -> - | AT17: =IF('Design Fee'!EO17>0,"✔","-") -> ✔ | AV17: =IF('Design Fee'!ET17>0,"✔","-") -> - | AW17: =IF('Design Fee'!EU17>0,"✔","-") -> - | AX17: =IF('Design Fee'!EV17>0,"✔","-") -> - | AY17: =IF('Design Fee'!EW17>0,"✔","-") -> - | AZ17: =IF('Design Fee'!EX17>0,"✔","-") -> - | BA17: =IF('Design Fee'!EZ17>0,"✔","-") -> - | BB17: =IF('Design Fee'!FA17>0,"✔","-") -> - | BC17: =IF('Design Fee'!FB17>0,"✔","-") -> - | BD17: =IF('Design Fee'!FC17>0,"✔","-") -> - | BE17: =IF('Design Fee'!FD17>0,"✔","-") -> - | BG17: =IF('Design Fee'!FY17>0,"✔","-") -> - | BH17: =IF('Design Fee'!FZ17>0,"✔","-") -> - | BI17: =IF('Design Fee'!GA17>0,"✔","-") -> - | BJ17: =IF('Design Fee'!GB17>0,"✔","-") -> - | BK17: =IF('Design Fee'!GC17>0,"✔","-") -> - | BL17: =IF('Design Fee'!GE17>0,"✔","-") -> - | BM17: =IF('Design Fee'!GF17>0,"✔","-") -> - | BN17: =IF('Design Fee'!GG17>0,"✔","-") -> - | BO17: =IF('Design Fee'!GH17>0,"✔","-") -> - | BP17: =IF('Design Fee'!GI17>0,"✔","-") -> - | BR17: =IF('Design Fee'!HD17>0,"✔","-") -> - | BS17: =IF('Design Fee'!HE17>0,"✔","-") -> - | BT17: =IF('Design Fee'!HF17>0,"✔","-") -> - | BU17: =IF('Design Fee'!HG17>0,"✔","-") -> - | BV17: =IF('Design Fee'!HH17>0,"✔","-") -> - | BW17: =IF('Design Fee'!HJ17>0,"✔","-") -> - | BX17: =IF('Design Fee'!HK17>0,"✔","-") -> - | BY17: =IF('Design Fee'!HL17>0,"✔","-") -> - | BZ17: =IF('Design Fee'!HM17>0,"✔","-") -> - | CA17: =IF('Design Fee'!HN17>0,"✔","-") -> - | CC17: =IF('Design Fee'!II17>0,"✔","-") -> ✔ | CE17: =IF('Design Fee'!IN17>0,"✔","-") -> - | CF17: =IF('Design Fee'!IO17>0,"✔","-") -> - | CG17: =IF('Design Fee'!IP17>0,"✔","-") -> - | CH17: =IF('Design Fee'!IQ17>0,"✔","-") -> - | CI17: =IF('Design Fee'!IR17>0,"✔","-") -> - | CJ17: =IF('Design Fee'!IT17>0,"✔","-") -> - | CK17: =IF('Design Fee'!IU17>0,"✔","-") -> - | CL17: =IF('Design Fee'!IV17>0,"✔","-") -> - | CM17: =IF('Design Fee'!IW17>0,"✔","-") -> - | CN17: =IF('Design Fee'!IX17>0,"✔","-") -> - | CP17: =IF('Design Fee'!JS17>0,"✔","-") -> - | CQ17: =IF('Design Fee'!JT17>0,"✔","-") -> - | CR17: =IF('Design Fee'!JU17>0,"✔","-") -> - | CS17: =IF('Design Fee'!JV17>0,"✔","-") -> - | CT17: =IF('Design Fee'!JW17>0,"✔","-") -> - | CU17: =IF('Design Fee'!JY17>0,"✔","-") -> - | CV17: =IF('Design Fee'!JZ17>0,"✔","-") -> - | CW17: =IF('Design Fee'!KA17>0,"✔","-") -> - | CX17: =IF('Design Fee'!KB17>0,"✔","-") -> - | CY17: =IF('Design Fee'!KC17>0,"✔","-") -> - | DA17: =IF('Design Fee'!KX17>0,"✔","-") -> - | DB17: =IF('Design Fee'!KY17>0,"✔","-") -> - | DC17: =IF('Design Fee'!KZ17>0,"✔","-") -> - | DD17: =IF('Design Fee'!LA17>0,"✔","-") -> - | DE17: =IF('Design Fee'!LB17>0,"✔","-") -> - | DF17: =IF('Design Fee'!LD17>0,"✔","-") -> - | DG17: =IF('Design Fee'!LE17>0,"✔","-") -> - | DH17: =IF('Design Fee'!LF17>0,"✔","-") -> - | DI17: =IF('Design Fee'!LG17>0,"✔","-") -> - | DJ17: =IF('Design Fee'!LH17>0,"✔","-") -> - | DL17: =IF('Design Fee'!MC17>0,"✔","-") -> ✔ | DN17: =IF('Design Fee'!MH17>0,"✔","-") -> - | DO17: =IF('Design Fee'!MI17>0,"✔","-") -> - | DP17: =IF('Design Fee'!MJ17>0,"✔","-") -> - | DQ17: =IF('Design Fee'!MK17>0,"✔","-") -> - | DR17: =IF('Design Fee'!ML17>0,"✔","-") -> - | DS17: =IF('Design Fee'!MN17>0,"✔","-") -> - | DT17: =IF('Design Fee'!MO17>0,"✔","-") -> - | DU17: =IF('Design Fee'!MP17>0,"✔","-") -> - | DV17: =IF('Design Fee'!MQ17>0,"✔","-") -> - | DW17: =IF('Design Fee'!MR17>0,"✔","-") -> - | DY17: =IF('Design Fee'!NM17>0,"✔","-") -> - | DZ17: =IF('Design Fee'!NN17>0,"✔","-") -> - | EA17: =IF('Design Fee'!NO17>0,"✔","-") -> - | EB17: =IF('Design Fee'!NP17>0,"✔","-") -> - | EC17: =IF('Design Fee'!NQ17>0,"✔","-") -> - | ED17: =IF('Design Fee'!NS17>0,"✔","-") -> - | EE17: =IF('Design Fee'!NT17>0,"✔","-") -> - | EF17: =IF('Design Fee'!NU17>0,"✔","-") -> - | EG17: =IF('Design Fee'!NV17>0,"✔","-") -> - | EH17: =IF('Design Fee'!NW17>0,"✔","-") -> - | EJ17: =IF('Design Fee'!OR17>0,"✔","-") -> - | EK17: =IF('Design Fee'!OS17>0,"✔","-") -> - | EL17: =IF('Design Fee'!OT17>0,"✔","-") -> - | EM17: =IF('Design Fee'!OU17>0,"✔","-") -> - | EN17: =IF('Design Fee'!OV17>0,"✔","-") -> - | EO17: =IF('Design Fee'!OX17>0,"✔","-") -> - | EP17: =IF('Design Fee'!OY17>0,"✔","-") -> - | EQ17: =IF('Design Fee'!OZ17>0,"✔","-") -> - | ER17: =IF('Design Fee'!PA17>0,"✔","-") -> - | ES17: =IF('Design Fee'!PB17>0,"✔","-") -> -
C18: 1 | D18: Master Plan | K18: =IF('Design Fee'!AU18>0,"✔","-") -> - | M18: =IF('Design Fee'!AZ18>0,"✔","-") -> - | N18: =IF('Design Fee'!BA18>0,"✔","-") -> - | O18: =IF('Design Fee'!BB18>0,"✔","-") -> - | P18: =IF('Design Fee'!BC18>0,"✔","-") -> - | Q18: =IF('Design Fee'!BD18>0,"✔","-") -> - | R18: =IF('Design Fee'!BF18>0,"✔","-") -> - | S18: =IF('Design Fee'!BG18>0,"✔","-") -> - | T18: =IF('Design Fee'!BH18>0,"✔","-") -> - | U18: =IF('Design Fee'!BI18>0,"✔","-") -> - | V18: =IF('Design Fee'!BJ18>0,"✔","-") -> - | X18: =IF('Design Fee'!CE18>0,"✔","-") -> - | Y18: =IF('Design Fee'!CF18>0,"✔","-") -> - | Z18: =IF('Design Fee'!CG18>0,"✔","-") -> - | AA18: =IF('Design Fee'!CH18>0,"✔","-") -> - | AB18: =IF('Design Fee'!CI18>0,"✔","-") -> - | AC18: =IF('Design Fee'!CK18>0,"✔","-") -> - | AD18: =IF('Design Fee'!CL18>0,"✔","-") -> - | AE18: =IF('Design Fee'!CM18>0,"✔","-") -> - | AF18: =IF('Design Fee'!CN18>0,"✔","-") -> - | AG18: =IF('Design Fee'!CO18>0,"✔","-") -> - | AI18: =IF('Design Fee'!DJ18>0,"✔","-") -> - | AJ18: =IF('Design Fee'!DK18>0,"✔","-") -> - | AK18: =IF('Design Fee'!DL18>0,"✔","-") -> - | AL18: =IF('Design Fee'!DM18>0,"✔","-") -> - | AM18: =IF('Design Fee'!DN18>0,"✔","-") -> - | AN18: =IF('Design Fee'!DP18>0,"✔","-") -> - | AO18: =IF('Design Fee'!DQ18>0,"✔","-") -> - | AP18: =IF('Design Fee'!DR18>0,"✔","-") -> - | AQ18: =IF('Design Fee'!DS18>0,"✔","-") -> - | AR18: =IF('Design Fee'!DT18>0,"✔","-") -> - | AT18: =IF('Design Fee'!EO18>0,"✔","-") -> - | AV18: =IF('Design Fee'!ET18>0,"✔","-") -> - | AW18: =IF('Design Fee'!EU18>0,"✔","-") -> - | AX18: =IF('Design Fee'!EV18>0,"✔","-") -> - | AY18: =IF('Design Fee'!EW18>0,"✔","-") -> - | AZ18: =IF('Design Fee'!EX18>0,"✔","-") -> - | BA18: =IF('Design Fee'!EZ18>0,"✔","-") -> - | BB18: =IF('Design Fee'!FA18>0,"✔","-") -> - | BC18: =IF('Design Fee'!FB18>0,"✔","-") -> - | BD18: =IF('Design Fee'!FC18>0,"✔","-") -> - | BE18: =IF('Design Fee'!FD18>0,"✔","-") -> - | BG18: =IF('Design Fee'!FY18>0,"✔","-") -> - | BH18: =IF('Design Fee'!FZ18>0,"✔","-") -> - | BI18: =IF('Design Fee'!GA18>0,"✔","-") -> - | BJ18: =IF('Design Fee'!GB18>0,"✔","-") -> - | BK18: =IF('Design Fee'!GC18>0,"✔","-") -> - | BL18: =IF('Design Fee'!GE18>0,"✔","-") -> - | BM18: =IF('Design Fee'!GF18>0,"✔","-") -> - | BN18: =IF('Design Fee'!GG18>0,"✔","-") -> - | BO18: =IF('Design Fee'!GH18>0,"✔","-") -> - | BP18: =IF('Design Fee'!GI18>0,"✔","-") -> - | BR18: =IF('Design Fee'!HD18>0,"✔","-") -> - | BS18: =IF('Design Fee'!HE18>0,"✔","-") -> - | BT18: =IF('Design Fee'!HF18>0,"✔","-") -> - | BU18: =IF('Design Fee'!HG18>0,"✔","-") -> - | BV18: =IF('Design Fee'!HH18>0,"✔","-") -> - | BW18: =IF('Design Fee'!HJ18>0,"✔","-") -> - | BX18: =IF('Design Fee'!HK18>0,"✔","-") -> - | BY18: =IF('Design Fee'!HL18>0,"✔","-") -> - | BZ18: =IF('Design Fee'!HM18>0,"✔","-") -> - | CA18: =IF('Design Fee'!HN18>0,"✔","-") -> - | CC18: =IF('Design Fee'!II18>0,"✔","-") -> - | CE18: =IF('Design Fee'!IN18>0,"✔","-") -> - | CF18: =IF('Design Fee'!IO18>0,"✔","-") -> - | CG18: =IF('Design Fee'!IP18>0,"✔","-") -> - | CH18: =IF('Design Fee'!IQ18>0,"✔","-") -> - | CI18: =IF('Design Fee'!IR18>0,"✔","-") -> - | CJ18: =IF('Design Fee'!IT18>0,"✔","-") -> - | CK18: =IF('Design Fee'!IU18>0,"✔","-") -> - | CL18: =IF('Design Fee'!IV18>0,"✔","-") -> - | CM18: =IF('Design Fee'!IW18>0,"✔","-") -> - | CN18: =IF('Design Fee'!IX18>0,"✔","-") -> - | CP18: =IF('Design Fee'!JS18>0,"✔","-") -> - | CQ18: =IF('Design Fee'!JT18>0,"✔","-") -> - | CR18: =IF('Design Fee'!JU18>0,"✔","-") -> - | CS18: =IF('Design Fee'!JV18>0,"✔","-") -> - | CT18: =IF('Design Fee'!JW18>0,"✔","-") -> - | CU18: =IF('Design Fee'!JY18>0,"✔","-") -> - | CV18: =IF('Design Fee'!JZ18>0,"✔","-") -> - | CW18: =IF('Design Fee'!KA18>0,"✔","-") -> - | CX18: =IF('Design Fee'!KB18>0,"✔","-") -> - | CY18: =IF('Design Fee'!KC18>0,"✔","-") -> - | DA18: =IF('Design Fee'!KX18>0,"✔","-") -> - | DB18: =IF('Design Fee'!KY18>0,"✔","-") -> - | DC18: =IF('Design Fee'!KZ18>0,"✔","-") -> - | DD18: =IF('Design Fee'!LA18>0,"✔","-") -> - | DE18: =IF('Design Fee'!LB18>0,"✔","-") -> - | DF18: =IF('Design Fee'!LD18>0,"✔","-") -> - | DG18: =IF('Design Fee'!LE18>0,"✔","-") -> - | DH18: =IF('Design Fee'!LF18>0,"✔","-") -> - | DI18: =IF('Design Fee'!LG18>0,"✔","-") -> - | DJ18: =IF('Design Fee'!LH18>0,"✔","-") -> - | DL18: =IF('Design Fee'!MC18>0,"✔","-") -> - | DN18: =IF('Design Fee'!MH18>0,"✔","-") -> - | DO18: =IF('Design Fee'!MI18>0,"✔","-") -> - | DP18: =IF('Design Fee'!MJ18>0,"✔","-") -> - | DQ18: =IF('Design Fee'!MK18>0,"✔","-") -> - | DR18: =IF('Design Fee'!ML18>0,"✔","-") -> - | DS18: =IF('Design Fee'!MN18>0,"✔","-") -> - | DT18: =IF('Design Fee'!MO18>0,"✔","-") -> - | DU18: =IF('Design Fee'!MP18>0,"✔","-") -> - | DV18: =IF('Design Fee'!MQ18>0,"✔","-") -> - | DW18: =IF('Design Fee'!MR18>0,"✔","-") -> - | DY18: =IF('Design Fee'!NM18>0,"✔","-") -> - | DZ18: =IF('Design Fee'!NN18>0,"✔","-") -> - | EA18: =IF('Design Fee'!NO18>0,"✔","-") -> - | EB18: =IF('Design Fee'!NP18>0,"✔","-") -> - | EC18: =IF('Design Fee'!NQ18>0,"✔","-") -> - | ED18: =IF('Design Fee'!NS18>0,"✔","-") -> - | EE18: =IF('Design Fee'!NT18>0,"✔","-") -> - | EF18: =IF('Design Fee'!NU18>0,"✔","-") -> - | EG18: =IF('Design Fee'!NV18>0,"✔","-") -> - | EH18: =IF('Design Fee'!NW18>0,"✔","-") -> - | EJ18: =IF('Design Fee'!OR18>0,"✔","-") -> - | EK18: =IF('Design Fee'!OS18>0,"✔","-") -> - | EL18: =IF('Design Fee'!OT18>0,"✔","-") -> - | EM18: =IF('Design Fee'!OU18>0,"✔","-") -> - | EN18: =IF('Design Fee'!OV18>0,"✔","-") -> - | EO18: =IF('Design Fee'!OX18>0,"✔","-") -> - | EP18: =IF('Design Fee'!OY18>0,"✔","-") -> - | EQ18: =IF('Design Fee'!OZ18>0,"✔","-") -> - | ER18: =IF('Design Fee'!PA18>0,"✔","-") -> - | ES18: =IF('Design Fee'!PB18>0,"✔","-") -> -
