Workbook

Sheet Summary
D2: No. of Batches | F2: =W2+AL2+BA2+BP2 -> 67 | G2: =X2+AM2+BB2+BQ2 -> 33 | H2: =W2+AL2+BA2+BP2 -> 67 | I2: =X2+AM2+BB2+BQ2 -> 33 | J2: =Y2+AN2+BC2+BR2 -> 34 | K2: =Z2+AO2+BD2+BS2 -> 30 | L2: =AA2+AP2+BE2+BT2 -> 4 | M2: =AB2+AQ2+BF2+BU2 -> 0 | N2: =AC2+AR2+BG2+BV2 -> 0 | O2: =AD2+AS2+BH2+BW2 -> 29 | ... R2: =AG2+AV2+BK2+BZ2 -> 5 | S2: 4 | W2: =COUNTIF(W75:W77,">0")+COUNTIF(W52:W60,">0")+COUNTIF(W80:W82,">0")+COUNTIF(W70:W72,">0")+COUNTIF(W85:W88,">0")+COUNTIFS(W63:W67,">0")+COUNTIFS(W11,">0")+COUNTIFS(W17,">0")+COUNTIFS(W23,">0")+COUNTIFS(W30,">0")+COUNTIFS(W39,">0")+COUNTIFS(W93,">0") -> 23 | X2: =COUNTIF(X75:X77,">0")+COUNTIF(X52:X60,">0")+COUNTIF(X80:X82,">0")+COUNTIF(X70:X72,">0")+COUNTIF(X85:X88,">0")+COUNTIFS(X63:X67,">0")+COUNTIFS(X11,">0")+COUNTIFS(X17,">0")+COUNTIFS(X23,">0")+COUNTIFS(X30,">0")+COUNTIFS(X39,">0")+COUNTIFS(X93,">0") -> 14 | Y2: =COUNTIF(Y75:Y77,">0")+COUNTIF(Y52:Y60,">0")+COUNTIF(Y80:Y82,">0")+COUNTIF(Y70:Y72,">0")+COUNTIF(Y85:Y88,">0")+COUNTIFS(Y63:Y67,">0")+COUNTIFS(Y11,">0")+COUNTIFS(Y17,">0")+COUNTIFS(Y23,">0")+COUNTIFS(Y30,">0")+COUNTIFS(Y39,">0")+COUNTIFS(Y93,">0") -> 9 | Z2: =COUNTIF(Z75:Z77,">0")+COUNTIF(Z52:Z60,">0")+COUNTIF(Z80:Z82,">0")+COUNTIF(Z70:Z72,">0")+COUNTIF(Z85:Z88,">0")+COUNTIFS(Z63:Z67,">0")+COUNTIFS(Z11,">0")+COUNTIFS(Z17,">0")+COUNTIFS(Z23,">0")+COUNTIFS(Z30,">0")+COUNTIFS(Z39,">0")+COUNTIFS(Z93,">0") -> 8 | AA2: =COUNTIF(AA75:AA77,">0")+COUNTIF(AA52:AA60,">0")+COUNTIF(AA80:AA82,">0")+COUNTIF(AA70:AA72,">0")+COUNTIF(AA85:AA88,">0")+COUNTIFS(AA63:AA67,">0")+COUNTIFS(AA11,">0")+COUNTIFS(AA17,">0")+COUNTIFS(AA23,">0")+COUNTIFS(AA30,">0")+COUNTIFS(AA39,">0")+COUNTIFS(AA93,">0") -> 1 | AB2: =COUNTIF(AB75:AB77,">0")+COUNTIF(AB52:AB60,">0")+COUNTIF(AB80:AB82,">0")+COUNTIF(AB70:AB72,">0")+COUNTIF(AB85:AB88,">0")+COUNTIFS(AB63:AB67,">0")+COUNTIFS(AB11,">0")+COUNTIFS(AB17,">0")+COUNTIFS(AB23,">0")+COUNTIFS(AB30,">0")+COUNTIFS(AB39,">0")+COUNTIFS(AB93,">0") -> 0 | AC2: =COUNTIF(AC75:AC77,">0")+COUNTIF(AC52:AC60,">0")+COUNTIF(AC80:AC82,">0")+COUNTIF(AC70:AC72,">0")+COUNTIF(AC85:AC88,">0")+COUNTIFS(AC63:AC67,">0")+COUNTIFS(AC11,">0")+COUNTIFS(AC17,">0")+COUNTIFS(AC23,">0")+COUNTIFS(AC30,">0")+COUNTIFS(AC39,">0")+COUNTIFS(AC93,">0") -> 0 | AD2: =COUNTIF(AD75:AD77,">0")+COUNTIF(AD52:AD60,">0")+COUNTIF(AD80:AD82,">0")+COUNTIF(AD70:AD72,">0")+COUNTIF(AD85:AD88,">0")+COUNTIFS(AD63:AD67,">0")+COUNTIFS(AD11,">0")+COUNTIFS(AD17,">0")+COUNTIFS(AD23,">0")+COUNTIFS(AD30,">0")+COUNTIFS(AD39,">0")+COUNTIFS(AD93,">0") -> 8 | ... AH2: =COUNTIF(AH75:AH77,">0")+COUNTIF(AH52:AH60,">0")+COUNTIF(AH80:AH82,">0")+COUNTIF(AH70:AH72,">0")+COUNTIF(AH85:AH88,">0")+COUNTIFS(AH63:AH67,">0")+COUNTIFS(AH11,">0")+COUNTIFS(AH17,">0")+COUNTIFS(AH23,">0")+COUNTIFS(AH30,">0")+COUNTIFS(AH39,">0")+COUNTIFS(AH93,">0") -> 0 | AL2: =COUNTIF(AL75:AL77,">0")+COUNTIF(AL52:AL60,">0")+COUNTIF(AL80:AL82,">0")+COUNTIF(AL70:AL72,">0")+COUNTIF(AL85:AL88,">0")+COUNTIFS(AL63:AL67,">0")+COUNTIFS(AL11,">0")+COUNTIFS(AL17,">0")+COUNTIFS(AL23,">0")+COUNTIFS(AL30,">0")+COUNTIFS(AL39,">0")+COUNTIFS(AL93,">0") -> 21 | AM2: =COUNTIF(AM75:AM77,">0")+COUNTIF(AM52:AM60,">0")+COUNTIF(AM80:AM82,">0")+COUNTIF(AM70:AM72,">0")+COUNTIF(AM85:AM88,">0")+COUNTIFS(AM63:AM67,">0")+COUNTIFS(AM11,">0")+COUNTIFS(AM17,">0")+COUNTIFS(AM23,">0")+COUNTIFS(AM30,">0")+COUNTIFS(AM39,">0")+COUNTIFS(AM93,">0") -> 11 | AN2: =COUNTIF(AN75:AN77,">0")+COUNTIF(AN52:AN60,">0")+COUNTIF(AN80:AN82,">0")+COUNTIF(AN70:AN72,">0")+COUNTIF(AN85:AN88,">0")+COUNTIFS(AN63:AN67,">0")+COUNTIFS(AN11,">0")+COUNTIFS(AN17,">0")+COUNTIFS(AN23,">0")+COUNTIFS(AN30,">0")+COUNTIFS(AN39,">0")+COUNTIFS(AN93,">0") -> 10 | AO2: =COUNTIF(AO75:AO77,">0")+COUNTIF(AO52:AO60,">0")+COUNTIF(AO80:AO82,">0")+COUNTIF(AO70:AO72,">0")+COUNTIF(AO85:AO88,">0")+COUNTIFS(AO63:AO67,">0")+COUNTIFS(AO11,">0")+COUNTIFS(AO17,">0")+COUNTIFS(AO23,">0")+COUNTIFS(AO30,">0")+COUNTIFS(AO39,">0")+COUNTIFS(AO93,">0") -> 9 | AP2: =COUNTIF(AP75:AP77,">0")+COUNTIF(AP52:AP60,">0")+COUNTIF(AP80:AP82,">0")+COUNTIF(AP70:AP72,">0")+COUNTIF(AP85:AP88,">0")+COUNTIFS(AP63:AP67,">0")+COUNTIFS(AP11,">0")+COUNTIFS(AP17,">0")+COUNTIFS(AP23,">0")+COUNTIFS(AP30,">0")+COUNTIFS(AP39,">0")+COUNTIFS(AP93,">0") -> 1 | AQ2: =COUNTIF(AQ75:AQ77,">0")+COUNTIF(AQ52:AQ60,">0")+COUNTIF(AQ80:AQ82,">0")+COUNTIF(AQ70:AQ72,">0")+COUNTIF(AQ85:AQ88,">0")+COUNTIFS(AQ63:AQ67,">0")+COUNTIFS(AQ11,">0")+COUNTIFS(AQ17,">0")+COUNTIFS(AQ23,">0")+COUNTIFS(AQ30,">0")+COUNTIFS(AQ39,">0")+COUNTIFS(AQ93,">0") -> 0 | AR2: =COUNTIF(AR75:AR77,">0")+COUNTIF(AR52:AR60,">0")+COUNTIF(AR80:AR82,">0")+COUNTIF(AR70:AR72,">0")+COUNTIF(AR85:AR88,">0")+COUNTIFS(AR63:AR67,">0")+COUNTIFS(AR11,">0")+COUNTIFS(AR17,">0")+COUNTIFS(AR23,">0")+COUNTIFS(AR30,">0")+COUNTIFS(AR39,">0")+COUNTIFS(AR93,">0") -> 0 | AS2: =COUNTIF(AS75:AS77,">0")+COUNTIF(AS52:AS60,">0")+COUNTIF(AS80:AS82,">0")+COUNTIF(AS70:AS72,">0")+COUNTIF(AS85:AS88,">0")+COUNTIFS(AS63:AS67,">0")+COUNTIFS(AS11,">0")+COUNTIFS(AS17,">0")+COUNTIFS(AS23,">0")+COUNTIFS(AS30,">0")+COUNTIFS(AS39,">0")+COUNTIFS(AS93,">0") -> 9 | ... AW2: =COUNTIF(AW75:AW77,">0")+COUNTIF(AW52:AW60,">0")+COUNTIF(AW80:AW82,">0")+COUNTIF(AW70:AW72,">0")+COUNTIF(AW85:AW88,">0")+COUNTIFS(AW63:AW67,">0")+COUNTIFS(AW11,">0")+COUNTIFS(AW17,">0")+COUNTIFS(AW23,">0")+COUNTIFS(AW30,">0")+COUNTIFS(AW39,">0")+COUNTIFS(AW93,">0") -> 0 | BA2: =COUNTIF(BA75:BA77,">0")+COUNTIF(BA52:BA60,">0")+COUNTIF(BA80:BA82,">0")+COUNTIF(BA70:BA72,">0")+COUNTIF(BA85:BA88,">0")+COUNTIFS(BA63:BA67,">0")+COUNTIFS(BA11,">0")+COUNTIFS(BA17,">0")+COUNTIFS(BA23,">0")+COUNTIFS(BA30,">0")+COUNTIFS(BA39,">0")+COUNTIFS(BA93,">0") -> 14 | BB2: =COUNTIF(BB75:BB77,">0")+COUNTIF(BB52:BB60,">0")+COUNTIF(BB80:BB82,">0")+COUNTIF(BB70:BB72,">0")+COUNTIF(BB85:BB88,">0")+COUNTIFS(BB63:BB67,">0")+COUNTIFS(BB11,">0")+COUNTIFS(BB17,">0")+COUNTIFS(BB23,">0")+COUNTIFS(BB30,">0")+COUNTIFS(BB39,">0")+COUNTIFS(BB93,">0") -> 4 | BC2: =COUNTIF(BC75:BC77,">0")+COUNTIF(BC52:BC60,">0")+COUNTIF(BC80:BC82,">0")+COUNTIF(BC70:BC72,">0")+COUNTIF(BC85:BC88,">0")+COUNTIFS(BC63:BC67,">0")+COUNTIFS(BC11,">0")+COUNTIFS(BC17,">0")+COUNTIFS(BC23,">0")+COUNTIFS(BC30,">0")+COUNTIFS(BC39,">0")+COUNTIFS(BC93,">0") -> 10 | BD2: =COUNTIF(BD75:BD77,">0")+COUNTIF(BD52:BD60,">0")+COUNTIF(BD80:BD82,">0")+COUNTIF(BD70:BD72,">0")+COUNTIF(BD85:BD88,">0")+COUNTIFS(BD63:BD67,">0")+COUNTIFS(BD11,">0")+COUNTIFS(BD17,">0")+COUNTIFS(BD23,">0")+COUNTIFS(BD30,">0")+COUNTIFS(BD39,">0")+COUNTIFS(BD93,">0") -> 9 | BE2: =COUNTIF(BE75:BE77,">0")+COUNTIF(BE52:BE60,">0")+COUNTIF(BE80:BE82,">0")+COUNTIF(BE70:BE72,">0")+COUNTIF(BE85:BE88,">0")+COUNTIFS(BE63:BE67,">0")+COUNTIFS(BE11,">0")+COUNTIFS(BE17,">0")+COUNTIFS(BE23,">0")+COUNTIFS(BE30,">0")+COUNTIFS(BE39,">0")+COUNTIFS(BE93,">0") -> 1 | BF2: =COUNTIF(BF75:BF77,">0")+COUNTIF(BF52:BF60,">0")+COUNTIF(BF80:BF82,">0")+COUNTIF(BF70:BF72,">0")+COUNTIF(BF85:BF88,">0")+COUNTIFS(BF63:BF67,">0")+COUNTIFS(BF11,">0")+COUNTIFS(BF17,">0")+COUNTIFS(BF23,">0")+COUNTIFS(BF30,">0")+COUNTIFS(BF39,">0")+COUNTIFS(BF93,">0") -> 0 | BG2: =COUNTIF(BG75:BG77,">0")+COUNTIF(BG52:BG60,">0")+COUNTIF(BG80:BG82,">0")+COUNTIF(BG70:BG72,">0")+COUNTIF(BG85:BG88,">0")+COUNTIFS(BG63:BG67,">0")+COUNTIFS(BG11,">0")+COUNTIFS(BG17,">0")+COUNTIFS(BG23,">0")+COUNTIFS(BG30,">0")+COUNTIFS(BG39,">0")+COUNTIFS(BG93,">0") -> 0 | BH2: =COUNTIF(BH75:BH77,">0")+COUNTIF(BH52:BH60,">0")+COUNTIF(BH80:BH82,">0")+COUNTIF(BH70:BH72,">0")+COUNTIF(BH85:BH88,">0")+COUNTIFS(BH63:BH67,">0")+COUNTIFS(BH11,">0")+COUNTIFS(BH17,">0")+COUNTIFS(BH23,">0")+COUNTIFS(BH30,">0")+COUNTIFS(BH39,">0")+COUNTIFS(BH93,">0") -> 8 | ... BL2: =COUNTIF(BL75:BL77,">0")+COUNTIF(BL52:BL60,">0")+COUNTIF(BL80:BL82,">0")+COUNTIF(BL70:BL72,">0")+COUNTIF(BL85:BL88,">0")+COUNTIFS(BL63:BL67,">0")+COUNTIFS(BL11,">0")+COUNTIFS(BL17,">0")+COUNTIFS(BL23,">0")+COUNTIFS(BL30,">0")+COUNTIFS(BL39,">0")+COUNTIFS(BL93,">0") -> 0 | BP2: =COUNTIF(BP75:BP77,">0")+COUNTIF(BP52:BP60,">0")+COUNTIF(BP80:BP82,">0")+COUNTIF(BP70:BP72,">0")+COUNTIF(BP85:BP88,">0")+COUNTIFS(BP63:BP67,">0")+COUNTIFS(BP11,">0")+COUNTIFS(BP17,">0")+COUNTIFS(BP23,">0")+COUNTIFS(BP30,">0")+COUNTIFS(BP39,">0")+COUNTIFS(BP93,">0") -> 9 | BQ2: =COUNTIF(BQ75:BQ77,">0")+COUNTIF(BQ52:BQ60,">0")+COUNTIF(BQ80:BQ82,">0")+COUNTIF(BQ70:BQ72,">0")+COUNTIF(BQ85:BQ88,">0")+COUNTIFS(BQ63:BQ67,">0")+COUNTIFS(BQ11,">0")+COUNTIFS(BQ17,">0")+COUNTIFS(BQ23,">0")+COUNTIFS(BQ30,">0")+COUNTIFS(BQ39,">0")+COUNTIFS(BQ93,">0") -> 4 | BR2: =COUNTIF(BR75:BR77,">0")+COUNTIF(BR52:BR60,">0")+COUNTIF(BR80:BR82,">0")+COUNTIF(BR70:BR72,">0")+COUNTIF(BR85:BR88,">0")+COUNTIFS(BR63:BR67,">0")+COUNTIFS(BR11,">0")+COUNTIFS(BR17,">0")+COUNTIFS(BR23,">0")+COUNTIFS(BR30,">0")+COUNTIFS(BR39,">0")+COUNTIFS(BR93,">0") -> 5 | BS2: =COUNTIF(BS75:BS77,">0")+COUNTIF(BS52:BS60,">0")+COUNTIF(BS80:BS82,">0")+COUNTIF(BS70:BS72,">0")+COUNTIF(BS85:BS88,">0")+COUNTIFS(BS63:BS67,">0")+COUNTIFS(BS11,">0")+COUNTIFS(BS17,">0")+COUNTIFS(BS23,">0")+COUNTIFS(BS30,">0")+COUNTIFS(BS39,">0")+COUNTIFS(BS93,">0") -> 4 | BT2: =COUNTIF(BT75:BT77,">0")+COUNTIF(BT52:BT60,">0")+COUNTIF(BT80:BT82,">0")+COUNTIF(BT70:BT72,">0")+COUNTIF(BT85:BT88,">0")+COUNTIFS(BT63:BT67,">0")+COUNTIFS(BT11,">0")+COUNTIFS(BT17,">0")+COUNTIFS(BT23,">0")+COUNTIFS(BT30,">0")+COUNTIFS(BT39,">0")+COUNTIFS(BT93,">0") -> 1 | BU2: =COUNTIF(BU75:BU77,">0")+COUNTIF(BU52:BU60,">0")+COUNTIF(BU80:BU82,">0")+COUNTIF(BU70:BU72,">0")+COUNTIF(BU85:BU88,">0")+COUNTIFS(BU63:BU67,">0")+COUNTIFS(BU11,">0")+COUNTIFS(BU17,">0")+COUNTIFS(BU23,">0")+COUNTIFS(BU30,">0")+COUNTIFS(BU39,">0")+COUNTIFS(BU93,">0") -> 0 | BV2: =COUNTIF(BV75:BV77,">0")+COUNTIF(BV52:BV60,">0")+COUNTIF(BV80:BV82,">0")+COUNTIF(BV70:BV72,">0")+COUNTIF(BV85:BV88,">0")+COUNTIFS(BV63:BV67,">0")+COUNTIFS(BV11,">0")+COUNTIFS(BV17,">0")+COUNTIFS(BV23,">0")+COUNTIFS(BV30,">0")+COUNTIFS(BV39,">0")+COUNTIFS(BV93,">0") -> 0 | BW2: =COUNTIF(BW75:BW77,">0")+COUNTIF(BW52:BW60,">0")+COUNTIF(BW80:BW82,">0")+COUNTIF(BW70:BW72,">0")+COUNTIF(BW85:BW88,">0")+COUNTIFS(BW63:BW67,">0")+COUNTIFS(BW11,">0")+COUNTIFS(BW17,">0")+COUNTIFS(BW23,">0")+COUNTIFS(BW30,">0")+COUNTIFS(BW39,">0")+COUNTIFS(BW93,">0") -> 4 | ... CA2: =COUNTIF(CA75:CA77,">0")+COUNTIF(CA52:CA60,">0")+COUNTIF(CA80:CA82,">0")+COUNTIF(CA70:CA72,">0")+COUNTIF(CA85:CA88,">0")+COUNTIFS(CA63:CA67,">0")+COUNTIFS(CA11,">0")+COUNTIFS(CA17,">0")+COUNTIFS(CA23,">0")+COUNTIFS(CA30,">0")+COUNTIFS(CA39,">0")+COUNTIFS(CA93,">0") -> 0
C4: 0059 | Pursuit of a Radical Rhapsody | Commercial | F4: Total | H4: Total Packages | I4: Packages till Dec'22 | J4: Planned Packages in CY 23 | K4: Q1 | L4: Q2 | M4: Q3 | N4: Q4 | O4: Actual Packages in CY 23 | P4: Q1 | Q4: Q2 | R4: Q3 | S4: Q4 | U4: AR | W4: Total Packages | X4: Packages till Dec'22 | Y4: Planned Packages in CY 23 | Z4: Q1 | AA4: Q2 | AB4: Q3 | AC4: Q4 | AD4: Actual Packages in CY 23 | AE4: Q1 | AF4: Q2 | AG4: Q3 | AH4: Q4 | AJ4: ST | AL4: Total Packages | AM4: Packages till Dec'22 | AN4: Planned Packages in CY 23 | AO4: Q1 | AP4: Q2 | AQ4: Q3 | AR4: Q4 | AS4: Actual Packages in CY 23 | AT4: Q1 | AU4: Q2 | AV4: Q3 | AW4: Q4 | AY4: MEP | BA4: Total Packages | BB4: Packages till Dec'22 | BC4: Planned Packages in CY 23 | BD4: Q1 | BE4: Q2 | BF4: Q3 | BG4: Q4 | BH4: Actual Packages in CY 23 | BI4: Q1 | BJ4: Q2 | BK4: Q3 | BL4: Q4 | BN4: LS | BP4: Total Packages | BQ4: Packages till Dec'22 | BR4: Planned Packages in CY 23 | BS4: Q1 | BT4: Q2 | BU4: Q3 | BV4: Q4 | BW4: Actual Packages in CY 23 | BX4: Q1 | BY4: Q2 | BZ4: Q3 | CA4: Q4
G5: =X5+AM5+BB5+BQ5 -> 0
F7: =W7+AL7+BA7+BP7 -> 0 | G7: =X7+AM7+BB7+BQ7 -> 0 | H7: =W7+AL7+BA7+BP7 -> 0 | I7: =X7+AM7+BB7+BQ7 -> 0 | J7: =Y7+AN7+BC7+BR7 -> 0 | K7: =Z7+AO7+BD7+BS7 -> 0 | L7: =AA7+AP7+BE7+BT7 -> 0 | M7: =AB7+AQ7+BF7+BU7 -> 0 | N7: =AC7+AR7+BG7+BV7 -> 0 | O7: =AD7+AS7+BH7+BW7 -> 0 | ... S7: =AH7+AW7+BL7+CA7 -> 0
C9: DESIGN
B11: 1 | C11: 1 | D11: Contract + Design Brief | W11: =IF('Design Fee'!H11>0,2,"-") -> 2 | X11: =IF('Design Fee'!J11>0,2,"-") -> 2 | Y11: =IF('Design Fee'!K11>0,2,"-") -> - | Z11: =IF('Design Fee'!L11>0,2,"-") -> - | AA11: =IF('Design Fee'!M11>0,2,"-") -> - | AB11: =IF('Design Fee'!N11>0,2,"-") -> - | AC11: =IF('Design Fee'!O11>0,2,"-") -> - | AD11: =IF('Design Fee'!Q11>0,2,"-") -> - | AE11: =IF('Design Fee'!R11>0,2,"-") -> - | AF11: =IF('Design Fee'!S11>0,2,"-") -> - | AG11: =IF('Design Fee'!T11>0,2,"-") -> - | AH11: =IF('Design Fee'!U11>0,2,"-") -> - | AL11: =IF('Design Fee'!AR11>0,2,"-") -> - | AM11: =IF('Design Fee'!AT11>0,2,"-") -> - | AN11: =IF('Design Fee'!AU11>0,2,"-") -> - | AO11: =IF('Design Fee'!AV11>0,2,"-") -> - | AP11: =IF('Design Fee'!AW11>0,2,"-") -> - | AQ11: =IF('Design Fee'!AX11>0,2,"-") -> - | AR11: =IF('Design Fee'!AY11>0,2,"-") -> - | AS11: =IF('Design Fee'!BA11>0,2,"-") -> - | AT11: =IF('Design Fee'!BB11>0,2,"-") -> - | AU11: =IF('Design Fee'!BC11>0,2,"-") -> - | AV11: =IF('Design Fee'!BD11>0,2,"-") -> - | AW11: =IF('Design Fee'!BE11>0,2,"-") -> - | BA11: =IF('Design Fee'!CB11>0,2,"-") -> - | BB11: =IF('Design Fee'!CD11>0,2,"-") -> - | BC11: =IF('Design Fee'!CE11>0,2,"-") -> - | BD11: =IF('Design Fee'!CF11>0,2,"-") -> - | BE11: =IF('Design Fee'!CG11>0,2,"-") -> - | BF11: =IF('Design Fee'!CH11>0,2,"-") -> - | BG11: =IF('Design Fee'!CI11>0,2,"-") -> - | BH11: =IF('Design Fee'!CK11>0,2,"-") -> - | BI11: =IF('Design Fee'!CL11>0,2,"-") -> - | BJ11: =IF('Design Fee'!CM11>0,2,"-") -> - | BK11: =IF('Design Fee'!CN11>0,2,"-") -> - | BL11: =IF('Design Fee'!CO11>0,2,"-") -> - | BP11: =IF('Design Fee'!DL11>0,2,"-") -> - | BQ11: =IF('Design Fee'!DN11>0,2,"-") -> - | BR11: =IF('Design Fee'!DO11>0,2,"-") -> - | BS11: =IF('Design Fee'!DP11>0,2,"-") -> - | BT11: =IF('Design Fee'!DQ11>0,2,"-") -> - | BU11: =IF('Design Fee'!DR11>0,2,"-") -> - | BV11: =IF('Design Fee'!DS11>0,2,"-") -> - | BW11: =IF('Design Fee'!DU11>0,2,"-") -> - | BX11: =IF('Design Fee'!DV11>0,2,"-") -> - | BY11: =IF('Design Fee'!DW11>0,2,"-") -> - | BZ11: =IF('Design Fee'!DX11>0,2,"-") -> - | CA11: =IF('Design Fee'!DY11>0,2,"-") -> -
B12: 1 | C12: 1 | D12: Vision Statement | W12: =IF('Design Fee'!H12>0,2,"-") -> - | X12: =IF('Design Fee'!J12>0,2,"-") -> - | Y12: =IF('Design Fee'!K12>0,2,"-") -> - | Z12: =IF('Design Fee'!L12>0,2,"-") -> - | AA12: =IF('Design Fee'!M12>0,2,"-") -> - | AB12: =IF('Design Fee'!N12>0,2,"-") -> - | AC12: =IF('Design Fee'!O12>0,2,"-") -> - | AD12: =IF('Design Fee'!Q12>0,2,"-") -> - | AE12: =IF('Design Fee'!R12>0,2,"-") -> - | AF12: =IF('Design Fee'!S12>0,2,"-") -> - | AG12: =IF('Design Fee'!T12>0,2,"-") -> - | AH12: =IF('Design Fee'!U12>0,2,"-") -> - | AL12: =IF('Design Fee'!AR12>0,2,"-") -> - | AM12: =IF('Design Fee'!AT12>0,2,"-") -> - | AN12: =IF('Design Fee'!AU12>0,2,"-") -> - | AO12: =IF('Design Fee'!AV12>0,2,"-") -> - | AP12: =IF('Design Fee'!AW12>0,2,"-") -> - | AQ12: =IF('Design Fee'!AX12>0,2,"-") -> - | AR12: =IF('Design Fee'!AY12>0,2,"-") -> - | AS12: =IF('Design Fee'!BA12>0,2,"-") -> - | AT12: =IF('Design Fee'!BB12>0,2,"-") -> - | AU12: =IF('Design Fee'!BC12>0,2,"-") -> - | AV12: =IF('Design Fee'!BD12>0,2,"-") -> - | AW12: =IF('Design Fee'!BE12>0,2,"-") -> - | BA12: =IF('Design Fee'!CB12>0,2,"-") -> - | BB12: =IF('Design Fee'!CD12>0,2,"-") -> - | BC12: =IF('Design Fee'!CE12>0,2,"-") -> - | BD12: =IF('Design Fee'!CF12>0,2,"-") -> - | BE12: =IF('Design Fee'!CG12>0,2,"-") -> - | BF12: =IF('Design Fee'!CH12>0,2,"-") -> - | BG12: =IF('Design Fee'!CI12>0,2,"-") -> - | BH12: =IF('Design Fee'!CK12>0,2,"-") -> - | BI12: =IF('Design Fee'!CL12>0,2,"-") -> - | BJ12: =IF('Design Fee'!CM12>0,2,"-") -> - | BK12: =IF('Design Fee'!CN12>0,2,"-") -> - | BL12: =IF('Design Fee'!CO12>0,2,"-") -> - | BP12: =IF('Design Fee'!DL12>0,2,"-") -> - | BQ12: =IF('Design Fee'!DN12>0,2,"-") -> - | BR12: =IF('Design Fee'!DO12>0,2,"-") -> - | BS12: =IF('Design Fee'!DP12>0,2,"-") -> - | BT12: =IF('Design Fee'!DQ12>0,2,"-") -> - | BU12: =IF('Design Fee'!DR12>0,2,"-") -> - | BV12: =IF('Design Fee'!DS12>0,2,"-") -> - | BW12: =IF('Design Fee'!DU12>0,2,"-") -> - | BX12: =IF('Design Fee'!DV12>0,2,"-") -> - | BY12: =IF('Design Fee'!DW12>0,2,"-") -> - | BZ12: =IF('Design Fee'!DX12>0,2,"-") -> - | CA12: =IF('Design Fee'!DY12>0,2,"-") -> -
B13: 2 | C13: 2 | D13: Land - Topographical Survey with information as per defined standard, | W13: =IF('Design Fee'!H13>0,2,"-") -> - | X13: =IF('Design Fee'!J13>0,2,"-") -> - | Y13: =IF('Design Fee'!K13>0,2,"-") -> - | Z13: =IF('Design Fee'!L13>0,2,"-") -> - | AA13: =IF('Design Fee'!M13>0,2,"-") -> - | AB13: =IF('Design Fee'!N13>0,2,"-") -> - | AC13: =IF('Design Fee'!O13>0,2,"-") -> - | AD13: =IF('Design Fee'!Q13>0,2,"-") -> - | AE13: =IF('Design Fee'!R13>0,2,"-") -> - | AF13: =IF('Design Fee'!S13>0,2,"-") -> - | AG13: =IF('Design Fee'!T13>0,2,"-") -> - | AH13: =IF('Design Fee'!U13>0,2,"-") -> - | AL13: =IF('Design Fee'!AR13>0,2,"-") -> - | AM13: =IF('Design Fee'!AT13>0,2,"-") -> - | AN13: =IF('Design Fee'!AU13>0,2,"-") -> - | AO13: =IF('Design Fee'!AV13>0,2,"-") -> - | AP13: =IF('Design Fee'!AW13>0,2,"-") -> - | AQ13: =IF('Design Fee'!AX13>0,2,"-") -> - | AR13: =IF('Design Fee'!AY13>0,2,"-") -> - | AS13: =IF('Design Fee'!BA13>0,2,"-") -> - | AT13: =IF('Design Fee'!BB13>0,2,"-") -> - | AU13: =IF('Design Fee'!BC13>0,2,"-") -> - | AV13: =IF('Design Fee'!BD13>0,2,"-") -> - | AW13: =IF('Design Fee'!BE13>0,2,"-") -> - | BA13: =IF('Design Fee'!CB13>0,2,"-") -> - | BB13: =IF('Design Fee'!CD13>0,2,"-") -> - | BC13: =IF('Design Fee'!CE13>0,2,"-") -> - | BD13: =IF('Design Fee'!CF13>0,2,"-") -> - | BE13: =IF('Design Fee'!CG13>0,2,"-") -> - | BF13: =IF('Design Fee'!CH13>0,2,"-") -> - | BG13: =IF('Design Fee'!CI13>0,2,"-") -> - | BH13: =IF('Design Fee'!CK13>0,2,"-") -> - | BI13: =IF('Design Fee'!CL13>0,2,"-") -> - | BJ13: =IF('Design Fee'!CM13>0,2,"-") -> - | BK13: =IF('Design Fee'!CN13>0,2,"-") -> - | BL13: =IF('Design Fee'!CO13>0,2,"-") -> - | BP13: =IF('Design Fee'!DL13>0,2,"-") -> - | BQ13: =IF('Design Fee'!DN13>0,2,"-") -> - | BR13: =IF('Design Fee'!DO13>0,2,"-") -> - | BS13: =IF('Design Fee'!DP13>0,2,"-") -> - | BT13: =IF('Design Fee'!DQ13>0,2,"-") -> - | BU13: =IF('Design Fee'!DR13>0,2,"-") -> - | BV13: =IF('Design Fee'!DS13>0,2,"-") -> - | BW13: =IF('Design Fee'!DU13>0,2,"-") -> - | BX13: =IF('Design Fee'!DV13>0,2,"-") -> - | BY13: =IF('Design Fee'!DW13>0,2,"-") -> - | BZ13: =IF('Design Fee'!DX13>0,2,"-") -> - | CA13: =IF('Design Fee'!DY13>0,2,"-") -> -
B14: 3 | C14: 3 | D14: Zoning & Development Regulations | W14: =IF('Design Fee'!H14>0,2,"-") -> - | X14: =IF('Design Fee'!J14>0,2,"-") -> - | Y14: =IF('Design Fee'!K14>0,2,"-") -> - | Z14: =IF('Design Fee'!L14>0,2,"-") -> - | AA14: =IF('Design Fee'!M14>0,2,"-") -> - | AB14: =IF('Design Fee'!N14>0,2,"-") -> - | AC14: =IF('Design Fee'!O14>0,2,"-") -> - | AD14: =IF('Design Fee'!Q14>0,2,"-") -> - | AE14: =IF('Design Fee'!R14>0,2,"-") -> - | AF14: =IF('Design Fee'!S14>0,2,"-") -> - | AG14: =IF('Design Fee'!T14>0,2,"-") -> - | AH14: =IF('Design Fee'!U14>0,2,"-") -> - | AL14: =IF('Design Fee'!AR14>0,2,"-") -> - | AM14: =IF('Design Fee'!AT14>0,2,"-") -> - | AN14: =IF('Design Fee'!AU14>0,2,"-") -> - | AO14: =IF('Design Fee'!AV14>0,2,"-") -> - | AP14: =IF('Design Fee'!AW14>0,2,"-") -> - | AQ14: =IF('Design Fee'!AX14>0,2,"-") -> - | AR14: =IF('Design Fee'!AY14>0,2,"-") -> - | AS14: =IF('Design Fee'!BA14>0,2,"-") -> - | AT14: =IF('Design Fee'!BB14>0,2,"-") -> - | AU14: =IF('Design Fee'!BC14>0,2,"-") -> - | AV14: =IF('Design Fee'!BD14>0,2,"-") -> - | AW14: =IF('Design Fee'!BE14>0,2,"-") -> - | BA14: =IF('Design Fee'!CB14>0,2,"-") -> - | BB14: =IF('Design Fee'!CD14>0,2,"-") -> - | BC14: =IF('Design Fee'!CE14>0,2,"-") -> - | BD14: =IF('Design Fee'!CF14>0,2,"-") -> - | BE14: =IF('Design Fee'!CG14>0,2,"-") -> - | BF14: =IF('Design Fee'!CH14>0,2,"-") -> - | BG14: =IF('Design Fee'!CI14>0,2,"-") -> - | BH14: =IF('Design Fee'!CK14>0,2,"-") -> - | BI14: =IF('Design Fee'!CL14>0,2,"-") -> - | BJ14: =IF('Design Fee'!CM14>0,2,"-") -> - | BK14: =IF('Design Fee'!CN14>0,2,"-") -> - | BL14: =IF('Design Fee'!CO14>0,2,"-") -> - | BP14: =IF('Design Fee'!DL14>0,2,"-") -> - | BQ14: =IF('Design Fee'!DN14>0,2,"-") -> - | BR14: =IF('Design Fee'!DO14>0,2,"-") -> - | BS14: =IF('Design Fee'!DP14>0,2,"-") -> - | BT14: =IF('Design Fee'!DQ14>0,2,"-") -> - | BU14: =IF('Design Fee'!DR14>0,2,"-") -> - | BV14: =IF('Design Fee'!DS14>0,2,"-") -> - | BW14: =IF('Design Fee'!DU14>0,2,"-") -> - | BX14: =IF('Design Fee'!DV14>0,2,"-") -> - | BY14: =IF('Design Fee'!DW14>0,2,"-") -> - | BZ14: =IF('Design Fee'!DX14>0,2,"-") -> - | CA14: =IF('Design Fee'!DY14>0,2,"-") -> -
B15: 4 | C15: 4 | D15: Design Brief | W15: =IF('Design Fee'!H15>0,2,"-") -> - | X15: =IF('Design Fee'!J15>0,2,"-") -> - | Y15: =IF('Design Fee'!K15>0,2,"-") -> - | Z15: =IF('Design Fee'!L15>0,2,"-") -> - | AA15: =IF('Design Fee'!M15>0,2,"-") -> - | AB15: =IF('Design Fee'!N15>0,2,"-") -> - | AC15: =IF('Design Fee'!O15>0,2,"-") -> - | AD15: =IF('Design Fee'!Q15>0,2,"-") -> - | AE15: =IF('Design Fee'!R15>0,2,"-") -> - | AF15: =IF('Design Fee'!S15>0,2,"-") -> - | AG15: =IF('Design Fee'!T15>0,2,"-") -> - | AH15: =IF('Design Fee'!U15>0,2,"-") -> - | AL15: =IF('Design Fee'!AR15>0,2,"-") -> - | AM15: =IF('Design Fee'!AT15>0,2,"-") -> - | AN15: =IF('Design Fee'!AU15>0,2,"-") -> - | AO15: =IF('Design Fee'!AV15>0,2,"-") -> - | AP15: =IF('Design Fee'!AW15>0,2,"-") -> - | AQ15: =IF('Design Fee'!AX15>0,2,"-") -> - | AR15: =IF('Design Fee'!AY15>0,2,"-") -> - | AS15: =IF('Design Fee'!BA15>0,2,"-") -> - | AT15: =IF('Design Fee'!BB15>0,2,"-") -> - | AU15: =IF('Design Fee'!BC15>0,2,"-") -> - | AV15: =IF('Design Fee'!BD15>0,2,"-") -> - | AW15: =IF('Design Fee'!BE15>0,2,"-") -> - | BA15: =IF('Design Fee'!CB15>0,2,"-") -> - | BB15: =IF('Design Fee'!CD15>0,2,"-") -> - | BC15: =IF('Design Fee'!CE15>0,2,"-") -> - | BD15: =IF('Design Fee'!CF15>0,2,"-") -> - | BE15: =IF('Design Fee'!CG15>0,2,"-") -> - | BF15: =IF('Design Fee'!CH15>0,2,"-") -> - | BG15: =IF('Design Fee'!CI15>0,2,"-") -> - | BH15: =IF('Design Fee'!CK15>0,2,"-") -> - | BI15: =IF('Design Fee'!CL15>0,2,"-") -> - | BJ15: =IF('Design Fee'!CM15>0,2,"-") -> - | BK15: =IF('Design Fee'!CN15>0,2,"-") -> - | BL15: =IF('Design Fee'!CO15>0,2,"-") -> - | BP15: =IF('Design Fee'!DL15>0,2,"-") -> - | BQ15: =IF('Design Fee'!DN15>0,2,"-") -> - | BR15: =IF('Design Fee'!DO15>0,2,"-") -> - | BS15: =IF('Design Fee'!DP15>0,2,"-") -> - | BT15: =IF('Design Fee'!DQ15>0,2,"-") -> - | BU15: =IF('Design Fee'!DR15>0,2,"-") -> - | BV15: =IF('Design Fee'!DS15>0,2,"-") -> - | BW15: =IF('Design Fee'!DU15>0,2,"-") -> - | BX15: =IF('Design Fee'!DV15>0,2,"-") -> - | BY15: =IF('Design Fee'!DW15>0,2,"-") -> - | BZ15: =IF('Design Fee'!DX15>0,2,"-") -> - | CA15: =IF('Design Fee'!DY15>0,2,"-") -> -
B17: 2 | C17: 2 | D17: Schematic Concept | G17: =X17+AM17+BB17+BQ17 -> 8 | W17: =IF('Design Fee'!H17>0,2,"-") -> 2 | X17: =IF('Design Fee'!J17>0,2,"-") -> 2 | Y17: =IF('Design Fee'!K17>0,2,"-") -> - | Z17: =IF('Design Fee'!L17>0,2,"-") -> - | AA17: =IF('Design Fee'!M17>0,2,"-") -> - | AB17: =IF('Design Fee'!N17>0,2,"-") -> - | AC17: =IF('Design Fee'!O17>0,2,"-") -> - | AD17: =IF('Design Fee'!Q17>0,2,"-") -> - | AE17: =IF('Design Fee'!R17>0,2,"-") -> - | AF17: =IF('Design Fee'!S17>0,2,"-") -> - | AG17: =IF('Design Fee'!T17>0,2,"-") -> - | AH17: =IF('Design Fee'!U17>0,2,"-") -> - | AL17: =IF('Design Fee'!AR17>0,2,"-") -> 2 | AM17: =IF('Design Fee'!AT17>0,2,"-") -> 2 | AN17: =IF('Design Fee'!AU17>0,2,"-") -> - | AO17: =IF('Design Fee'!AV17>0,2,"-") -> - | AP17: =IF('Design Fee'!AW17>0,2,"-") -> - | AQ17: =IF('Design Fee'!AX17>0,2,"-") -> - | AR17: =IF('Design Fee'!AY17>0,2,"-") -> - | AS17: =IF('Design Fee'!BA17>0,2,"-") -> - | AT17: =IF('Design Fee'!BB17>0,2,"-") -> - | AU17: =IF('Design Fee'!BC17>0,2,"-") -> - | AV17: =IF('Design Fee'!BD17>0,2,"-") -> - | AW17: =IF('Design Fee'!BE17>0,2,"-") -> - | BA17: =IF('Design Fee'!CB17>0,2,"-") -> 2 | BB17: =IF('Design Fee'!CD17>0,2,"-") -> 2 | BC17: =IF('Design Fee'!CE17>0,2,"-") -> - | BD17: =IF('Design Fee'!CF17>0,2,"-") -> - | BE17: =IF('Design Fee'!CG17>0,2,"-") -> - | BF17: =IF('Design Fee'!CH17>0,2,"-") -> - | BG17: =IF('Design Fee'!CI17>0,2,"-") -> - | BH17: =IF('Design Fee'!CK17>0,2,"-") -> - | BI17: =IF('Design Fee'!CL17>0,2,"-") -> - | BJ17: =IF('Design Fee'!CM17>0,2,"-") -> - | BK17: =IF('Design Fee'!CN17>0,2,"-") -> - | BL17: =IF('Design Fee'!CO17>0,2,"-") -> - | BP17: =IF('Design Fee'!DL17>0,2,"-") -> 2 | BQ17: =IF('Design Fee'!DN17>0,2,"-") -> 2 | BR17: =IF('Design Fee'!DO17>0,2,"-") -> - | BS17: =IF('Design Fee'!DP17>0,2,"-") -> - | BT17: =IF('Design Fee'!DQ17>0,2,"-") -> - | BU17: =IF('Design Fee'!DR17>0,2,"-") -> - | BV17: =IF('Design Fee'!DS17>0,2,"-") -> - | BW17: =IF('Design Fee'!DU17>0,2,"-") -> - | BX17: =IF('Design Fee'!DV17>0,2,"-") -> - | BY17: =IF('Design Fee'!DW17>0,2,"-") -> - | BZ17: =IF('Design Fee'!DX17>0,2,"-") -> - | CA17: =IF('Design Fee'!DY17>0,2,"-") -> -
B18: 6 | C18: 1 | D18: Master Plan | W18: =IF('Design Fee'!H18>0,2,"-") -> - | X18: =IF('Design Fee'!J18>0,2,"-") -> - | Y18: =IF('Design Fee'!K18>0,2,"-") -> - | Z18: =IF('Design Fee'!L18>0,2,"-") -> - | AA18: =IF('Design Fee'!M18>0,2,"-") -> - | AB18: =IF('Design Fee'!N18>0,2,"-") -> - | AC18: =IF('Design Fee'!O18>0,2,"-") -> - | AD18: =IF('Design Fee'!Q18>0,2,"-") -> - | AE18: =IF('Design Fee'!R18>0,2,"-") -> - | AF18: =IF('Design Fee'!S18>0,2,"-") -> - | AG18: =IF('Design Fee'!T18>0,2,"-") -> - | AH18: =IF('Design Fee'!U18>0,2,"-") -> - | AL18: =IF('Design Fee'!AR18>0,2,"-") -> - | AM18: =IF('Design Fee'!AT18>0,2,"-") -> - | AN18: =IF('Design Fee'!AU18>0,2,"-") -> - | AO18: =IF('Design Fee'!AV18>0,2,"-") -> - | AP18: =IF('Design Fee'!AW18>0,2,"-") -> - | AQ18: =IF('Design Fee'!AX18>0,2,"-") -> - | AR18: =IF('Design Fee'!AY18>0,2,"-") -> - | AS18: =IF('Design Fee'!BA18>0,2,"-") -> - | AT18: =IF('Design Fee'!BB18>0,2,"-") -> - | AU18: =IF('Design Fee'!BC18>0,2,"-") -> - | AV18: =IF('Design Fee'!BD18>0,2,"-") -> - | AW18: =IF('Design Fee'!BE18>0,2,"-") -> - | BA18: =IF('Design Fee'!CB18>0,2,"-") -> - | BB18: =IF('Design Fee'!CD18>0,2,"-") -> - | BC18: =IF('Design Fee'!CE18>0,2,"-") -> - | BD18: =IF('Design Fee'!CF18>0,2,"-") -> - | BE18: =IF('Design Fee'!CG18>0,2,"-") -> - | BF18: =IF('Design Fee'!CH18>0,2,"-") -> - | BG18: =IF('Design Fee'!CI18>0,2,"-") -> - | BH18: =IF('Design Fee'!CK18>0,2,"-") -> - | BI18: =IF('Design Fee'!CL18>0,2,"-") -> - | BJ18: =IF('Design Fee'!CM18>0,2,"-") -> - | BK18: =IF('Design Fee'!CN18>0,2,"-") -> - | BL18: =IF('Design Fee'!CO18>0,2,"-") -> - | BP18: =IF('Design Fee'!DL18>0,2,"-") -> - | BQ18: =IF('Design Fee'!DN18>0,2,"-") -> - | BR18: =IF('Design Fee'!DO18>0,2,"-") -> - | BS18: =IF('Design Fee'!DP18>0,2,"-") -> - | BT18: =IF('Design Fee'!DQ18>0,2,"-") -> - | BU18: =IF('Design Fee'!DR18>0,2,"-") -> - | BV18: =IF('Design Fee'!DS18>0,2,"-") -> - | BW18: =IF('Design Fee'!DU18>0,2,"-") -> - | BX18: =IF('Design Fee'!DV18>0,2,"-") -> - | BY18: =IF('Design Fee'!DW18>0,2,"-") -> - | BZ18: =IF('Design Fee'!DX18>0,2,"-") -> - | CA18: =IF('Design Fee'!DY18>0,2,"-") -> -
B19: 6 | C19: 2 | D19: Blocks and Products | W19: =IF('Design Fee'!H19>0,2,"-") -> - | X19: =IF('Design Fee'!J19>0,2,"-") -> - | Y19: =IF('Design Fee'!K19>0,2,"-") -> - | Z19: =IF('Design Fee'!L19>0,2,"-") -> - | AA19: =IF('Design Fee'!M19>0,2,"-") -> - | AB19: =IF('Design Fee'!N19>0,2,"-") -> - | AC19: =IF('Design Fee'!O19>0,2,"-") -> - | AD19: =IF('Design Fee'!Q19>0,2,"-") -> - | AE19: =IF('Design Fee'!R19>0,2,"-") -> - | AF19: =IF('Design Fee'!S19>0,2,"-") -> - | AG19: =IF('Design Fee'!T19>0,2,"-") -> - | AH19: =IF('Design Fee'!U19>0,2,"-") -> - | AL19: =IF('Design Fee'!AR19>0,2,"-") -> - | AM19: =IF('Design Fee'!AT19>0,2,"-") -> - | AN19: =IF('Design Fee'!AU19>0,2,"-") -> - | AO19: =IF('Design Fee'!AV19>0,2,"-") -> - | AP19: =IF('Design Fee'!AW19>0,2,"-") -> - | AQ19: =IF('Design Fee'!AX19>0,2,"-") -> - | AR19: =IF('Design Fee'!AY19>0,2,"-") -> - | AS19: =IF('Design Fee'!BA19>0,2,"-") -> - | AT19: =IF('Design Fee'!BB19>0,2,"-") -> - | AU19: =IF('Design Fee'!BC19>0,2,"-") -> - | AV19: =IF('Design Fee'!BD19>0,2,"-") -> - | AW19: =IF('Design Fee'!BE19>0,2,"-") -> - | BA19: =IF('Design Fee'!CB19>0,2,"-") -> - | BB19: =IF('Design Fee'!CD19>0,2,"-") -> - | BC19: =IF('Design Fee'!CE19>0,2,"-") -> - | BD19: =IF('Design Fee'!CF19>0,2,"-") -> - | BE19: =IF('Design Fee'!CG19>0,2,"-") -> - | BF19: =IF('Design Fee'!CH19>0,2,"-") -> - | BG19: =IF('Design Fee'!CI19>0,2,"-") -> - | BH19: =IF('Design Fee'!CK19>0,2,"-") -> - | BI19: =IF('Design Fee'!CL19>0,2,"-") -> - | BJ19: =IF('Design Fee'!CM19>0,2,"-") -> - | BK19: =IF('Design Fee'!CN19>0,2,"-") -> - | BL19: =IF('Design Fee'!CO19>0,2,"-") -> - | BP19: =IF('Design Fee'!DL19>0,2,"-") -> - | BQ19: =IF('Design Fee'!DN19>0,2,"-") -> - | BR19: =IF('Design Fee'!DO19>0,2,"-") -> - | BS19: =IF('Design Fee'!DP19>0,2,"-") -> - | BT19: =IF('Design Fee'!DQ19>0,2,"-") -> - | BU19: =IF('Design Fee'!DR19>0,2,"-") -> - | BV19: =IF('Design Fee'!DS19>0,2,"-") -> - | BW19: =IF('Design Fee'!DU19>0,2,"-") -> - | BX19: =IF('Design Fee'!DV19>0,2,"-") -> - | BY19: =IF('Design Fee'!DW19>0,2,"-") -> - | BZ19: =IF('Design Fee'!DX19>0,2,"-") -> - | CA19: =IF('Design Fee'!DY19>0,2,"-") -> -
B20: 6 | C20: 3 | D20: Amenities & Facilities | W20: =IF('Design Fee'!H20>0,2,"-") -> - | X20: =IF('Design Fee'!J20>0,2,"-") -> - | Y20: =IF('Design Fee'!K20>0,2,"-") -> - | Z20: =IF('Design Fee'!L20>0,2,"-") -> - | AA20: =IF('Design Fee'!M20>0,2,"-") -> - | AB20: =IF('Design Fee'!N20>0,2,"-") -> - | AC20: =IF('Design Fee'!O20>0,2,"-") -> - | AD20: =IF('Design Fee'!Q20>0,2,"-") -> - | AE20: =IF('Design Fee'!R20>0,2,"-") -> - | AF20: =IF('Design Fee'!S20>0,2,"-") -> - | AG20: =IF('Design Fee'!T20>0,2,"-") -> - | AH20: =IF('Design Fee'!U20>0,2,"-") -> - | AL20: =IF('Design Fee'!AR20>0,2,"-") -> - | AM20: =IF('Design Fee'!AT20>0,2,"-") -> - | AN20: =IF('Design Fee'!AU20>0,2,"-") -> - | AO20: =IF('Design Fee'!AV20>0,2,"-") -> - | AP20: =IF('Design Fee'!AW20>0,2,"-") -> - | AQ20: =IF('Design Fee'!AX20>0,2,"-") -> - | AR20: =IF('Design Fee'!AY20>0,2,"-") -> - | AS20: =IF('Design Fee'!BA20>0,2,"-") -> - | AT20: =IF('Design Fee'!BB20>0,2,"-") -> - | AU20: =IF('Design Fee'!BC20>0,2,"-") -> - | AV20: =IF('Design Fee'!BD20>0,2,"-") -> - | AW20: =IF('Design Fee'!BE20>0,2,"-") -> - | BA20: =IF('Design Fee'!CB20>0,2,"-") -> - | BB20: =IF('Design Fee'!CD20>0,2,"-") -> - | BC20: =IF('Design Fee'!CE20>0,2,"-") -> - | BD20: =IF('Design Fee'!CF20>0,2,"-") -> - | BE20: =IF('Design Fee'!CG20>0,2,"-") -> - | BF20: =IF('Design Fee'!CH20>0,2,"-") -> - | BG20: =IF('Design Fee'!CI20>0,2,"-") -> - | BH20: =IF('Design Fee'!CK20>0,2,"-") -> - | BI20: =IF('Design Fee'!CL20>0,2,"-") -> - | BJ20: =IF('Design Fee'!CM20>0,2,"-") -> - | BK20: =IF('Design Fee'!CN20>0,2,"-") -> - | BL20: =IF('Design Fee'!CO20>0,2,"-") -> - | BP20: =IF('Design Fee'!DL20>0,2,"-") -> - | BQ20: =IF('Design Fee'!DN20>0,2,"-") -> - | BR20: =IF('Design Fee'!DO20>0,2,"-") -> - | BS20: =IF('Design Fee'!DP20>0,2,"-") -> - | BT20: =IF('Design Fee'!DQ20>0,2,"-") -> - | BU20: =IF('Design Fee'!DR20>0,2,"-") -> - | BV20: =IF('Design Fee'!DS20>0,2,"-") -> - | BW20: =IF('Design Fee'!DU20>0,2,"-") -> - | BX20: =IF('Design Fee'!DV20>0,2,"-") -> - | BY20: =IF('Design Fee'!DW20>0,2,"-") -> - | BZ20: =IF('Design Fee'!DX20>0,2,"-") -> - | CA20: =IF('Design Fee'!DY20>0,2,"-") -> -
B21: 6 | C21: 4 | D21: Design Basis | W21: =IF('Design Fee'!H21>0,2,"-") -> - | X21: =IF('Design Fee'!J21>0,2,"-") -> - | Y21: =IF('Design Fee'!K21>0,2,"-") -> - | Z21: =IF('Design Fee'!L21>0,2,"-") -> - | AA21: =IF('Design Fee'!M21>0,2,"-") -> - | AB21: =IF('Design Fee'!N21>0,2,"-") -> - | AC21: =IF('Design Fee'!O21>0,2,"-") -> - | AD21: =IF('Design Fee'!Q21>0,2,"-") -> - | AE21: =IF('Design Fee'!R21>0,2,"-") -> - | AF21: =IF('Design Fee'!S21>0,2,"-") -> - | AG21: =IF('Design Fee'!T21>0,2,"-") -> - | AH21: =IF('Design Fee'!U21>0,2,"-") -> - | AL21: =IF('Design Fee'!AR21>0,2,"-") -> - | AM21: =IF('Design Fee'!AT21>0,2,"-") -> - | AN21: =IF('Design Fee'!AU21>0,2,"-") -> - | AO21: =IF('Design Fee'!AV21>0,2,"-") -> - | AP21: =IF('Design Fee'!AW21>0,2,"-") -> - | AQ21: =IF('Design Fee'!AX21>0,2,"-") -> - | AR21: =IF('Design Fee'!AY21>0,2,"-") -> - | AS21: =IF('Design Fee'!BA21>0,2,"-") -> - | AT21: =IF('Design Fee'!BB21>0,2,"-") -> - | AU21: =IF('Design Fee'!BC21>0,2,"-") -> - | AV21: =IF('Design Fee'!BD21>0,2,"-") -> - | AW21: =IF('Design Fee'!BE21>0,2,"-") -> - | BA21: =IF('Design Fee'!CB21>0,2,"-") -> - | BB21: =IF('Design Fee'!CD21>0,2,"-") -> - | BC21: =IF('Design Fee'!CE21>0,2,"-") -> - | BD21: =IF('Design Fee'!CF21>0,2,"-") -> - | BE21: =IF('Design Fee'!CG21>0,2,"-") -> - | BF21: =IF('Design Fee'!CH21>0,2,"-") -> - | BG21: =IF('Design Fee'!CI21>0,2,"-") -> - | BH21: =IF('Design Fee'!CK21>0,2,"-") -> - | BI21: =IF('Design Fee'!CL21>0,2,"-") -> - | BJ21: =IF('Design Fee'!CM21>0,2,"-") -> - | BK21: =IF('Design Fee'!CN21>0,2,"-") -> - | BL21: =IF('Design Fee'!CO21>0,2,"-") -> - | BP21: =IF('Design Fee'!DL21>0,2,"-") -> - | BQ21: =IF('Design Fee'!DN21>0,2,"-") -> - | BR21: =IF('Design Fee'!DO21>0,2,"-") -> - | BS21: =IF('Design Fee'!DP21>0,2,"-") -> - | BT21: =IF('Design Fee'!DQ21>0,2,"-") -> - | BU21: =IF('Design Fee'!DR21>0,2,"-") -> - | BV21: =IF('Design Fee'!DS21>0,2,"-") -> - | BW21: =IF('Design Fee'!DU21>0,2,"-") -> - | BX21: =IF('Design Fee'!DV21>0,2,"-") -> - | BY21: =IF('Design Fee'!DW21>0,2,"-") -> - | BZ21: =IF('Design Fee'!DX21>0,2,"-") -> - | CA21: =IF('Design Fee'!DY21>0,2,"-") -> -
B23: 2 | C23: 3 | D23: Pre Construction Set | G23: =X23+AM23+BB23+BQ23 -> 8 | W23: =IF('Design Fee'!H23>0,2,"-") -> 2 | X23: =IF('Design Fee'!J23>0,2,"-") -> 2 | Y23: =IF('Design Fee'!K23>0,2,"-") -> - | Z23: =IF('Design Fee'!L23>0,2,"-") -> - | AA23: =IF('Design Fee'!M23>0,2,"-") -> - | AB23: =IF('Design Fee'!N23>0,2,"-") -> - | AC23: =IF('Design Fee'!O23>0,2,"-") -> - | AD23: =IF('Design Fee'!Q23>0,2,"-") -> - | AE23: =IF('Design Fee'!R23>0,2,"-") -> - | AF23: =IF('Design Fee'!S23>0,2,"-") -> - | AG23: =IF('Design Fee'!T23>0,2,"-") -> - | AH23: =IF('Design Fee'!U23>0,2,"-") -> - | AL23: =IF('Design Fee'!AR23>0,2,"-") -> 2 | AM23: =IF('Design Fee'!AT23>0,2,"-") -> 2 | AN23: =IF('Design Fee'!AU23>0,2,"-") -> - | AO23: =IF('Design Fee'!AV23>0,2,"-") -> - | AP23: =IF('Design Fee'!AW23>0,2,"-") -> - | AQ23: =IF('Design Fee'!AX23>0,2,"-") -> - | AR23: =IF('Design Fee'!AY23>0,2,"-") -> - | AS23: =IF('Design Fee'!BA23>0,2,"-") -> - | AT23: =IF('Design Fee'!BB23>0,2,"-") -> - | AU23: =IF('Design Fee'!BC23>0,2,"-") -> - | AV23: =IF('Design Fee'!BD23>0,2,"-") -> - | AW23: =IF('Design Fee'!BE23>0,2,"-") -> - | BA23: =IF('Design Fee'!CB23>0,2,"-") -> 2 | BB23: =IF('Design Fee'!CD23>0,2,"-") -> 2 | BC23: =IF('Design Fee'!CE23>0,2,"-") -> - | BD23: =IF('Design Fee'!CF23>0,2,"-") -> - | BE23: =IF('Design Fee'!CG23>0,2,"-") -> - | BF23: =IF('Design Fee'!CH23>0,2,"-") -> - | BG23: =IF('Design Fee'!CI23>0,2,"-") -> - | BH23: =IF('Design Fee'!CK23>0,2,"-") -> - | BI23: =IF('Design Fee'!CL23>0,2,"-") -> - | BJ23: =IF('Design Fee'!CM23>0,2,"-") -> - | BK23: =IF('Design Fee'!CN23>0,2,"-") -> - | BL23: =IF('Design Fee'!CO23>0,2,"-") -> - | BP23: =IF('Design Fee'!DL23>0,2,"-") -> 2 | BQ23: =IF('Design Fee'!DN23>0,2,"-") -> 2 | BR23: =IF('Design Fee'!DO23>0,2,"-") -> - | BS23: =IF('Design Fee'!DP23>0,2,"-") -> - | BT23: =IF('Design Fee'!DQ23>0,2,"-") -> - | BU23: =IF('Design Fee'!DR23>0,2,"-") -> - | BV23: =IF('Design Fee'!DS23>0,2,"-") -> - | BW23: =IF('Design Fee'!DU23>0,2,"-") -> - | BX23: =IF('Design Fee'!DV23>0,2,"-") -> - | BY23: =IF('Design Fee'!DW23>0,2,"-") -> - | BZ23: =IF('Design Fee'!DX23>0,2,"-") -> - | CA23: =IF('Design Fee'!DY23>0,2,"-") -> -
B24: 1 | C24: 1 | D24: Master Plan | W24: =IF('Design Fee'!H24>0,2,"-") -> - | X24: =IF('Design Fee'!J24>0,2,"-") -> - | Y24: =IF('Design Fee'!K24>0,2,"-") -> - | Z24: =IF('Design Fee'!L24>0,2,"-") -> - | AA24: =IF('Design Fee'!M24>0,2,"-") -> - | AB24: =IF('Design Fee'!N24>0,2,"-") -> - | AC24: =IF('Design Fee'!O24>0,2,"-") -> - | AD24: =IF('Design Fee'!Q24>0,2,"-") -> - | AE24: =IF('Design Fee'!R24>0,2,"-") -> - | AF24: =IF('Design Fee'!S24>0,2,"-") -> - | AG24: =IF('Design Fee'!T24>0,2,"-") -> - | AH24: =IF('Design Fee'!U24>0,2,"-") -> - | AL24: =IF('Design Fee'!AR24>0,2,"-") -> - | AM24: =IF('Design Fee'!AT24>0,2,"-") -> - | AN24: =IF('Design Fee'!AU24>0,2,"-") -> - | AO24: =IF('Design Fee'!AV24>0,2,"-") -> - | AP24: =IF('Design Fee'!AW24>0,2,"-") -> - | AQ24: =IF('Design Fee'!AX24>0,2,"-") -> - | AR24: =IF('Design Fee'!AY24>0,2,"-") -> - | AS24: =IF('Design Fee'!BA24>0,2,"-") -> - | AT24: =IF('Design Fee'!BB24>0,2,"-") -> - | AU24: =IF('Design Fee'!BC24>0,2,"-") -> - | AV24: =IF('Design Fee'!BD24>0,2,"-") -> - | AW24: =IF('Design Fee'!BE24>0,2,"-") -> - | BA24: =IF('Design Fee'!CB24>0,2,"-") -> - | BB24: =IF('Design Fee'!CD24>0,2,"-") -> - | BC24: =IF('Design Fee'!CE24>0,2,"-") -> - | BD24: =IF('Design Fee'!CF24>0,2,"-") -> - | BE24: =IF('Design Fee'!CG24>0,2,"-") -> - | BF24: =IF('Design Fee'!CH24>0,2,"-") -> - | BG24: =IF('Design Fee'!CI24>0,2,"-") -> - | BH24: =IF('Design Fee'!CK24>0,2,"-") -> - | BI24: =IF('Design Fee'!CL24>0,2,"-") -> - | BJ24: =IF('Design Fee'!CM24>0,2,"-") -> - | BK24: =IF('Design Fee'!CN24>0,2,"-") -> - | BL24: =IF('Design Fee'!CO24>0,2,"-") -> - | BP24: =IF('Design Fee'!DL24>0,2,"-") -> - | BQ24: =IF('Design Fee'!DN24>0,2,"-") -> - | BR24: =IF('Design Fee'!DO24>0,2,"-") -> - | BS24: =IF('Design Fee'!DP24>0,2,"-") -> - | BT24: =IF('Design Fee'!DQ24>0,2,"-") -> - | BU24: =IF('Design Fee'!DR24>0,2,"-") -> - | BV24: =IF('Design Fee'!DS24>0,2,"-") -> - | BW24: =IF('Design Fee'!DU24>0,2,"-") -> - | BX24: =IF('Design Fee'!DV24>0,2,"-") -> - | BY24: =IF('Design Fee'!DW24>0,2,"-") -> - | BZ24: =IF('Design Fee'!DX24>0,2,"-") -> - | CA24: =IF('Design Fee'!DY24>0,2,"-") -> -
B25: 1 | C25: 2 | D25: Blocks | W25: =IF('Design Fee'!H25>0,2,"-") -> - | X25: =IF('Design Fee'!J25>0,2,"-") -> - | Y25: =IF('Design Fee'!K25>0,2,"-") -> - | Z25: =IF('Design Fee'!L25>0,2,"-") -> - | AA25: =IF('Design Fee'!M25>0,2,"-") -> - | AB25: =IF('Design Fee'!N25>0,2,"-") -> - | AC25: =IF('Design Fee'!O25>0,2,"-") -> - | AD25: =IF('Design Fee'!Q25>0,2,"-") -> - | AE25: =IF('Design Fee'!R25>0,2,"-") -> - | AF25: =IF('Design Fee'!S25>0,2,"-") -> - | AG25: =IF('Design Fee'!T25>0,2,"-") -> - | AH25: =IF('Design Fee'!U25>0,2,"-") -> - | AL25: =IF('Design Fee'!AR25>0,2,"-") -> - | AM25: =IF('Design Fee'!AT25>0,2,"-") -> - | AN25: =IF('Design Fee'!AU25>0,2,"-") -> - | AO25: =IF('Design Fee'!AV25>0,2,"-") -> - | AP25: =IF('Design Fee'!AW25>0,2,"-") -> - | AQ25: =IF('Design Fee'!AX25>0,2,"-") -> - | AR25: =IF('Design Fee'!AY25>0,2,"-") -> - | AS25: =IF('Design Fee'!BA25>0,2,"-") -> - | AT25: =IF('Design Fee'!BB25>0,2,"-") -> - | AU25: =IF('Design Fee'!BC25>0,2,"-") -> - | AV25: =IF('Design Fee'!BD25>0,2,"-") -> - | AW25: =IF('Design Fee'!BE25>0,2,"-") -> - | BA25: =IF('Design Fee'!CB25>0,2,"-") -> - | BB25: =IF('Design Fee'!CD25>0,2,"-") -> - | BC25: =IF('Design Fee'!CE25>0,2,"-") -> - | BD25: =IF('Design Fee'!CF25>0,2,"-") -> - | BE25: =IF('Design Fee'!CG25>0,2,"-") -> - | BF25: =IF('Design Fee'!CH25>0,2,"-") -> - | BG25: =IF('Design Fee'!CI25>0,2,"-") -> - | BH25: =IF('Design Fee'!CK25>0,2,"-") -> - | BI25: =IF('Design Fee'!CL25>0,2,"-") -> - | BJ25: =IF('Design Fee'!CM25>0,2,"-") -> - | BK25: =IF('Design Fee'!CN25>0,2,"-") -> - | BL25: =IF('Design Fee'!CO25>0,2,"-") -> - | BP25: =IF('Design Fee'!DL25>0,2,"-") -> - | BQ25: =IF('Design Fee'!DN25>0,2,"-") -> - | BR25: =IF('Design Fee'!DO25>0,2,"-") -> - | BS25: =IF('Design Fee'!DP25>0,2,"-") -> - | BT25: =IF('Design Fee'!DQ25>0,2,"-") -> - | BU25: =IF('Design Fee'!DR25>0,2,"-") -> - | BV25: =IF('Design Fee'!DS25>0,2,"-") -> - | BW25: =IF('Design Fee'!DU25>0,2,"-") -> - | BX25: =IF('Design Fee'!DV25>0,2,"-") -> - | BY25: =IF('Design Fee'!DW25>0,2,"-") -> - | BZ25: =IF('Design Fee'!DX25>0,2,"-") -> - | CA25: =IF('Design Fee'!DY25>0,2,"-") -> -
B26: 1 | C26: 3 | D26: Products | W26: =IF('Design Fee'!H26>0,2,"-") -> - | X26: =IF('Design Fee'!J26>0,2,"-") -> - | Y26: =IF('Design Fee'!K26>0,2,"-") -> - | Z26: =IF('Design Fee'!L26>0,2,"-") -> - | AA26: =IF('Design Fee'!M26>0,2,"-") -> - | AB26: =IF('Design Fee'!N26>0,2,"-") -> - | AC26: =IF('Design Fee'!O26>0,2,"-") -> - | AD26: =IF('Design Fee'!Q26>0,2,"-") -> - | AE26: =IF('Design Fee'!R26>0,2,"-") -> - | AF26: =IF('Design Fee'!S26>0,2,"-") -> - | AG26: =IF('Design Fee'!T26>0,2,"-") -> - | AH26: =IF('Design Fee'!U26>0,2,"-") -> - | AL26: =IF('Design Fee'!AR26>0,2,"-") -> - | AM26: =IF('Design Fee'!AT26>0,2,"-") -> - | AN26: =IF('Design Fee'!AU26>0,2,"-") -> - | AO26: =IF('Design Fee'!AV26>0,2,"-") -> - | AP26: =IF('Design Fee'!AW26>0,2,"-") -> - | AQ26: =IF('Design Fee'!AX26>0,2,"-") -> - | AR26: =IF('Design Fee'!AY26>0,2,"-") -> - | AS26: =IF('Design Fee'!BA26>0,2,"-") -> - | AT26: =IF('Design Fee'!BB26>0,2,"-") -> - | AU26: =IF('Design Fee'!BC26>0,2,"-") -> - | AV26: =IF('Design Fee'!BD26>0,2,"-") -> - | AW26: =IF('Design Fee'!BE26>0,2,"-") -> - | BA26: =IF('Design Fee'!CB26>0,2,"-") -> - | BB26: =IF('Design Fee'!CD26>0,2,"-") -> - | BC26: =IF('Design Fee'!CE26>0,2,"-") -> - | BD26: =IF('Design Fee'!CF26>0,2,"-") -> - | BE26: =IF('Design Fee'!CG26>0,2,"-") -> - | BF26: =IF('Design Fee'!CH26>0,2,"-") -> - | BG26: =IF('Design Fee'!CI26>0,2,"-") -> - | BH26: =IF('Design Fee'!CK26>0,2,"-") -> - | BI26: =IF('Design Fee'!CL26>0,2,"-") -> - | BJ26: =IF('Design Fee'!CM26>0,2,"-") -> - | BK26: =IF('Design Fee'!CN26>0,2,"-") -> - | BL26: =IF('Design Fee'!CO26>0,2,"-") -> - | BP26: =IF('Design Fee'!DL26>0,2,"-") -> - | BQ26: =IF('Design Fee'!DN26>0,2,"-") -> - | BR26: =IF('Design Fee'!DO26>0,2,"-") -> - | BS26: =IF('Design Fee'!DP26>0,2,"-") -> - | BT26: =IF('Design Fee'!DQ26>0,2,"-") -> - | BU26: =IF('Design Fee'!DR26>0,2,"-") -> - | BV26: =IF('Design Fee'!DS26>0,2,"-") -> - | BW26: =IF('Design Fee'!DU26>0,2,"-") -> - | BX26: =IF('Design Fee'!DV26>0,2,"-") -> - | BY26: =IF('Design Fee'!DW26>0,2,"-") -> - | BZ26: =IF('Design Fee'!DX26>0,2,"-") -> - | CA26: =IF('Design Fee'!DY26>0,2,"-") -> -
B27: 1 | C27: 4 | D27: Amenities & Facilities | W27: =IF('Design Fee'!H27>0,2,"-") -> - | X27: =IF('Design Fee'!J27>0,2,"-") -> - | Y27: =IF('Design Fee'!K27>0,2,"-") -> - | Z27: =IF('Design Fee'!L27>0,2,"-") -> - | AA27: =IF('Design Fee'!M27>0,2,"-") -> - | AB27: =IF('Design Fee'!N27>0,2,"-") -> - | AC27: =IF('Design Fee'!O27>0,2,"-") -> - | AD27: =IF('Design Fee'!Q27>0,2,"-") -> - | AE27: =IF('Design Fee'!R27>0,2,"-") -> - | AF27: =IF('Design Fee'!S27>0,2,"-") -> - | AG27: =IF('Design Fee'!T27>0,2,"-") -> - | AH27: =IF('Design Fee'!U27>0,2,"-") -> - | AL27: =IF('Design Fee'!AR27>0,2,"-") -> - | AM27: =IF('Design Fee'!AT27>0,2,"-") -> - | AN27: =IF('Design Fee'!AU27>0,2,"-") -> - | AO27: =IF('Design Fee'!AV27>0,2,"-") -> - | AP27: =IF('Design Fee'!AW27>0,2,"-") -> - | AQ27: =IF('Design Fee'!AX27>0,2,"-") -> - | AR27: =IF('Design Fee'!AY27>0,2,"-") -> - | AS27: =IF('Design Fee'!BA27>0,2,"-") -> - | AT27: =IF('Design Fee'!BB27>0,2,"-") -> - | AU27: =IF('Design Fee'!BC27>0,2,"-") -> - | AV27: =IF('Design Fee'!BD27>0,2,"-") -> - | AW27: =IF('Design Fee'!BE27>0,2,"-") -> - | BA27: =IF('Design Fee'!CB27>0,2,"-") -> - | BB27: =IF('Design Fee'!CD27>0,2,"-") -> - | BC27: =IF('Design Fee'!CE27>0,2,"-") -> - | BD27: =IF('Design Fee'!CF27>0,2,"-") -> - | BE27: =IF('Design Fee'!CG27>0,2,"-") -> - | BF27: =IF('Design Fee'!CH27>0,2,"-") -> - | BG27: =IF('Design Fee'!CI27>0,2,"-") -> - | BH27: =IF('Design Fee'!CK27>0,2,"-") -> - | BI27: =IF('Design Fee'!CL27>0,2,"-") -> - | BJ27: =IF('Design Fee'!CM27>0,2,"-") -> - | BK27: =IF('Design Fee'!CN27>0,2,"-") -> - | BL27: =IF('Design Fee'!CO27>0,2,"-") -> - | BP27: =IF('Design Fee'!DL27>0,2,"-") -> - | BQ27: =IF('Design Fee'!DN27>0,2,"-") -> - | BR27: =IF('Design Fee'!DO27>0,2,"-") -> - | BS27: =IF('Design Fee'!DP27>0,2,"-") -> - | BT27: =IF('Design Fee'!DQ27>0,2,"-") -> - | BU27: =IF('Design Fee'!DR27>0,2,"-") -> - | BV27: =IF('Design Fee'!DS27>0,2,"-") -> - | BW27: =IF('Design Fee'!DU27>0,2,"-") -> - | BX27: =IF('Design Fee'!DV27>0,2,"-") -> - | BY27: =IF('Design Fee'!DW27>0,2,"-") -> - | BZ27: =IF('Design Fee'!DX27>0,2,"-") -> - | CA27: =IF('Design Fee'!DY27>0,2,"-") -> -
B28: 5 | C28: 5 | D28: Design Basis | W28: =IF('Design Fee'!H28>0,2,"-") -> - | X28: =IF('Design Fee'!J28>0,2,"-") -> - | Y28: =IF('Design Fee'!K28>0,2,"-") -> - | Z28: =IF('Design Fee'!L28>0,2,"-") -> - | AA28: =IF('Design Fee'!M28>0,2,"-") -> - | AB28: =IF('Design Fee'!N28>0,2,"-") -> - | AC28: =IF('Design Fee'!O28>0,2,"-") -> - | AD28: =IF('Design Fee'!Q28>0,2,"-") -> - | AE28: =IF('Design Fee'!R28>0,2,"-") -> - | AF28: =IF('Design Fee'!S28>0,2,"-") -> - | AG28: =IF('Design Fee'!T28>0,2,"-") -> - | AH28: =IF('Design Fee'!U28>0,2,"-") -> - | AL28: =IF('Design Fee'!AR28>0,2,"-") -> - | AM28: =IF('Design Fee'!AT28>0,2,"-") -> - | AN28: =IF('Design Fee'!AU28>0,2,"-") -> - | AO28: =IF('Design Fee'!AV28>0,2,"-") -> - | AP28: =IF('Design Fee'!AW28>0,2,"-") -> - | AQ28: =IF('Design Fee'!AX28>0,2,"-") -> - | AR28: =IF('Design Fee'!AY28>0,2,"-") -> - | AS28: =IF('Design Fee'!BA28>0,2,"-") -> - | AT28: =IF('Design Fee'!BB28>0,2,"-") -> - | AU28: =IF('Design Fee'!BC28>0,2,"-") -> - | AV28: =IF('Design Fee'!BD28>0,2,"-") -> - | AW28: =IF('Design Fee'!BE28>0,2,"-") -> - | BA28: =IF('Design Fee'!CB28>0,2,"-") -> - | BB28: =IF('Design Fee'!CD28>0,2,"-") -> - | BC28: =IF('Design Fee'!CE28>0,2,"-") -> - | BD28: =IF('Design Fee'!CF28>0,2,"-") -> - | BE28: =IF('Design Fee'!CG28>0,2,"-") -> - | BF28: =IF('Design Fee'!CH28>0,2,"-") -> - | BG28: =IF('Design Fee'!CI28>0,2,"-") -> - | BH28: =IF('Design Fee'!CK28>0,2,"-") -> - | BI28: =IF('Design Fee'!CL28>0,2,"-") -> - | BJ28: =IF('Design Fee'!CM28>0,2,"-") -> - | BK28: =IF('Design Fee'!CN28>0,2,"-") -> - | BL28: =IF('Design Fee'!CO28>0,2,"-") -> - | BP28: =IF('Design Fee'!DL28>0,2,"-") -> - | BQ28: =IF('Design Fee'!DN28>0,2,"-") -> - | BR28: =IF('Design Fee'!DO28>0,2,"-") -> - | BS28: =IF('Design Fee'!DP28>0,2,"-") -> - | BT28: =IF('Design Fee'!DQ28>0,2,"-") -> - | BU28: =IF('Design Fee'!DR28>0,2,"-") -> - | BV28: =IF('Design Fee'!DS28>0,2,"-") -> - | BW28: =IF('Design Fee'!DU28>0,2,"-") -> - | BX28: =IF('Design Fee'!DV28>0,2,"-") -> - | BY28: =IF('Design Fee'!DW28>0,2,"-") -> - | BZ28: =IF('Design Fee'!DX28>0,2,"-") -> - | CA28: =IF('Design Fee'!DY28>0,2,"-") -> -
B30: 3 | C30: 4 | D30: Approvals | W30: =IF('Design Fee'!H30>0,2,"-") -> 2 | X30: =IF('Design Fee'!J30>0,2,"-") -> 2 | Y30: =IF('Design Fee'!K30>0,2,"-") -> - | Z30: =IF('Design Fee'!L30>0,2,"-") -> - | AA30: =IF('Design Fee'!M30>0,2,"-") -> - | AB30: =IF('Design Fee'!N30>0,2,"-") -> - | AC30: =IF('Design Fee'!O30>0,2,"-") -> - | AD30: =IF('Design Fee'!Q30>0,2,"-") -> - | AE30: =IF('Design Fee'!R30>0,2,"-") -> - | AF30: =IF('Design Fee'!S30>0,2,"-") -> - | AG30: =IF('Design Fee'!T30>0,2,"-") -> - | AH30: =IF('Design Fee'!U30>0,2,"-") -> - | AL30: =IF('Design Fee'!AR30>0,2,"-") -> - | AM30: =IF('Design Fee'!AT30>0,2,"-") -> - | AN30: =IF('Design Fee'!AU30>0,2,"-") -> - | AO30: =IF('Design Fee'!AV30>0,2,"-") -> - | AP30: =IF('Design Fee'!AW30>0,2,"-") -> - | AQ30: =IF('Design Fee'!AX30>0,2,"-") -> - | AR30: =IF('Design Fee'!AY30>0,2,"-") -> - | AS30: =IF('Design Fee'!BA30>0,2,"-") -> - | AT30: =IF('Design Fee'!BB30>0,2,"-") -> - | AU30: =IF('Design Fee'!BC30>0,2,"-") -> - | AV30: =IF('Design Fee'!BD30>0,2,"-") -> - | AW30: =IF('Design Fee'!BE30>0,2,"-") -> - | BA30: =IF('Design Fee'!CB30>0,2,"-") -> 2 | BB30: =IF('Design Fee'!CD30>0,2,"-") -> 2 | BC30: =IF('Design Fee'!CE30>0,2,"-") -> - | BD30: =IF('Design Fee'!CF30>0,2,"-") -> - | BE30: =IF('Design Fee'!CG30>0,2,"-") -> - | BF30: =IF('Design Fee'!CH30>0,2,"-") -> - | BG30: =IF('Design Fee'!CI30>0,2,"-") -> - | BH30: =IF('Design Fee'!CK30>0,2,"-") -> - | BI30: =IF('Design Fee'!CL30>0,2,"-") -> - | BJ30: =IF('Design Fee'!CM30>0,2,"-") -> - | BK30: =IF('Design Fee'!CN30>0,2,"-") -> - | BL30: =IF('Design Fee'!CO30>0,2,"-") -> - | BP30: =IF('Design Fee'!DL30>0,2,"-") -> 2 | BQ30: =IF('Design Fee'!DN30>0,2,"-") -> 2 | BR30: =IF('Design Fee'!DO30>0,2,"-") -> - | BS30: =IF('Design Fee'!DP30>0,2,"-") -> - | BT30: =IF('Design Fee'!DQ30>0,2,"-") -> - | BU30: =IF('Design Fee'!DR30>0,2,"-") -> - | BV30: =IF('Design Fee'!DS30>0,2,"-") -> - | BW30: =IF('Design Fee'!DU30>0,2,"-") -> - | BX30: =IF('Design Fee'!DV30>0,2,"-") -> - | BY30: =IF('Design Fee'!DW30>0,2,"-") -> - | BZ30: =IF('Design Fee'!DX30>0,2,"-") -> - | CA30: =IF('Design Fee'!DY30>0,2,"-") -> -
B31: 1 | C31: 1 | D31: Development Plan | W31: =IF('Design Fee'!H31>0,2,"-") -> - | X31: =IF('Design Fee'!J31>0,2,"-") -> - | Y31: =IF('Design Fee'!K31>0,2,"-") -> - | Z31: =IF('Design Fee'!L31>0,2,"-") -> - | AA31: =IF('Design Fee'!M31>0,2,"-") -> - | AB31: =IF('Design Fee'!N31>0,2,"-") -> - | AC31: =IF('Design Fee'!O31>0,2,"-") -> - | AD31: =IF('Design Fee'!Q31>0,2,"-") -> - | AE31: =IF('Design Fee'!R31>0,2,"-") -> - | AF31: =IF('Design Fee'!S31>0,2,"-") -> - | AG31: =IF('Design Fee'!T31>0,2,"-") -> - | AH31: =IF('Design Fee'!U31>0,2,"-") -> - | AL31: =IF('Design Fee'!AR31>0,2,"-") -> - | AM31: =IF('Design Fee'!AT31>0,2,"-") -> - | AN31: =IF('Design Fee'!AU31>0,2,"-") -> - | AO31: =IF('Design Fee'!AV31>0,2,"-") -> - | AP31: =IF('Design Fee'!AW31>0,2,"-") -> - | AQ31: =IF('Design Fee'!AX31>0,2,"-") -> - | AR31: =IF('Design Fee'!AY31>0,2,"-") -> - | AS31: =IF('Design Fee'!BA31>0,2,"-") -> - | AT31: =IF('Design Fee'!BB31>0,2,"-") -> - | AU31: =IF('Design Fee'!BC31>0,2,"-") -> - | AV31: =IF('Design Fee'!BD31>0,2,"-") -> - | AW31: =IF('Design Fee'!BE31>0,2,"-") -> - | BA31: =IF('Design Fee'!CB31>0,2,"-") -> - | BB31: =IF('Design Fee'!CD31>0,2,"-") -> - | BC31: =IF('Design Fee'!CE31>0,2,"-") -> - | BD31: =IF('Design Fee'!CF31>0,2,"-") -> - | BE31: =IF('Design Fee'!CG31>0,2,"-") -> - | BF31: =IF('Design Fee'!CH31>0,2,"-") -> - | BG31: =IF('Design Fee'!CI31>0,2,"-") -> - | BH31: =IF('Design Fee'!CK31>0,2,"-") -> - | BI31: =IF('Design Fee'!CL31>0,2,"-") -> - | BJ31: =IF('Design Fee'!CM31>0,2,"-") -> - | BK31: =IF('Design Fee'!CN31>0,2,"-") -> - | BL31: =IF('Design Fee'!CO31>0,2,"-") -> - | BP31: =IF('Design Fee'!DL31>0,2,"-") -> - | BQ31: =IF('Design Fee'!DN31>0,2,"-") -> - | BR31: =IF('Design Fee'!DO31>0,2,"-") -> - | BS31: =IF('Design Fee'!DP31>0,2,"-") -> - | BT31: =IF('Design Fee'!DQ31>0,2,"-") -> - | BU31: =IF('Design Fee'!DR31>0,2,"-") -> - | BV31: =IF('Design Fee'!DS31>0,2,"-") -> - | BW31: =IF('Design Fee'!DU31>0,2,"-") -> - | BX31: =IF('Design Fee'!DV31>0,2,"-") -> - | BY31: =IF('Design Fee'!DW31>0,2,"-") -> - | BZ31: =IF('Design Fee'!DX31>0,2,"-") -> - | CA31: =IF('Design Fee'!DY31>0,2,"-") -> -
B32: 1 | C32: 2 | D32: Building Plan | W32: =IF('Design Fee'!H32>0,2,"-") -> - | X32: =IF('Design Fee'!J32>0,2,"-") -> - | Y32: =IF('Design Fee'!K32>0,2,"-") -> - | Z32: =IF('Design Fee'!L32>0,2,"-") -> - | AA32: =IF('Design Fee'!M32>0,2,"-") -> - | AB32: =IF('Design Fee'!N32>0,2,"-") -> - | AC32: =IF('Design Fee'!O32>0,2,"-") -> - | AD32: =IF('Design Fee'!Q32>0,2,"-") -> - | AE32: =IF('Design Fee'!R32>0,2,"-") -> - | AF32: =IF('Design Fee'!S32>0,2,"-") -> - | AG32: =IF('Design Fee'!T32>0,2,"-") -> - | AH32: =IF('Design Fee'!U32>0,2,"-") -> - | AL32: =IF('Design Fee'!AR32>0,2,"-") -> - | AM32: =IF('Design Fee'!AT32>0,2,"-") -> - | AN32: =IF('Design Fee'!AU32>0,2,"-") -> - | AO32: =IF('Design Fee'!AV32>0,2,"-") -> - | AP32: =IF('Design Fee'!AW32>0,2,"-") -> - | AQ32: =IF('Design Fee'!AX32>0,2,"-") -> - | AR32: =IF('Design Fee'!AY32>0,2,"-") -> - | AS32: =IF('Design Fee'!BA32>0,2,"-") -> - | AT32: =IF('Design Fee'!BB32>0,2,"-") -> - | AU32: =IF('Design Fee'!BC32>0,2,"-") -> - | AV32: =IF('Design Fee'!BD32>0,2,"-") -> - | AW32: =IF('Design Fee'!BE32>0,2,"-") -> - | BA32: =IF('Design Fee'!CB32>0,2,"-") -> - | BB32: =IF('Design Fee'!CD32>0,2,"-") -> - | BC32: =IF('Design Fee'!CE32>0,2,"-") -> - | BD32: =IF('Design Fee'!CF32>0,2,"-") -> - | BE32: =IF('Design Fee'!CG32>0,2,"-") -> - | BF32: =IF('Design Fee'!CH32>0,2,"-") -> - | BG32: =IF('Design Fee'!CI32>0,2,"-") -> - | BH32: =IF('Design Fee'!CK32>0,2,"-") -> - | BI32: =IF('Design Fee'!CL32>0,2,"-") -> - | BJ32: =IF('Design Fee'!CM32>0,2,"-") -> - | BK32: =IF('Design Fee'!CN32>0,2,"-") -> - | BL32: =IF('Design Fee'!CO32>0,2,"-") -> - | BP32: =IF('Design Fee'!DL32>0,2,"-") -> - | BQ32: =IF('Design Fee'!DN32>0,2,"-") -> - | BR32: =IF('Design Fee'!DO32>0,2,"-") -> - | BS32: =IF('Design Fee'!DP32>0,2,"-") -> - | BT32: =IF('Design Fee'!DQ32>0,2,"-") -> - | BU32: =IF('Design Fee'!DR32>0,2,"-") -> - | BV32: =IF('Design Fee'!DS32>0,2,"-") -> - | BW32: =IF('Design Fee'!DU32>0,2,"-") -> - | BX32: =IF('Design Fee'!DV32>0,2,"-") -> - | BY32: =IF('Design Fee'!DW32>0,2,"-") -> - | BZ32: =IF('Design Fee'!DX32>0,2,"-") -> - | CA32: =IF('Design Fee'!DY32>0,2,"-") -> -
B33: 2 | C33: 3 | D33: Fire Safety | W33: =IF('Design Fee'!H33>0,2,"-") -> - | X33: =IF('Design Fee'!J33>0,2,"-") -> - | Y33: =IF('Design Fee'!K33>0,2,"-") -> - | Z33: =IF('Design Fee'!L33>0,2,"-") -> - | AA33: =IF('Design Fee'!M33>0,2,"-") -> - | AB33: =IF('Design Fee'!N33>0,2,"-") -> - | AC33: =IF('Design Fee'!O33>0,2,"-") -> - | AD33: =IF('Design Fee'!Q33>0,2,"-") -> - | AE33: =IF('Design Fee'!R33>0,2,"-") -> - | AF33: =IF('Design Fee'!S33>0,2,"-") -> - | AG33: =IF('Design Fee'!T33>0,2,"-") -> - | AH33: =IF('Design Fee'!U33>0,2,"-") -> - | AL33: =IF('Design Fee'!AR33>0,2,"-") -> - | AM33: =IF('Design Fee'!AT33>0,2,"-") -> - | AN33: =IF('Design Fee'!AU33>0,2,"-") -> - | AO33: =IF('Design Fee'!AV33>0,2,"-") -> - | AP33: =IF('Design Fee'!AW33>0,2,"-") -> - | AQ33: =IF('Design Fee'!AX33>0,2,"-") -> - | AR33: =IF('Design Fee'!AY33>0,2,"-") -> - | AS33: =IF('Design Fee'!BA33>0,2,"-") -> - | AT33: =IF('Design Fee'!BB33>0,2,"-") -> - | AU33: =IF('Design Fee'!BC33>0,2,"-") -> - | AV33: =IF('Design Fee'!BD33>0,2,"-") -> - | AW33: =IF('Design Fee'!BE33>0,2,"-") -> - | BA33: =IF('Design Fee'!CB33>0,2,"-") -> - | BB33: =IF('Design Fee'!CD33>0,2,"-") -> - | BC33: =IF('Design Fee'!CE33>0,2,"-") -> - | BD33: =IF('Design Fee'!CF33>0,2,"-") -> - | BE33: =IF('Design Fee'!CG33>0,2,"-") -> - | BF33: =IF('Design Fee'!CH33>0,2,"-") -> - | BG33: =IF('Design Fee'!CI33>0,2,"-") -> - | BH33: =IF('Design Fee'!CK33>0,2,"-") -> - | BI33: =IF('Design Fee'!CL33>0,2,"-") -> - | BJ33: =IF('Design Fee'!CM33>0,2,"-") -> - | BK33: =IF('Design Fee'!CN33>0,2,"-") -> - | BL33: =IF('Design Fee'!CO33>0,2,"-") -> - | BP33: =IF('Design Fee'!DL33>0,2,"-") -> - | BQ33: =IF('Design Fee'!DN33>0,2,"-") -> - | BR33: =IF('Design Fee'!DO33>0,2,"-") -> - | BS33: =IF('Design Fee'!DP33>0,2,"-") -> - | BT33: =IF('Design Fee'!DQ33>0,2,"-") -> - | BU33: =IF('Design Fee'!DR33>0,2,"-") -> - | BV33: =IF('Design Fee'!DS33>0,2,"-") -> - | BW33: =IF('Design Fee'!DU33>0,2,"-") -> - | BX33: =IF('Design Fee'!DV33>0,2,"-") -> - | BY33: =IF('Design Fee'!DW33>0,2,"-") -> - | BZ33: =IF('Design Fee'!DX33>0,2,"-") -> - | CA33: =IF('Design Fee'!DY33>0,2,"-") -> -
B34: 3 | C34: 4 | D34: Environment | W34: =IF('Design Fee'!H34>0,2,"-") -> - | X34: =IF('Design Fee'!J34>0,2,"-") -> - | Y34: =IF('Design Fee'!K34>0,2,"-") -> - | Z34: =IF('Design Fee'!L34>0,2,"-") -> - | AA34: =IF('Design Fee'!M34>0,2,"-") -> - | AB34: =IF('Design Fee'!N34>0,2,"-") -> - | AC34: =IF('Design Fee'!O34>0,2,"-") -> - | AD34: =IF('Design Fee'!Q34>0,2,"-") -> - | AE34: =IF('Design Fee'!R34>0,2,"-") -> - | AF34: =IF('Design Fee'!S34>0,2,"-") -> - | AG34: =IF('Design Fee'!T34>0,2,"-") -> - | AH34: =IF('Design Fee'!U34>0,2,"-") -> - | AL34: =IF('Design Fee'!AR34>0,2,"-") -> - | AM34: =IF('Design Fee'!AT34>0,2,"-") -> - | AN34: =IF('Design Fee'!AU34>0,2,"-") -> - | AO34: =IF('Design Fee'!AV34>0,2,"-") -> - | AP34: =IF('Design Fee'!AW34>0,2,"-") -> - | AQ34: =IF('Design Fee'!AX34>0,2,"-") -> - | AR34: =IF('Design Fee'!AY34>0,2,"-") -> - | AS34: =IF('Design Fee'!BA34>0,2,"-") -> - | AT34: =IF('Design Fee'!BB34>0,2,"-") -> - | AU34: =IF('Design Fee'!BC34>0,2,"-") -> - | AV34: =IF('Design Fee'!BD34>0,2,"-") -> - | AW34: =IF('Design Fee'!BE34>0,2,"-") -> - | BA34: =IF('Design Fee'!CB34>0,2,"-") -> - | BB34: =IF('Design Fee'!CD34>0,2,"-") -> - | BC34: =IF('Design Fee'!CE34>0,2,"-") -> - | BD34: =IF('Design Fee'!CF34>0,2,"-") -> - | BE34: =IF('Design Fee'!CG34>0,2,"-") -> - | BF34: =IF('Design Fee'!CH34>0,2,"-") -> - | BG34: =IF('Design Fee'!CI34>0,2,"-") -> - | BH34: =IF('Design Fee'!CK34>0,2,"-") -> - | BI34: =IF('Design Fee'!CL34>0,2,"-") -> - | BJ34: =IF('Design Fee'!CM34>0,2,"-") -> - | BK34: =IF('Design Fee'!CN34>0,2,"-") -> - | BL34: =IF('Design Fee'!CO34>0,2,"-") -> - | BP34: =IF('Design Fee'!DL34>0,2,"-") -> - | BQ34: =IF('Design Fee'!DN34>0,2,"-") -> - | BR34: =IF('Design Fee'!DO34>0,2,"-") -> - | BS34: =IF('Design Fee'!DP34>0,2,"-") -> - | BT34: =IF('Design Fee'!DQ34>0,2,"-") -> - | BU34: =IF('Design Fee'!DR34>0,2,"-") -> - | BV34: =IF('Design Fee'!DS34>0,2,"-") -> - | BW34: =IF('Design Fee'!DU34>0,2,"-") -> - | BX34: =IF('Design Fee'!DV34>0,2,"-") -> - | BY34: =IF('Design Fee'!DW34>0,2,"-") -> - | BZ34: =IF('Design Fee'!DX34>0,2,"-") -> - | CA34: =IF('Design Fee'!DY34>0,2,"-") -> -
B35: 4 | C35: 5 | D35: Water Supply and Sewerage | W35: =IF('Design Fee'!H35>0,2,"-") -> - | X35: =IF('Design Fee'!J35>0,2,"-") -> - | Y35: =IF('Design Fee'!K35>0,2,"-") -> - | Z35: =IF('Design Fee'!L35>0,2,"-") -> - | AA35: =IF('Design Fee'!M35>0,2,"-") -> - | AB35: =IF('Design Fee'!N35>0,2,"-") -> - | AC35: =IF('Design Fee'!O35>0,2,"-") -> - | AD35: =IF('Design Fee'!Q35>0,2,"-") -> - | AE35: =IF('Design Fee'!R35>0,2,"-") -> - | AF35: =IF('Design Fee'!S35>0,2,"-") -> - | AG35: =IF('Design Fee'!T35>0,2,"-") -> - | AH35: =IF('Design Fee'!U35>0,2,"-") -> - | AL35: =IF('Design Fee'!AR35>0,2,"-") -> - | AM35: =IF('Design Fee'!AT35>0,2,"-") -> - | AN35: =IF('Design Fee'!AU35>0,2,"-") -> - | AO35: =IF('Design Fee'!AV35>0,2,"-") -> - | AP35: =IF('Design Fee'!AW35>0,2,"-") -> - | AQ35: =IF('Design Fee'!AX35>0,2,"-") -> - | AR35: =IF('Design Fee'!AY35>0,2,"-") -> - | AS35: =IF('Design Fee'!BA35>0,2,"-") -> - | AT35: =IF('Design Fee'!BB35>0,2,"-") -> - | AU35: =IF('Design Fee'!BC35>0,2,"-") -> - | AV35: =IF('Design Fee'!BD35>0,2,"-") -> - | AW35: =IF('Design Fee'!BE35>0,2,"-") -> - | BA35: =IF('Design Fee'!CB35>0,2,"-") -> - | BB35: =IF('Design Fee'!CD35>0,2,"-") -> - | BC35: =IF('Design Fee'!CE35>0,2,"-") -> - | BD35: =IF('Design Fee'!CF35>0,2,"-") -> - | BE35: =IF('Design Fee'!CG35>0,2,"-") -> - | BF35: =IF('Design Fee'!CH35>0,2,"-") -> - | BG35: =IF('Design Fee'!CI35>0,2,"-") -> - | BH35: =IF('Design Fee'!CK35>0,2,"-") -> - | BI35: =IF('Design Fee'!CL35>0,2,"-") -> - | BJ35: =IF('Design Fee'!CM35>0,2,"-") -> - | BK35: =IF('Design Fee'!CN35>0,2,"-") -> - | BL35: =IF('Design Fee'!CO35>0,2,"-") -> - | BP35: =IF('Design Fee'!DL35>0,2,"-") -> - | BQ35: =IF('Design Fee'!DN35>0,2,"-") -> - | BR35: =IF('Design Fee'!DO35>0,2,"-") -> - | BS35: =IF('Design Fee'!DP35>0,2,"-") -> - | BT35: =IF('Design Fee'!DQ35>0,2,"-") -> - | BU35: =IF('Design Fee'!DR35>0,2,"-") -> - | BV35: =IF('Design Fee'!DS35>0,2,"-") -> - | BW35: =IF('Design Fee'!DU35>0,2,"-") -> - | BX35: =IF('Design Fee'!DV35>0,2,"-") -> - | BY35: =IF('Design Fee'!DW35>0,2,"-") -> - | BZ35: =IF('Design Fee'!DX35>0,2,"-") -> - | CA35: =IF('Design Fee'!DY35>0,2,"-") -> -
